[2019-Dec-19 22:33] 127.0.0.1 GET http /favicon.ico? 5xx INTERNAL SERVER ERROR
Traceback (most recent call last):
  File "/home/jon/venv/p3/lib/python3.6/site-packages/flask/app.py", line 1813, in full_dispatch_request
    rv = self.dispatch_request()
  File "/home/jon/venv/p3/lib/python3.6/site-packages/flask/app.py", line 1791, in dispatch_request
    self.raise_routing_exception(req)
  File "/home/jon/venv/p3/lib/python3.6/site-packages/flask/app.py", line 1774, in raise_routing_exception
    raise request.routing_exception
  File "/home/jon/venv/p3/lib/python3.6/site-packages/flask/ctx.py", line 336, in match_request
    self.url_adapter.match(return_rule=True)
  File "/home/jon/venv/p3/lib/python3.6/site-packages/werkzeug/routing.py", line 1581, in match
    raise NotFound()
werkzeug.exceptions.NotFound: 404 Not Found: The requested URL was not found on the server.  If you entered the URL manually please check your spelling and try again.

[2019-Dec-19 22:33] 127.0.0.1 GET http /network3? 200 OK
[2019-Dec-19 22:33] 127.0.0.1 GET http /favicon.ico? 5xx INTERNAL SERVER ERROR
Traceback (most recent call last):
  File "/home/jon/venv/p3/lib/python3.6/site-packages/flask/app.py", line 1813, in full_dispatch_request
    rv = self.dispatch_request()
  File "/home/jon/venv/p3/lib/python3.6/site-packages/flask/app.py", line 1791, in dispatch_request
    self.raise_routing_exception(req)
  File "/home/jon/venv/p3/lib/python3.6/site-packages/flask/app.py", line 1774, in raise_routing_exception
    raise request.routing_exception
  File "/home/jon/venv/p3/lib/python3.6/site-packages/flask/ctx.py", line 336, in match_request
    self.url_adapter.match(return_rule=True)
  File "/home/jon/venv/p3/lib/python3.6/site-packages/werkzeug/routing.py", line 1581, in match
    raise NotFound()
werkzeug.exceptions.NotFound: 404 Not Found: The requested URL was not found on the server.  If you entered the URL manually please check your spelling and try again.

[2019-Dec-19 22:34] 127.0.0.1 GET http /network3? 200 OK
[2019-Dec-19 22:34] 127.0.0.1 GET http /favicon.ico? 5xx INTERNAL SERVER ERROR
Traceback (most recent call last):
  File "/home/jon/venv/p3/lib/python3.6/site-packages/flask/app.py", line 1813, in full_dispatch_request
    rv = self.dispatch_request()
  File "/home/jon/venv/p3/lib/python3.6/site-packages/flask/app.py", line 1791, in dispatch_request
    self.raise_routing_exception(req)
  File "/home/jon/venv/p3/lib/python3.6/site-packages/flask/app.py", line 1774, in raise_routing_exception
    raise request.routing_exception
  File "/home/jon/venv/p3/lib/python3.6/site-packages/flask/ctx.py", line 336, in match_request
    self.url_adapter.match(return_rule=True)
  File "/home/jon/venv/p3/lib/python3.6/site-packages/werkzeug/routing.py", line 1581, in match
    raise NotFound()
werkzeug.exceptions.NotFound: 404 Not Found: The requested URL was not found on the server.  If you entered the URL manually please check your spelling and try again.

[2019-Dec-19 22:34] 127.0.0.1 GET http /network3? 200 OK
[2019-Dec-19 22:34] 127.0.0.1 GET http /favicon.ico? 5xx INTERNAL SERVER ERROR
Traceback (most recent call last):
  File "/home/jon/venv/p3/lib/python3.6/site-packages/flask/app.py", line 1813, in full_dispatch_request
    rv = self.dispatch_request()
  File "/home/jon/venv/p3/lib/python3.6/site-packages/flask/app.py", line 1791, in dispatch_request
    self.raise_routing_exception(req)
  File "/home/jon/venv/p3/lib/python3.6/site-packages/flask/app.py", line 1774, in raise_routing_exception
    raise request.routing_exception
  File "/home/jon/venv/p3/lib/python3.6/site-packages/flask/ctx.py", line 336, in match_request
    self.url_adapter.match(return_rule=True)
  File "/home/jon/venv/p3/lib/python3.6/site-packages/werkzeug/routing.py", line 1581, in match
    raise NotFound()
werkzeug.exceptions.NotFound: 404 Not Found: The requested URL was not found on the server.  If you entered the URL manually please check your spelling and try again.

[2019-Dec-19 22:35] 127.0.0.1 GET http /network3? 200 OK
[2019-Dec-19 22:35] 127.0.0.1 GET http /favicon.ico? 5xx INTERNAL SERVER ERROR
Traceback (most recent call last):
  File "/home/jon/venv/p3/lib/python3.6/site-packages/flask/app.py", line 1813, in full_dispatch_request
    rv = self.dispatch_request()
  File "/home/jon/venv/p3/lib/python3.6/site-packages/flask/app.py", line 1791, in dispatch_request
    self.raise_routing_exception(req)
  File "/home/jon/venv/p3/lib/python3.6/site-packages/flask/app.py", line 1774, in raise_routing_exception
    raise request.routing_exception
  File "/home/jon/venv/p3/lib/python3.6/site-packages/flask/ctx.py", line 336, in match_request
    self.url_adapter.match(return_rule=True)
  File "/home/jon/venv/p3/lib/python3.6/site-packages/werkzeug/routing.py", line 1581, in match
    raise NotFound()
werkzeug.exceptions.NotFound: 404 Not Found: The requested URL was not found on the server.  If you entered the URL manually please check your spelling and try again.

[2019-Dec-19 22:38] 127.0.0.1 GET http /network3? 200 OK
[2019-Dec-19 22:38] 127.0.0.1 GET http /favicon.ico? 5xx INTERNAL SERVER ERROR
Traceback (most recent call last):
  File "/home/jon/venv/p3/lib/python3.6/site-packages/flask/app.py", line 1813, in full_dispatch_request
    rv = self.dispatch_request()
  File "/home/jon/venv/p3/lib/python3.6/site-packages/flask/app.py", line 1791, in dispatch_request
    self.raise_routing_exception(req)
  File "/home/jon/venv/p3/lib/python3.6/site-packages/flask/app.py", line 1774, in raise_routing_exception
    raise request.routing_exception
  File "/home/jon/venv/p3/lib/python3.6/site-packages/flask/ctx.py", line 336, in match_request
    self.url_adapter.match(return_rule=True)
  File "/home/jon/venv/p3/lib/python3.6/site-packages/werkzeug/routing.py", line 1581, in match
    raise NotFound()
werkzeug.exceptions.NotFound: 404 Not Found: The requested URL was not found on the server.  If you entered the URL manually please check your spelling and try again.

[2019-Dec-19 22:39] 127.0.0.1 GET http /network3? 200 OK
[2019-Dec-19 22:39] 127.0.0.1 GET http /favicon.ico? 5xx INTERNAL SERVER ERROR
Traceback (most recent call last):
  File "/home/jon/venv/p3/lib/python3.6/site-packages/flask/app.py", line 1813, in full_dispatch_request
    rv = self.dispatch_request()
  File "/home/jon/venv/p3/lib/python3.6/site-packages/flask/app.py", line 1791, in dispatch_request
    self.raise_routing_exception(req)
  File "/home/jon/venv/p3/lib/python3.6/site-packages/flask/app.py", line 1774, in raise_routing_exception
    raise request.routing_exception
  File "/home/jon/venv/p3/lib/python3.6/site-packages/flask/ctx.py", line 336, in match_request
    self.url_adapter.match(return_rule=True)
  File "/home/jon/venv/p3/lib/python3.6/site-packages/werkzeug/routing.py", line 1581, in match
    raise NotFound()
werkzeug.exceptions.NotFound: 404 Not Found: The requested URL was not found on the server.  If you entered the URL manually please check your spelling and try again.

[2019-Dec-19 22:40] 127.0.0.1 GET http /network3? 200 OK
[2019-Dec-19 22:40] 127.0.0.1 GET http /favicon.ico? 5xx INTERNAL SERVER ERROR
Traceback (most recent call last):
  File "/home/jon/venv/p3/lib/python3.6/site-packages/flask/app.py", line 1813, in full_dispatch_request
    rv = self.dispatch_request()
  File "/home/jon/venv/p3/lib/python3.6/site-packages/flask/app.py", line 1791, in dispatch_request
    self.raise_routing_exception(req)
  File "/home/jon/venv/p3/lib/python3.6/site-packages/flask/app.py", line 1774, in raise_routing_exception
    raise request.routing_exception
  File "/home/jon/venv/p3/lib/python3.6/site-packages/flask/ctx.py", line 336, in match_request
    self.url_adapter.match(return_rule=True)
  File "/home/jon/venv/p3/lib/python3.6/site-packages/werkzeug/routing.py", line 1581, in match
    raise NotFound()
werkzeug.exceptions.NotFound: 404 Not Found: The requested URL was not found on the server.  If you entered the URL manually please check your spelling and try again.

[2019-Dec-19 22:43] 127.0.0.1 GET http /network3? 200 OK
[2019-Dec-19 22:43] 127.0.0.1 GET http /favicon.ico? 5xx INTERNAL SERVER ERROR
Traceback (most recent call last):
  File "/home/jon/venv/p3/lib/python3.6/site-packages/flask/app.py", line 1813, in full_dispatch_request
    rv = self.dispatch_request()
  File "/home/jon/venv/p3/lib/python3.6/site-packages/flask/app.py", line 1791, in dispatch_request
    self.raise_routing_exception(req)
  File "/home/jon/venv/p3/lib/python3.6/site-packages/flask/app.py", line 1774, in raise_routing_exception
    raise request.routing_exception
  File "/home/jon/venv/p3/lib/python3.6/site-packages/flask/ctx.py", line 336, in match_request
    self.url_adapter.match(return_rule=True)
  File "/home/jon/venv/p3/lib/python3.6/site-packages/werkzeug/routing.py", line 1581, in match
    raise NotFound()
werkzeug.exceptions.NotFound: 404 Not Found: The requested URL was not found on the server.  If you entered the URL manually please check your spelling and try again.

[2019-Dec-19 22:44] 127.0.0.1 GET http /network3? 200 OK
[2019-Dec-19 22:44] 127.0.0.1 GET http /favicon.ico? 5xx INTERNAL SERVER ERROR
Traceback (most recent call last):
  File "/home/jon/venv/p3/lib/python3.6/site-packages/flask/app.py", line 1813, in full_dispatch_request
    rv = self.dispatch_request()
  File "/home/jon/venv/p3/lib/python3.6/site-packages/flask/app.py", line 1791, in dispatch_request
    self.raise_routing_exception(req)
  File "/home/jon/venv/p3/lib/python3.6/site-packages/flask/app.py", line 1774, in raise_routing_exception
    raise request.routing_exception
  File "/home/jon/venv/p3/lib/python3.6/site-packages/flask/ctx.py", line 336, in match_request
    self.url_adapter.match(return_rule=True)
  File "/home/jon/venv/p3/lib/python3.6/site-packages/werkzeug/routing.py", line 1581, in match
    raise NotFound()
werkzeug.exceptions.NotFound: 404 Not Found: The requested URL was not found on the server.  If you entered the URL manually please check your spelling and try again.

[2019-Dec-19 22:44] 127.0.0.1 GET http /network3? 200 OK
[2019-Dec-19 22:45] 127.0.0.1 GET http /favicon.ico? 5xx INTERNAL SERVER ERROR
Traceback (most recent call last):
  File "/home/jon/venv/p3/lib/python3.6/site-packages/flask/app.py", line 1813, in full_dispatch_request
    rv = self.dispatch_request()
  File "/home/jon/venv/p3/lib/python3.6/site-packages/flask/app.py", line 1791, in dispatch_request
    self.raise_routing_exception(req)
  File "/home/jon/venv/p3/lib/python3.6/site-packages/flask/app.py", line 1774, in raise_routing_exception
    raise request.routing_exception
  File "/home/jon/venv/p3/lib/python3.6/site-packages/flask/ctx.py", line 336, in match_request
    self.url_adapter.match(return_rule=True)
  File "/home/jon/venv/p3/lib/python3.6/site-packages/werkzeug/routing.py", line 1581, in match
    raise NotFound()
werkzeug.exceptions.NotFound: 404 Not Found: The requested URL was not found on the server.  If you entered the URL manually please check your spelling and try again.

[2019-Dec-19 22:54] 127.0.0.1 GET http /network3? 200 OK
[2019-Dec-19 22:54] 127.0.0.1 GET http /favicon.ico? 5xx INTERNAL SERVER ERROR
Traceback (most recent call last):
  File "/home/jon/venv/p3/lib/python3.6/site-packages/flask/app.py", line 1813, in full_dispatch_request
    rv = self.dispatch_request()
  File "/home/jon/venv/p3/lib/python3.6/site-packages/flask/app.py", line 1791, in dispatch_request
    self.raise_routing_exception(req)
  File "/home/jon/venv/p3/lib/python3.6/site-packages/flask/app.py", line 1774, in raise_routing_exception
    raise request.routing_exception
  File "/home/jon/venv/p3/lib/python3.6/site-packages/flask/ctx.py", line 336, in match_request
    self.url_adapter.match(return_rule=True)
  File "/home/jon/venv/p3/lib/python3.6/site-packages/werkzeug/routing.py", line 1581, in match
    raise NotFound()
werkzeug.exceptions.NotFound: 404 Not Found: The requested URL was not found on the server.  If you entered the URL manually please check your spelling and try again.

[2019-Dec-19 22:58] 127.0.0.1 GET http /network3? 200 OK
[2019-Dec-19 22:58] 127.0.0.1 GET http /favicon.ico? 5xx INTERNAL SERVER ERROR
Traceback (most recent call last):
  File "/home/jon/venv/p3/lib/python3.6/site-packages/flask/app.py", line 1813, in full_dispatch_request
    rv = self.dispatch_request()
  File "/home/jon/venv/p3/lib/python3.6/site-packages/flask/app.py", line 1791, in dispatch_request
    self.raise_routing_exception(req)
  File "/home/jon/venv/p3/lib/python3.6/site-packages/flask/app.py", line 1774, in raise_routing_exception
    raise request.routing_exception
  File "/home/jon/venv/p3/lib/python3.6/site-packages/flask/ctx.py", line 336, in match_request
    self.url_adapter.match(return_rule=True)
  File "/home/jon/venv/p3/lib/python3.6/site-packages/werkzeug/routing.py", line 1581, in match
    raise NotFound()
werkzeug.exceptions.NotFound: 404 Not Found: The requested URL was not found on the server.  If you entered the URL manually please check your spelling and try again.

[2019-Dec-19 23:02] 127.0.0.1 GET http /network3? 200 OK
[2019-Dec-19 23:02] 127.0.0.1 GET http /favicon.ico? 5xx INTERNAL SERVER ERROR
Traceback (most recent call last):
  File "/home/jon/venv/p3/lib/python3.6/site-packages/flask/app.py", line 1813, in full_dispatch_request
    rv = self.dispatch_request()
  File "/home/jon/venv/p3/lib/python3.6/site-packages/flask/app.py", line 1791, in dispatch_request
    self.raise_routing_exception(req)
  File "/home/jon/venv/p3/lib/python3.6/site-packages/flask/app.py", line 1774, in raise_routing_exception
    raise request.routing_exception
  File "/home/jon/venv/p3/lib/python3.6/site-packages/flask/ctx.py", line 336, in match_request
    self.url_adapter.match(return_rule=True)
  File "/home/jon/venv/p3/lib/python3.6/site-packages/werkzeug/routing.py", line 1581, in match
    raise NotFound()
werkzeug.exceptions.NotFound: 404 Not Found: The requested URL was not found on the server.  If you entered the URL manually please check your spelling and try again.

[2019-Dec-19 23:03] 127.0.0.1 GET http /network3? 200 OK
[2019-Dec-19 23:03] 127.0.0.1 GET http /favicon.ico? 5xx INTERNAL SERVER ERROR
Traceback (most recent call last):
  File "/home/jon/venv/p3/lib/python3.6/site-packages/flask/app.py", line 1813, in full_dispatch_request
    rv = self.dispatch_request()
  File "/home/jon/venv/p3/lib/python3.6/site-packages/flask/app.py", line 1791, in dispatch_request
    self.raise_routing_exception(req)
  File "/home/jon/venv/p3/lib/python3.6/site-packages/flask/app.py", line 1774, in raise_routing_exception
    raise request.routing_exception
  File "/home/jon/venv/p3/lib/python3.6/site-packages/flask/ctx.py", line 336, in match_request
    self.url_adapter.match(return_rule=True)
  File "/home/jon/venv/p3/lib/python3.6/site-packages/werkzeug/routing.py", line 1581, in match
    raise NotFound()
werkzeug.exceptions.NotFound: 404 Not Found: The requested URL was not found on the server.  If you entered the URL manually please check your spelling and try again.

[2019-Dec-19 23:04] 127.0.0.1 GET http /network3? 200 OK
[2019-Dec-19 23:04] 127.0.0.1 GET http /favicon.ico? 5xx INTERNAL SERVER ERROR
Traceback (most recent call last):
  File "/home/jon/venv/p3/lib/python3.6/site-packages/flask/app.py", line 1813, in full_dispatch_request
    rv = self.dispatch_request()
  File "/home/jon/venv/p3/lib/python3.6/site-packages/flask/app.py", line 1791, in dispatch_request
    self.raise_routing_exception(req)
  File "/home/jon/venv/p3/lib/python3.6/site-packages/flask/app.py", line 1774, in raise_routing_exception
    raise request.routing_exception
  File "/home/jon/venv/p3/lib/python3.6/site-packages/flask/ctx.py", line 336, in match_request
    self.url_adapter.match(return_rule=True)
  File "/home/jon/venv/p3/lib/python3.6/site-packages/werkzeug/routing.py", line 1581, in match
    raise NotFound()
werkzeug.exceptions.NotFound: 404 Not Found: The requested URL was not found on the server.  If you entered the URL manually please check your spelling and try again.

[2019-Dec-19 23:04] 127.0.0.1 GET http /network3? 200 OK
[2019-Dec-19 23:04] 127.0.0.1 GET http /favicon.ico? 5xx INTERNAL SERVER ERROR
Traceback (most recent call last):
  File "/home/jon/venv/p3/lib/python3.6/site-packages/flask/app.py", line 1813, in full_dispatch_request
    rv = self.dispatch_request()
  File "/home/jon/venv/p3/lib/python3.6/site-packages/flask/app.py", line 1791, in dispatch_request
    self.raise_routing_exception(req)
  File "/home/jon/venv/p3/lib/python3.6/site-packages/flask/app.py", line 1774, in raise_routing_exception
    raise request.routing_exception
  File "/home/jon/venv/p3/lib/python3.6/site-packages/flask/ctx.py", line 336, in match_request
    self.url_adapter.match(return_rule=True)
  File "/home/jon/venv/p3/lib/python3.6/site-packages/werkzeug/routing.py", line 1581, in match
    raise NotFound()
werkzeug.exceptions.NotFound: 404 Not Found: The requested URL was not found on the server.  If you entered the URL manually please check your spelling and try again.

[2019-Dec-19 23:05] 127.0.0.1 GET http /network3? 200 OK
[2019-Dec-19 23:05] 127.0.0.1 GET http /favicon.ico? 5xx INTERNAL SERVER ERROR
Traceback (most recent call last):
  File "/home/jon/venv/p3/lib/python3.6/site-packages/flask/app.py", line 1813, in full_dispatch_request
    rv = self.dispatch_request()
  File "/home/jon/venv/p3/lib/python3.6/site-packages/flask/app.py", line 1791, in dispatch_request
    self.raise_routing_exception(req)
  File "/home/jon/venv/p3/lib/python3.6/site-packages/flask/app.py", line 1774, in raise_routing_exception
    raise request.routing_exception
  File "/home/jon/venv/p3/lib/python3.6/site-packages/flask/ctx.py", line 336, in match_request
    self.url_adapter.match(return_rule=True)
  File "/home/jon/venv/p3/lib/python3.6/site-packages/werkzeug/routing.py", line 1581, in match
    raise NotFound()
werkzeug.exceptions.NotFound: 404 Not Found: The requested URL was not found on the server.  If you entered the URL manually please check your spelling and try again.

[2019-Dec-19 23:05] 127.0.0.1 GET http /network3? 200 OK
[2019-Dec-19 23:05] 127.0.0.1 GET http /favicon.ico? 5xx INTERNAL SERVER ERROR
Traceback (most recent call last):
  File "/home/jon/venv/p3/lib/python3.6/site-packages/flask/app.py", line 1813, in full_dispatch_request
    rv = self.dispatch_request()
  File "/home/jon/venv/p3/lib/python3.6/site-packages/flask/app.py", line 1791, in dispatch_request
    self.raise_routing_exception(req)
  File "/home/jon/venv/p3/lib/python3.6/site-packages/flask/app.py", line 1774, in raise_routing_exception
    raise request.routing_exception
  File "/home/jon/venv/p3/lib/python3.6/site-packages/flask/ctx.py", line 336, in match_request
    self.url_adapter.match(return_rule=True)
  File "/home/jon/venv/p3/lib/python3.6/site-packages/werkzeug/routing.py", line 1581, in match
    raise NotFound()
werkzeug.exceptions.NotFound: 404 Not Found: The requested URL was not found on the server.  If you entered the URL manually please check your spelling and try again.

[2019-Dec-19 23:06] 127.0.0.1 GET http /network3? 200 OK
[2019-Dec-19 23:06] 127.0.0.1 GET http /favicon.ico? 5xx INTERNAL SERVER ERROR
Traceback (most recent call last):
  File "/home/jon/venv/p3/lib/python3.6/site-packages/flask/app.py", line 1813, in full_dispatch_request
    rv = self.dispatch_request()
  File "/home/jon/venv/p3/lib/python3.6/site-packages/flask/app.py", line 1791, in dispatch_request
    self.raise_routing_exception(req)
  File "/home/jon/venv/p3/lib/python3.6/site-packages/flask/app.py", line 1774, in raise_routing_exception
    raise request.routing_exception
  File "/home/jon/venv/p3/lib/python3.6/site-packages/flask/ctx.py", line 336, in match_request
    self.url_adapter.match(return_rule=True)
  File "/home/jon/venv/p3/lib/python3.6/site-packages/werkzeug/routing.py", line 1581, in match
    raise NotFound()
werkzeug.exceptions.NotFound: 404 Not Found: The requested URL was not found on the server.  If you entered the URL manually please check your spelling and try again.

[2019-Dec-19 23:06] 127.0.0.1 GET http /network3? 200 OK
[2019-Dec-19 23:06] 127.0.0.1 GET http /favicon.ico? 5xx INTERNAL SERVER ERROR
Traceback (most recent call last):
  File "/home/jon/venv/p3/lib/python3.6/site-packages/flask/app.py", line 1813, in full_dispatch_request
    rv = self.dispatch_request()
  File "/home/jon/venv/p3/lib/python3.6/site-packages/flask/app.py", line 1791, in dispatch_request
    self.raise_routing_exception(req)
  File "/home/jon/venv/p3/lib/python3.6/site-packages/flask/app.py", line 1774, in raise_routing_exception
    raise request.routing_exception
  File "/home/jon/venv/p3/lib/python3.6/site-packages/flask/ctx.py", line 336, in match_request
    self.url_adapter.match(return_rule=True)
  File "/home/jon/venv/p3/lib/python3.6/site-packages/werkzeug/routing.py", line 1581, in match
    raise NotFound()
werkzeug.exceptions.NotFound: 404 Not Found: The requested URL was not found on the server.  If you entered the URL manually please check your spelling and try again.

[2019-Dec-19 23:07] 127.0.0.1 GET http /network3? 200 OK
[2019-Dec-19 23:07] 127.0.0.1 GET http /favicon.ico? 5xx INTERNAL SERVER ERROR
Traceback (most recent call last):
  File "/home/jon/venv/p3/lib/python3.6/site-packages/flask/app.py", line 1813, in full_dispatch_request
    rv = self.dispatch_request()
  File "/home/jon/venv/p3/lib/python3.6/site-packages/flask/app.py", line 1791, in dispatch_request
    self.raise_routing_exception(req)
  File "/home/jon/venv/p3/lib/python3.6/site-packages/flask/app.py", line 1774, in raise_routing_exception
    raise request.routing_exception
  File "/home/jon/venv/p3/lib/python3.6/site-packages/flask/ctx.py", line 336, in match_request
    self.url_adapter.match(return_rule=True)
  File "/home/jon/venv/p3/lib/python3.6/site-packages/werkzeug/routing.py", line 1581, in match
    raise NotFound()
werkzeug.exceptions.NotFound: 404 Not Found: The requested URL was not found on the server.  If you entered the URL manually please check your spelling and try again.

[2019-Dec-19 23:07] 127.0.0.1 GET http /network3? 200 OK
[2019-Dec-19 23:07] 127.0.0.1 GET http /favicon.ico? 5xx INTERNAL SERVER ERROR
Traceback (most recent call last):
  File "/home/jon/venv/p3/lib/python3.6/site-packages/flask/app.py", line 1813, in full_dispatch_request
    rv = self.dispatch_request()
  File "/home/jon/venv/p3/lib/python3.6/site-packages/flask/app.py", line 1791, in dispatch_request
    self.raise_routing_exception(req)
  File "/home/jon/venv/p3/lib/python3.6/site-packages/flask/app.py", line 1774, in raise_routing_exception
    raise request.routing_exception
  File "/home/jon/venv/p3/lib/python3.6/site-packages/flask/ctx.py", line 336, in match_request
    self.url_adapter.match(return_rule=True)
  File "/home/jon/venv/p3/lib/python3.6/site-packages/werkzeug/routing.py", line 1581, in match
    raise NotFound()
werkzeug.exceptions.NotFound: 404 Not Found: The requested URL was not found on the server.  If you entered the URL manually please check your spelling and try again.

[2019-Dec-19 23:08] 127.0.0.1 GET http /network3? 200 OK
[2019-Dec-19 23:08] 127.0.0.1 GET http /favicon.ico? 5xx INTERNAL SERVER ERROR
Traceback (most recent call last):
  File "/home/jon/venv/p3/lib/python3.6/site-packages/flask/app.py", line 1813, in full_dispatch_request
    rv = self.dispatch_request()
  File "/home/jon/venv/p3/lib/python3.6/site-packages/flask/app.py", line 1791, in dispatch_request
    self.raise_routing_exception(req)
  File "/home/jon/venv/p3/lib/python3.6/site-packages/flask/app.py", line 1774, in raise_routing_exception
    raise request.routing_exception
  File "/home/jon/venv/p3/lib/python3.6/site-packages/flask/ctx.py", line 336, in match_request
    self.url_adapter.match(return_rule=True)
  File "/home/jon/venv/p3/lib/python3.6/site-packages/werkzeug/routing.py", line 1581, in match
    raise NotFound()
werkzeug.exceptions.NotFound: 404 Not Found: The requested URL was not found on the server.  If you entered the URL manually please check your spelling and try again.

[2019-Dec-19 23:08] 127.0.0.1 GET http /network3? 200 OK
[2019-Dec-19 23:08] 127.0.0.1 GET http /favicon.ico? 5xx INTERNAL SERVER ERROR
Traceback (most recent call last):
  File "/home/jon/venv/p3/lib/python3.6/site-packages/flask/app.py", line 1813, in full_dispatch_request
    rv = self.dispatch_request()
  File "/home/jon/venv/p3/lib/python3.6/site-packages/flask/app.py", line 1791, in dispatch_request
    self.raise_routing_exception(req)
  File "/home/jon/venv/p3/lib/python3.6/site-packages/flask/app.py", line 1774, in raise_routing_exception
    raise request.routing_exception
  File "/home/jon/venv/p3/lib/python3.6/site-packages/flask/ctx.py", line 336, in match_request
    self.url_adapter.match(return_rule=True)
  File "/home/jon/venv/p3/lib/python3.6/site-packages/werkzeug/routing.py", line 1581, in match
    raise NotFound()
werkzeug.exceptions.NotFound: 404 Not Found: The requested URL was not found on the server.  If you entered the URL manually please check your spelling and try again.

[2019-Dec-19 23:09] 127.0.0.1 GET http /network3? 200 OK
[2019-Dec-19 23:09] 127.0.0.1 GET http /favicon.ico? 5xx INTERNAL SERVER ERROR
Traceback (most recent call last):
  File "/home/jon/venv/p3/lib/python3.6/site-packages/flask/app.py", line 1813, in full_dispatch_request
    rv = self.dispatch_request()
  File "/home/jon/venv/p3/lib/python3.6/site-packages/flask/app.py", line 1791, in dispatch_request
    self.raise_routing_exception(req)
  File "/home/jon/venv/p3/lib/python3.6/site-packages/flask/app.py", line 1774, in raise_routing_exception
    raise request.routing_exception
  File "/home/jon/venv/p3/lib/python3.6/site-packages/flask/ctx.py", line 336, in match_request
    self.url_adapter.match(return_rule=True)
  File "/home/jon/venv/p3/lib/python3.6/site-packages/werkzeug/routing.py", line 1581, in match
    raise NotFound()
werkzeug.exceptions.NotFound: 404 Not Found: The requested URL was not found on the server.  If you entered the URL manually please check your spelling and try again.

[2019-Dec-19 23:10] 127.0.0.1 GET http /network3? 200 OK
[2019-Dec-19 23:10] 127.0.0.1 GET http /favicon.ico? 5xx INTERNAL SERVER ERROR
Traceback (most recent call last):
  File "/home/jon/venv/p3/lib/python3.6/site-packages/flask/app.py", line 1813, in full_dispatch_request
    rv = self.dispatch_request()
  File "/home/jon/venv/p3/lib/python3.6/site-packages/flask/app.py", line 1791, in dispatch_request
    self.raise_routing_exception(req)
  File "/home/jon/venv/p3/lib/python3.6/site-packages/flask/app.py", line 1774, in raise_routing_exception
    raise request.routing_exception
  File "/home/jon/venv/p3/lib/python3.6/site-packages/flask/ctx.py", line 336, in match_request
    self.url_adapter.match(return_rule=True)
  File "/home/jon/venv/p3/lib/python3.6/site-packages/werkzeug/routing.py", line 1581, in match
    raise NotFound()
werkzeug.exceptions.NotFound: 404 Not Found: The requested URL was not found on the server.  If you entered the URL manually please check your spelling and try again.

[2019-Dec-19 23:11] 127.0.0.1 GET http /network3? 200 OK
[2019-Dec-19 23:11] 127.0.0.1 GET http /favicon.ico? 5xx INTERNAL SERVER ERROR
Traceback (most recent call last):
  File "/home/jon/venv/p3/lib/python3.6/site-packages/flask/app.py", line 1813, in full_dispatch_request
    rv = self.dispatch_request()
  File "/home/jon/venv/p3/lib/python3.6/site-packages/flask/app.py", line 1791, in dispatch_request
    self.raise_routing_exception(req)
  File "/home/jon/venv/p3/lib/python3.6/site-packages/flask/app.py", line 1774, in raise_routing_exception
    raise request.routing_exception
  File "/home/jon/venv/p3/lib/python3.6/site-packages/flask/ctx.py", line 336, in match_request
    self.url_adapter.match(return_rule=True)
  File "/home/jon/venv/p3/lib/python3.6/site-packages/werkzeug/routing.py", line 1581, in match
    raise NotFound()
werkzeug.exceptions.NotFound: 404 Not Found: The requested URL was not found on the server.  If you entered the URL manually please check your spelling and try again.

[2019-Dec-19 23:17] 127.0.0.1 GET http /network3? 200 OK
[2019-Dec-19 23:17] 127.0.0.1 GET http /favicon.ico? 5xx INTERNAL SERVER ERROR
Traceback (most recent call last):
  File "/home/jon/venv/p3/lib/python3.6/site-packages/flask/app.py", line 1813, in full_dispatch_request
    rv = self.dispatch_request()
  File "/home/jon/venv/p3/lib/python3.6/site-packages/flask/app.py", line 1791, in dispatch_request
    self.raise_routing_exception(req)
  File "/home/jon/venv/p3/lib/python3.6/site-packages/flask/app.py", line 1774, in raise_routing_exception
    raise request.routing_exception
  File "/home/jon/venv/p3/lib/python3.6/site-packages/flask/ctx.py", line 336, in match_request
    self.url_adapter.match(return_rule=True)
  File "/home/jon/venv/p3/lib/python3.6/site-packages/werkzeug/routing.py", line 1581, in match
    raise NotFound()
werkzeug.exceptions.NotFound: 404 Not Found: The requested URL was not found on the server.  If you entered the URL manually please check your spelling and try again.

[2019-Dec-19 23:19] 127.0.0.1 GET http /network3? 200 OK
[2019-Dec-19 23:19] 127.0.0.1 GET http /favicon.ico? 5xx INTERNAL SERVER ERROR
Traceback (most recent call last):
  File "/home/jon/venv/p3/lib/python3.6/site-packages/flask/app.py", line 1813, in full_dispatch_request
    rv = self.dispatch_request()
  File "/home/jon/venv/p3/lib/python3.6/site-packages/flask/app.py", line 1791, in dispatch_request
    self.raise_routing_exception(req)
  File "/home/jon/venv/p3/lib/python3.6/site-packages/flask/app.py", line 1774, in raise_routing_exception
    raise request.routing_exception
  File "/home/jon/venv/p3/lib/python3.6/site-packages/flask/ctx.py", line 336, in match_request
    self.url_adapter.match(return_rule=True)
  File "/home/jon/venv/p3/lib/python3.6/site-packages/werkzeug/routing.py", line 1581, in match
    raise NotFound()
werkzeug.exceptions.NotFound: 404 Not Found: The requested URL was not found on the server.  If you entered the URL manually please check your spelling and try again.

[2019-Dec-19 23:24] 127.0.0.1 GET http /network3? 200 OK
[2019-Dec-19 23:24] 127.0.0.1 GET http /favicon.ico? 5xx INTERNAL SERVER ERROR
Traceback (most recent call last):
  File "/home/jon/venv/p3/lib/python3.6/site-packages/flask/app.py", line 1813, in full_dispatch_request
    rv = self.dispatch_request()
  File "/home/jon/venv/p3/lib/python3.6/site-packages/flask/app.py", line 1791, in dispatch_request
    self.raise_routing_exception(req)
  File "/home/jon/venv/p3/lib/python3.6/site-packages/flask/app.py", line 1774, in raise_routing_exception
    raise request.routing_exception
  File "/home/jon/venv/p3/lib/python3.6/site-packages/flask/ctx.py", line 336, in match_request
    self.url_adapter.match(return_rule=True)
  File "/home/jon/venv/p3/lib/python3.6/site-packages/werkzeug/routing.py", line 1581, in match
    raise NotFound()
werkzeug.exceptions.NotFound: 404 Not Found: The requested URL was not found on the server.  If you entered the URL manually please check your spelling and try again.

[2019-Dec-19 23:24] 127.0.0.1 GET http /network3? 200 OK
[2019-Dec-19 23:24] 127.0.0.1 GET http /favicon.ico? 5xx INTERNAL SERVER ERROR
Traceback (most recent call last):
  File "/home/jon/venv/p3/lib/python3.6/site-packages/flask/app.py", line 1813, in full_dispatch_request
    rv = self.dispatch_request()
  File "/home/jon/venv/p3/lib/python3.6/site-packages/flask/app.py", line 1791, in dispatch_request
    self.raise_routing_exception(req)
  File "/home/jon/venv/p3/lib/python3.6/site-packages/flask/app.py", line 1774, in raise_routing_exception
    raise request.routing_exception
  File "/home/jon/venv/p3/lib/python3.6/site-packages/flask/ctx.py", line 336, in match_request
    self.url_adapter.match(return_rule=True)
  File "/home/jon/venv/p3/lib/python3.6/site-packages/werkzeug/routing.py", line 1581, in match
    raise NotFound()
werkzeug.exceptions.NotFound: 404 Not Found: The requested URL was not found on the server.  If you entered the URL manually please check your spelling and try again.

[2019-Dec-19 23:25] 127.0.0.1 GET http /network3? 200 OK
[2019-Dec-19 23:25] 127.0.0.1 GET http /favicon.ico? 5xx INTERNAL SERVER ERROR
Traceback (most recent call last):
  File "/home/jon/venv/p3/lib/python3.6/site-packages/flask/app.py", line 1813, in full_dispatch_request
    rv = self.dispatch_request()
  File "/home/jon/venv/p3/lib/python3.6/site-packages/flask/app.py", line 1791, in dispatch_request
    self.raise_routing_exception(req)
  File "/home/jon/venv/p3/lib/python3.6/site-packages/flask/app.py", line 1774, in raise_routing_exception
    raise request.routing_exception
  File "/home/jon/venv/p3/lib/python3.6/site-packages/flask/ctx.py", line 336, in match_request
    self.url_adapter.match(return_rule=True)
  File "/home/jon/venv/p3/lib/python3.6/site-packages/werkzeug/routing.py", line 1581, in match
    raise NotFound()
werkzeug.exceptions.NotFound: 404 Not Found: The requested URL was not found on the server.  If you entered the URL manually please check your spelling and try again.

[2019-Dec-19 23:30] 127.0.0.1 GET http /network3? 200 OK
[2019-Dec-19 23:30] 127.0.0.1 GET http /favicon.ico? 5xx INTERNAL SERVER ERROR
Traceback (most recent call last):
  File "/home/jon/venv/p3/lib/python3.6/site-packages/flask/app.py", line 1813, in full_dispatch_request
    rv = self.dispatch_request()
  File "/home/jon/venv/p3/lib/python3.6/site-packages/flask/app.py", line 1791, in dispatch_request
    self.raise_routing_exception(req)
  File "/home/jon/venv/p3/lib/python3.6/site-packages/flask/app.py", line 1774, in raise_routing_exception
    raise request.routing_exception
  File "/home/jon/venv/p3/lib/python3.6/site-packages/flask/ctx.py", line 336, in match_request
    self.url_adapter.match(return_rule=True)
  File "/home/jon/venv/p3/lib/python3.6/site-packages/werkzeug/routing.py", line 1581, in match
    raise NotFound()
werkzeug.exceptions.NotFound: 404 Not Found: The requested URL was not found on the server.  If you entered the URL manually please check your spelling and try again.

[2019-Dec-19 23:32] 127.0.0.1 GET http /? 200 OK
[2019-Dec-19 23:32] 127.0.0.1 GET http /static/css/auto-complete.css? 200 OK
[2019-Dec-19 23:32] 127.0.0.1 GET http /static/css/signin.css? 200 OK
[2019-Dec-19 23:32] 127.0.0.1 GET http /static/js/script.js? 200 OK
[2019-Dec-19 23:32] 127.0.0.1 GET http /static/js/fetch.js? 200 OK
[2019-Dec-19 23:32] 127.0.0.1 GET http /static/js/jquery-1.9.0.js? 200 OK
[2019-Dec-19 23:32] 127.0.0.1 GET http /static/js/auto-complete.min.js? 200 OK
[2019-Dec-19 23:32] 127.0.0.1 GET http /static/css/my_style.css? 200 OK
[2019-Dec-19 23:32] 127.0.0.1 GET http /static/css/scss_css.css? 200 OK
[2019-Dec-19 23:32] 127.0.0.1 GET http /static/data/data.json? 200 OK
[2019-Dec-19 23:32] 127.0.0.1 GET http /static/js/autocomplete.js? 200 OK
[2019-Dec-19 23:32] 127.0.0.1 GET http /static/css/scss_css.css.map? 200 OK
[2019-Dec-19 23:32] 127.0.0.1 GET http /network2? 200 OK
[2019-Dec-19 23:32] 127.0.0.1 GET http /d3_data2? 200 OK
[2019-Dec-19 23:32] 127.0.0.1 GET http /favicon.ico? 5xx INTERNAL SERVER ERROR
Traceback (most recent call last):
  File "/home/jon/venv/p3/lib/python3.6/site-packages/flask/app.py", line 1813, in full_dispatch_request
    rv = self.dispatch_request()
  File "/home/jon/venv/p3/lib/python3.6/site-packages/flask/app.py", line 1791, in dispatch_request
    self.raise_routing_exception(req)
  File "/home/jon/venv/p3/lib/python3.6/site-packages/flask/app.py", line 1774, in raise_routing_exception
    raise request.routing_exception
  File "/home/jon/venv/p3/lib/python3.6/site-packages/flask/ctx.py", line 336, in match_request
    self.url_adapter.match(return_rule=True)
  File "/home/jon/venv/p3/lib/python3.6/site-packages/werkzeug/routing.py", line 1581, in match
    raise NotFound()
werkzeug.exceptions.NotFound: 404 Not Found: The requested URL was not found on the server.  If you entered the URL manually please check your spelling and try again.

[2019-Dec-19 23:34] 127.0.0.1 GET http /? 200 OK
[2019-Dec-19 23:34] 127.0.0.1 GET http /static/css/auto-complete.css? 200 OK
[2019-Dec-19 23:34] 127.0.0.1 GET http /static/css/signin.css? 200 OK
[2019-Dec-19 23:34] 127.0.0.1 GET http /static/js/script.js? 200 OK
[2019-Dec-19 23:34] 127.0.0.1 GET http /static/js/jquery-1.9.0.js? 200 OK
[2019-Dec-19 23:34] 127.0.0.1 GET http /static/js/fetch.js? 200 OK
[2019-Dec-19 23:34] 127.0.0.1 GET http /static/css/my_style.css? 200 OK
[2019-Dec-19 23:34] 127.0.0.1 GET http /static/css/scss_css.css? 200 OK
[2019-Dec-19 23:34] 127.0.0.1 GET http /static/js/auto-complete.min.js? 200 OK
[2019-Dec-19 23:34] 127.0.0.1 GET http /static/data/data.json? 200 OK
[2019-Dec-19 23:34] 127.0.0.1 GET http /static/js/autocomplete.js? 200 OK
[2019-Dec-19 23:34] 127.0.0.1 GET http /static/css/scss_css.css.map? 200 OK
[2019-Dec-19 23:34] 127.0.0.1 GET http /network3? 200 OK
[2019-Dec-19 23:34] 127.0.0.1 GET http /favicon.ico? 5xx INTERNAL SERVER ERROR
Traceback (most recent call last):
  File "/home/jon/venv/p3/lib/python3.6/site-packages/flask/app.py", line 1813, in full_dispatch_request
    rv = self.dispatch_request()
  File "/home/jon/venv/p3/lib/python3.6/site-packages/flask/app.py", line 1791, in dispatch_request
    self.raise_routing_exception(req)
  File "/home/jon/venv/p3/lib/python3.6/site-packages/flask/app.py", line 1774, in raise_routing_exception
    raise request.routing_exception
  File "/home/jon/venv/p3/lib/python3.6/site-packages/flask/ctx.py", line 336, in match_request
    self.url_adapter.match(return_rule=True)
  File "/home/jon/venv/p3/lib/python3.6/site-packages/werkzeug/routing.py", line 1581, in match
    raise NotFound()
werkzeug.exceptions.NotFound: 404 Not Found: The requested URL was not found on the server.  If you entered the URL manually please check your spelling and try again.

[2019-Dec-19 23:39] 127.0.0.1 GET http /network3? 200 OK
[2019-Dec-19 23:39] 127.0.0.1 GET http /favicon.ico? 5xx INTERNAL SERVER ERROR
Traceback (most recent call last):
  File "/home/jon/venv/p3/lib/python3.6/site-packages/flask/app.py", line 1813, in full_dispatch_request
    rv = self.dispatch_request()
  File "/home/jon/venv/p3/lib/python3.6/site-packages/flask/app.py", line 1791, in dispatch_request
    self.raise_routing_exception(req)
  File "/home/jon/venv/p3/lib/python3.6/site-packages/flask/app.py", line 1774, in raise_routing_exception
    raise request.routing_exception
  File "/home/jon/venv/p3/lib/python3.6/site-packages/flask/ctx.py", line 336, in match_request
    self.url_adapter.match(return_rule=True)
  File "/home/jon/venv/p3/lib/python3.6/site-packages/werkzeug/routing.py", line 1581, in match
    raise NotFound()
werkzeug.exceptions.NotFound: 404 Not Found: The requested URL was not found on the server.  If you entered the URL manually please check your spelling and try again.

[2019-Dec-19 23:40] 127.0.0.1 GET http /network3? 200 OK
[2019-Dec-19 23:40] 127.0.0.1 GET http /favicon.ico? 5xx INTERNAL SERVER ERROR
Traceback (most recent call last):
  File "/home/jon/venv/p3/lib/python3.6/site-packages/flask/app.py", line 1813, in full_dispatch_request
    rv = self.dispatch_request()
  File "/home/jon/venv/p3/lib/python3.6/site-packages/flask/app.py", line 1791, in dispatch_request
    self.raise_routing_exception(req)
  File "/home/jon/venv/p3/lib/python3.6/site-packages/flask/app.py", line 1774, in raise_routing_exception
    raise request.routing_exception
  File "/home/jon/venv/p3/lib/python3.6/site-packages/flask/ctx.py", line 336, in match_request
    self.url_adapter.match(return_rule=True)
  File "/home/jon/venv/p3/lib/python3.6/site-packages/werkzeug/routing.py", line 1581, in match
    raise NotFound()
werkzeug.exceptions.NotFound: 404 Not Found: The requested URL was not found on the server.  If you entered the URL manually please check your spelling and try again.

[2019-Dec-19 23:43] 127.0.0.1 GET http /network3? 200 OK
[2019-Dec-19 23:43] 127.0.0.1 GET http /favicon.ico? 5xx INTERNAL SERVER ERROR
Traceback (most recent call last):
  File "/home/jon/venv/p3/lib/python3.6/site-packages/flask/app.py", line 1813, in full_dispatch_request
    rv = self.dispatch_request()
  File "/home/jon/venv/p3/lib/python3.6/site-packages/flask/app.py", line 1791, in dispatch_request
    self.raise_routing_exception(req)
  File "/home/jon/venv/p3/lib/python3.6/site-packages/flask/app.py", line 1774, in raise_routing_exception
    raise request.routing_exception
  File "/home/jon/venv/p3/lib/python3.6/site-packages/flask/ctx.py", line 336, in match_request
    self.url_adapter.match(return_rule=True)
  File "/home/jon/venv/p3/lib/python3.6/site-packages/werkzeug/routing.py", line 1581, in match
    raise NotFound()
werkzeug.exceptions.NotFound: 404 Not Found: The requested URL was not found on the server.  If you entered the URL manually please check your spelling and try again.

[2019-Dec-19 23:44] 127.0.0.1 GET http /network3? 200 OK
[2019-Dec-19 23:44] 127.0.0.1 GET http /favicon.ico? 5xx INTERNAL SERVER ERROR
Traceback (most recent call last):
  File "/home/jon/venv/p3/lib/python3.6/site-packages/flask/app.py", line 1813, in full_dispatch_request
    rv = self.dispatch_request()
  File "/home/jon/venv/p3/lib/python3.6/site-packages/flask/app.py", line 1791, in dispatch_request
    self.raise_routing_exception(req)
  File "/home/jon/venv/p3/lib/python3.6/site-packages/flask/app.py", line 1774, in raise_routing_exception
    raise request.routing_exception
  File "/home/jon/venv/p3/lib/python3.6/site-packages/flask/ctx.py", line 336, in match_request
    self.url_adapter.match(return_rule=True)
  File "/home/jon/venv/p3/lib/python3.6/site-packages/werkzeug/routing.py", line 1581, in match
    raise NotFound()
werkzeug.exceptions.NotFound: 404 Not Found: The requested URL was not found on the server.  If you entered the URL manually please check your spelling and try again.

[2019-Dec-19 23:45] 127.0.0.1 GET http /network3? 200 OK
[2019-Dec-19 23:45] 127.0.0.1 GET http /favicon.ico? 5xx INTERNAL SERVER ERROR
Traceback (most recent call last):
  File "/home/jon/venv/p3/lib/python3.6/site-packages/flask/app.py", line 1813, in full_dispatch_request
    rv = self.dispatch_request()
  File "/home/jon/venv/p3/lib/python3.6/site-packages/flask/app.py", line 1791, in dispatch_request
    self.raise_routing_exception(req)
  File "/home/jon/venv/p3/lib/python3.6/site-packages/flask/app.py", line 1774, in raise_routing_exception
    raise request.routing_exception
  File "/home/jon/venv/p3/lib/python3.6/site-packages/flask/ctx.py", line 336, in match_request
    self.url_adapter.match(return_rule=True)
  File "/home/jon/venv/p3/lib/python3.6/site-packages/werkzeug/routing.py", line 1581, in match
    raise NotFound()
werkzeug.exceptions.NotFound: 404 Not Found: The requested URL was not found on the server.  If you entered the URL manually please check your spelling and try again.

[2019-Dec-19 23:46] 127.0.0.1 GET http /network3? 200 OK
[2019-Dec-19 23:46] 127.0.0.1 GET http /favicon.ico? 5xx INTERNAL SERVER ERROR
Traceback (most recent call last):
  File "/home/jon/venv/p3/lib/python3.6/site-packages/flask/app.py", line 1813, in full_dispatch_request
    rv = self.dispatch_request()
  File "/home/jon/venv/p3/lib/python3.6/site-packages/flask/app.py", line 1791, in dispatch_request
    self.raise_routing_exception(req)
  File "/home/jon/venv/p3/lib/python3.6/site-packages/flask/app.py", line 1774, in raise_routing_exception
    raise request.routing_exception
  File "/home/jon/venv/p3/lib/python3.6/site-packages/flask/ctx.py", line 336, in match_request
    self.url_adapter.match(return_rule=True)
  File "/home/jon/venv/p3/lib/python3.6/site-packages/werkzeug/routing.py", line 1581, in match
    raise NotFound()
werkzeug.exceptions.NotFound: 404 Not Found: The requested URL was not found on the server.  If you entered the URL manually please check your spelling and try again.

[2019-Dec-19 23:47] 127.0.0.1 GET http /network3? 200 OK
[2019-Dec-19 23:47] 127.0.0.1 GET http /favicon.ico? 5xx INTERNAL SERVER ERROR
Traceback (most recent call last):
  File "/home/jon/venv/p3/lib/python3.6/site-packages/flask/app.py", line 1813, in full_dispatch_request
    rv = self.dispatch_request()
  File "/home/jon/venv/p3/lib/python3.6/site-packages/flask/app.py", line 1791, in dispatch_request
    self.raise_routing_exception(req)
  File "/home/jon/venv/p3/lib/python3.6/site-packages/flask/app.py", line 1774, in raise_routing_exception
    raise request.routing_exception
  File "/home/jon/venv/p3/lib/python3.6/site-packages/flask/ctx.py", line 336, in match_request
    self.url_adapter.match(return_rule=True)
  File "/home/jon/venv/p3/lib/python3.6/site-packages/werkzeug/routing.py", line 1581, in match
    raise NotFound()
werkzeug.exceptions.NotFound: 404 Not Found: The requested URL was not found on the server.  If you entered the URL manually please check your spelling and try again.

[2019-Dec-19 23:47] 127.0.0.1 GET http /network3? 200 OK
[2019-Dec-19 23:47] 127.0.0.1 GET http /favicon.ico? 5xx INTERNAL SERVER ERROR
Traceback (most recent call last):
  File "/home/jon/venv/p3/lib/python3.6/site-packages/flask/app.py", line 1813, in full_dispatch_request
    rv = self.dispatch_request()
  File "/home/jon/venv/p3/lib/python3.6/site-packages/flask/app.py", line 1791, in dispatch_request
    self.raise_routing_exception(req)
  File "/home/jon/venv/p3/lib/python3.6/site-packages/flask/app.py", line 1774, in raise_routing_exception
    raise request.routing_exception
  File "/home/jon/venv/p3/lib/python3.6/site-packages/flask/ctx.py", line 336, in match_request
    self.url_adapter.match(return_rule=True)
  File "/home/jon/venv/p3/lib/python3.6/site-packages/werkzeug/routing.py", line 1581, in match
    raise NotFound()
werkzeug.exceptions.NotFound: 404 Not Found: The requested URL was not found on the server.  If you entered the URL manually please check your spelling and try again.

[2019-Dec-19 23:49] 127.0.0.1 GET http /network3? 200 OK
[2019-Dec-19 23:49] 127.0.0.1 GET http /favicon.ico? 5xx INTERNAL SERVER ERROR
Traceback (most recent call last):
  File "/home/jon/venv/p3/lib/python3.6/site-packages/flask/app.py", line 1813, in full_dispatch_request
    rv = self.dispatch_request()
  File "/home/jon/venv/p3/lib/python3.6/site-packages/flask/app.py", line 1791, in dispatch_request
    self.raise_routing_exception(req)
  File "/home/jon/venv/p3/lib/python3.6/site-packages/flask/app.py", line 1774, in raise_routing_exception
    raise request.routing_exception
  File "/home/jon/venv/p3/lib/python3.6/site-packages/flask/ctx.py", line 336, in match_request
    self.url_adapter.match(return_rule=True)
  File "/home/jon/venv/p3/lib/python3.6/site-packages/werkzeug/routing.py", line 1581, in match
    raise NotFound()
werkzeug.exceptions.NotFound: 404 Not Found: The requested URL was not found on the server.  If you entered the URL manually please check your spelling and try again.

