[2019-Dec-20 20:42] 127.0.0.1 GET http /favicon.ico? 5xx INTERNAL SERVER ERROR
Traceback (most recent call last):
  File "/home/jon/venv/p3/lib/python3.6/site-packages/flask/app.py", line 1813, in full_dispatch_request
    rv = self.dispatch_request()
  File "/home/jon/venv/p3/lib/python3.6/site-packages/flask/app.py", line 1791, in dispatch_request
    self.raise_routing_exception(req)
  File "/home/jon/venv/p3/lib/python3.6/site-packages/flask/app.py", line 1774, in raise_routing_exception
    raise request.routing_exception
  File "/home/jon/venv/p3/lib/python3.6/site-packages/flask/ctx.py", line 336, in match_request
    self.url_adapter.match(return_rule=True)
  File "/home/jon/venv/p3/lib/python3.6/site-packages/werkzeug/routing.py", line 1581, in match
    raise NotFound()
werkzeug.exceptions.NotFound: 404 Not Found: The requested URL was not found on the server.  If you entered the URL manually please check your spelling and try again.

[2019-Dec-20 20:42] 127.0.0.1 GET http /favicon.ico? 5xx INTERNAL SERVER ERROR
Traceback (most recent call last):
  File "/home/jon/venv/p3/lib/python3.6/site-packages/flask/app.py", line 1813, in full_dispatch_request
    rv = self.dispatch_request()
  File "/home/jon/venv/p3/lib/python3.6/site-packages/flask/app.py", line 1791, in dispatch_request
    self.raise_routing_exception(req)
  File "/home/jon/venv/p3/lib/python3.6/site-packages/flask/app.py", line 1774, in raise_routing_exception
    raise request.routing_exception
  File "/home/jon/venv/p3/lib/python3.6/site-packages/flask/ctx.py", line 336, in match_request
    self.url_adapter.match(return_rule=True)
  File "/home/jon/venv/p3/lib/python3.6/site-packages/werkzeug/routing.py", line 1581, in match
    raise NotFound()
werkzeug.exceptions.NotFound: 404 Not Found: The requested URL was not found on the server.  If you entered the URL manually please check your spelling and try again.

[2019-Dec-20 20:42] 127.0.0.1 GET http /favicon.ico? 5xx INTERNAL SERVER ERROR
Traceback (most recent call last):
  File "/home/jon/venv/p3/lib/python3.6/site-packages/flask/app.py", line 1813, in full_dispatch_request
    rv = self.dispatch_request()
  File "/home/jon/venv/p3/lib/python3.6/site-packages/flask/app.py", line 1791, in dispatch_request
    self.raise_routing_exception(req)
  File "/home/jon/venv/p3/lib/python3.6/site-packages/flask/app.py", line 1774, in raise_routing_exception
    raise request.routing_exception
  File "/home/jon/venv/p3/lib/python3.6/site-packages/flask/ctx.py", line 336, in match_request
    self.url_adapter.match(return_rule=True)
  File "/home/jon/venv/p3/lib/python3.6/site-packages/werkzeug/routing.py", line 1581, in match
    raise NotFound()
werkzeug.exceptions.NotFound: 404 Not Found: The requested URL was not found on the server.  If you entered the URL manually please check your spelling and try again.

[2019-Dec-20 20:45] 127.0.0.1 GET http /favicon.ico? 5xx INTERNAL SERVER ERROR
Traceback (most recent call last):
  File "/home/jon/venv/p3/lib/python3.6/site-packages/flask/app.py", line 1813, in full_dispatch_request
    rv = self.dispatch_request()
  File "/home/jon/venv/p3/lib/python3.6/site-packages/flask/app.py", line 1791, in dispatch_request
    self.raise_routing_exception(req)
  File "/home/jon/venv/p3/lib/python3.6/site-packages/flask/app.py", line 1774, in raise_routing_exception
    raise request.routing_exception
  File "/home/jon/venv/p3/lib/python3.6/site-packages/flask/ctx.py", line 336, in match_request
    self.url_adapter.match(return_rule=True)
  File "/home/jon/venv/p3/lib/python3.6/site-packages/werkzeug/routing.py", line 1581, in match
    raise NotFound()
werkzeug.exceptions.NotFound: 404 Not Found: The requested URL was not found on the server.  If you entered the URL manually please check your spelling and try again.

[2019-Dec-20 20:45] 127.0.0.1 GET http /favicon.ico? 5xx INTERNAL SERVER ERROR
Traceback (most recent call last):
  File "/home/jon/venv/p3/lib/python3.6/site-packages/flask/app.py", line 1813, in full_dispatch_request
    rv = self.dispatch_request()
  File "/home/jon/venv/p3/lib/python3.6/site-packages/flask/app.py", line 1791, in dispatch_request
    self.raise_routing_exception(req)
  File "/home/jon/venv/p3/lib/python3.6/site-packages/flask/app.py", line 1774, in raise_routing_exception
    raise request.routing_exception
  File "/home/jon/venv/p3/lib/python3.6/site-packages/flask/ctx.py", line 336, in match_request
    self.url_adapter.match(return_rule=True)
  File "/home/jon/venv/p3/lib/python3.6/site-packages/werkzeug/routing.py", line 1581, in match
    raise NotFound()
werkzeug.exceptions.NotFound: 404 Not Found: The requested URL was not found on the server.  If you entered the URL manually please check your spelling and try again.

[2019-Dec-20 20:45] 127.0.0.1 GET http /multi? 200 OK
[2019-Dec-20 20:45] 127.0.0.1 GET http /favicon.ico? 5xx INTERNAL SERVER ERROR
Traceback (most recent call last):
  File "/home/jon/venv/p3/lib/python3.6/site-packages/flask/app.py", line 1813, in full_dispatch_request
    rv = self.dispatch_request()
  File "/home/jon/venv/p3/lib/python3.6/site-packages/flask/app.py", line 1791, in dispatch_request
    self.raise_routing_exception(req)
  File "/home/jon/venv/p3/lib/python3.6/site-packages/flask/app.py", line 1774, in raise_routing_exception
    raise request.routing_exception
  File "/home/jon/venv/p3/lib/python3.6/site-packages/flask/ctx.py", line 336, in match_request
    self.url_adapter.match(return_rule=True)
  File "/home/jon/venv/p3/lib/python3.6/site-packages/werkzeug/routing.py", line 1581, in match
    raise NotFound()
werkzeug.exceptions.NotFound: 404 Not Found: The requested URL was not found on the server.  If you entered the URL manually please check your spelling and try again.

[2019-Dec-20 20:45] 127.0.0.1 GET http /favicon.ico? 5xx INTERNAL SERVER ERROR
Traceback (most recent call last):
  File "/home/jon/venv/p3/lib/python3.6/site-packages/flask/app.py", line 1813, in full_dispatch_request
    rv = self.dispatch_request()
  File "/home/jon/venv/p3/lib/python3.6/site-packages/flask/app.py", line 1791, in dispatch_request
    self.raise_routing_exception(req)
  File "/home/jon/venv/p3/lib/python3.6/site-packages/flask/app.py", line 1774, in raise_routing_exception
    raise request.routing_exception
  File "/home/jon/venv/p3/lib/python3.6/site-packages/flask/ctx.py", line 336, in match_request
    self.url_adapter.match(return_rule=True)
  File "/home/jon/venv/p3/lib/python3.6/site-packages/werkzeug/routing.py", line 1581, in match
    raise NotFound()
werkzeug.exceptions.NotFound: 404 Not Found: The requested URL was not found on the server.  If you entered the URL manually please check your spelling and try again.

[2019-Dec-20 20:45] 127.0.0.1 GET http /favicon.ico? 5xx INTERNAL SERVER ERROR
Traceback (most recent call last):
  File "/home/jon/venv/p3/lib/python3.6/site-packages/flask/app.py", line 1813, in full_dispatch_request
    rv = self.dispatch_request()
  File "/home/jon/venv/p3/lib/python3.6/site-packages/flask/app.py", line 1791, in dispatch_request
    self.raise_routing_exception(req)
  File "/home/jon/venv/p3/lib/python3.6/site-packages/flask/app.py", line 1774, in raise_routing_exception
    raise request.routing_exception
  File "/home/jon/venv/p3/lib/python3.6/site-packages/flask/ctx.py", line 336, in match_request
    self.url_adapter.match(return_rule=True)
  File "/home/jon/venv/p3/lib/python3.6/site-packages/werkzeug/routing.py", line 1581, in match
    raise NotFound()
werkzeug.exceptions.NotFound: 404 Not Found: The requested URL was not found on the server.  If you entered the URL manually please check your spelling and try again.

[2019-Dec-20 20:45] 127.0.0.1 GET http /favicon.ico? 5xx INTERNAL SERVER ERROR
Traceback (most recent call last):
  File "/home/jon/venv/p3/lib/python3.6/site-packages/flask/app.py", line 1813, in full_dispatch_request
    rv = self.dispatch_request()
  File "/home/jon/venv/p3/lib/python3.6/site-packages/flask/app.py", line 1791, in dispatch_request
    self.raise_routing_exception(req)
  File "/home/jon/venv/p3/lib/python3.6/site-packages/flask/app.py", line 1774, in raise_routing_exception
    raise request.routing_exception
  File "/home/jon/venv/p3/lib/python3.6/site-packages/flask/ctx.py", line 336, in match_request
    self.url_adapter.match(return_rule=True)
  File "/home/jon/venv/p3/lib/python3.6/site-packages/werkzeug/routing.py", line 1581, in match
    raise NotFound()
werkzeug.exceptions.NotFound: 404 Not Found: The requested URL was not found on the server.  If you entered the URL manually please check your spelling and try again.

[2019-Dec-20 20:49] 127.0.0.1 GET http /favicon.ico? 5xx INTERNAL SERVER ERROR
Traceback (most recent call last):
  File "/home/jon/venv/p3/lib/python3.6/site-packages/flask/app.py", line 1813, in full_dispatch_request
    rv = self.dispatch_request()
  File "/home/jon/venv/p3/lib/python3.6/site-packages/flask/app.py", line 1791, in dispatch_request
    self.raise_routing_exception(req)
  File "/home/jon/venv/p3/lib/python3.6/site-packages/flask/app.py", line 1774, in raise_routing_exception
    raise request.routing_exception
  File "/home/jon/venv/p3/lib/python3.6/site-packages/flask/ctx.py", line 336, in match_request
    self.url_adapter.match(return_rule=True)
  File "/home/jon/venv/p3/lib/python3.6/site-packages/werkzeug/routing.py", line 1581, in match
    raise NotFound()
werkzeug.exceptions.NotFound: 404 Not Found: The requested URL was not found on the server.  If you entered the URL manually please check your spelling and try again.

[2019-Dec-20 20:49] 127.0.0.1 GET http /favicon.ico? 5xx INTERNAL SERVER ERROR
Traceback (most recent call last):
  File "/home/jon/venv/p3/lib/python3.6/site-packages/flask/app.py", line 1813, in full_dispatch_request
    rv = self.dispatch_request()
  File "/home/jon/venv/p3/lib/python3.6/site-packages/flask/app.py", line 1791, in dispatch_request
    self.raise_routing_exception(req)
  File "/home/jon/venv/p3/lib/python3.6/site-packages/flask/app.py", line 1774, in raise_routing_exception
    raise request.routing_exception
  File "/home/jon/venv/p3/lib/python3.6/site-packages/flask/ctx.py", line 336, in match_request
    self.url_adapter.match(return_rule=True)
  File "/home/jon/venv/p3/lib/python3.6/site-packages/werkzeug/routing.py", line 1581, in match
    raise NotFound()
werkzeug.exceptions.NotFound: 404 Not Found: The requested URL was not found on the server.  If you entered the URL manually please check your spelling and try again.

[2019-Dec-20 21:28] 127.0.0.1 GET http /? 200 OK
[2019-Dec-20 21:34] 127.0.0.1 GET http /multi? 200 OK
[2019-Dec-20 21:34] 127.0.0.1 GET http /favicon.ico? 5xx INTERNAL SERVER ERROR
Traceback (most recent call last):
  File "/home/jon/venv/p3/lib/python3.6/site-packages/flask/app.py", line 1813, in full_dispatch_request
    rv = self.dispatch_request()
  File "/home/jon/venv/p3/lib/python3.6/site-packages/flask/app.py", line 1791, in dispatch_request
    self.raise_routing_exception(req)
  File "/home/jon/venv/p3/lib/python3.6/site-packages/flask/app.py", line 1774, in raise_routing_exception
    raise request.routing_exception
  File "/home/jon/venv/p3/lib/python3.6/site-packages/flask/ctx.py", line 336, in match_request
    self.url_adapter.match(return_rule=True)
  File "/home/jon/venv/p3/lib/python3.6/site-packages/werkzeug/routing.py", line 1581, in match
    raise NotFound()
werkzeug.exceptions.NotFound: 404 Not Found: The requested URL was not found on the server.  If you entered the URL manually please check your spelling and try again.

[2019-Dec-20 21:34] 127.0.0.1 GET http /? 200 OK
[2019-Dec-20 22:04] 127.0.0.1 GET http /doc? 200 OK
[2019-Dec-20 22:04] 127.0.0.1 GET http /? 200 OK
[2019-Dec-20 22:04] 127.0.0.1 GET http /? 200 OK
[2019-Dec-20 22:04] 127.0.0.1 GET http /multi? 200 OK
[2019-Dec-20 22:04] 127.0.0.1 GET http /favicon.ico? 5xx INTERNAL SERVER ERROR
Traceback (most recent call last):
  File "/home/jon/venv/p3/lib/python3.6/site-packages/flask/app.py", line 1813, in full_dispatch_request
    rv = self.dispatch_request()
  File "/home/jon/venv/p3/lib/python3.6/site-packages/flask/app.py", line 1791, in dispatch_request
    self.raise_routing_exception(req)
  File "/home/jon/venv/p3/lib/python3.6/site-packages/flask/app.py", line 1774, in raise_routing_exception
    raise request.routing_exception
  File "/home/jon/venv/p3/lib/python3.6/site-packages/flask/ctx.py", line 336, in match_request
    self.url_adapter.match(return_rule=True)
  File "/home/jon/venv/p3/lib/python3.6/site-packages/werkzeug/routing.py", line 1581, in match
    raise NotFound()
werkzeug.exceptions.NotFound: 404 Not Found: The requested URL was not found on the server.  If you entered the URL manually please check your spelling and try again.

[2019-Dec-20 22:04] 127.0.0.1 GET http /favicon.ico? 5xx INTERNAL SERVER ERROR
Traceback (most recent call last):
  File "/home/jon/venv/p3/lib/python3.6/site-packages/flask/app.py", line 1813, in full_dispatch_request
    rv = self.dispatch_request()
  File "/home/jon/venv/p3/lib/python3.6/site-packages/flask/app.py", line 1791, in dispatch_request
    self.raise_routing_exception(req)
  File "/home/jon/venv/p3/lib/python3.6/site-packages/flask/app.py", line 1774, in raise_routing_exception
    raise request.routing_exception
  File "/home/jon/venv/p3/lib/python3.6/site-packages/flask/ctx.py", line 336, in match_request
    self.url_adapter.match(return_rule=True)
  File "/home/jon/venv/p3/lib/python3.6/site-packages/werkzeug/routing.py", line 1581, in match
    raise NotFound()
werkzeug.exceptions.NotFound: 404 Not Found: The requested URL was not found on the server.  If you entered the URL manually please check your spelling and try again.

[2019-Dec-26 20:54] 127.0.0.1 GET http /? 200 OK
[2019-Dec-26 20:54] 127.0.0.1 GET http /static/css/auto-complete.css? 304 NOT MODIFIED
[2019-Dec-26 20:54] 127.0.0.1 GET http /static/css/signin.css? 304 NOT MODIFIED
[2019-Dec-26 20:54] 127.0.0.1 GET http /static/js/jquery-1.9.0.js? 200 OK
[2019-Dec-26 20:54] 127.0.0.1 GET http /static/js/script.js? 200 OK
[2019-Dec-26 20:54] 127.0.0.1 GET http /static/js/fetch.js? 304 NOT MODIFIED
[2019-Dec-26 20:54] 127.0.0.1 GET http /static/js/auto-complete.min.js? 200 OK
[2019-Dec-26 20:54] 127.0.0.1 GET http /static/css/scss_css.css? 304 NOT MODIFIED
[2019-Dec-26 20:54] 127.0.0.1 GET http /static/css/my_style.css? 304 NOT MODIFIED
[2019-Dec-26 20:54] 127.0.0.1 GET http /static/data/data.json? 200 OK
[2019-Dec-26 20:54] 127.0.0.1 GET http /static/js/autocomplete.js? 200 OK
[2019-Dec-26 20:54] 127.0.0.1 GET http /multi? 200 OK
[2019-Dec-26 20:54] 127.0.0.1 GET http /favicon.ico? 5xx INTERNAL SERVER ERROR
Traceback (most recent call last):
  File "/home/jon/venv/p3/lib/python3.6/site-packages/flask/app.py", line 1813, in full_dispatch_request
    rv = self.dispatch_request()
  File "/home/jon/venv/p3/lib/python3.6/site-packages/flask/app.py", line 1791, in dispatch_request
    self.raise_routing_exception(req)
  File "/home/jon/venv/p3/lib/python3.6/site-packages/flask/app.py", line 1774, in raise_routing_exception
    raise request.routing_exception
  File "/home/jon/venv/p3/lib/python3.6/site-packages/flask/ctx.py", line 336, in match_request
    self.url_adapter.match(return_rule=True)
  File "/home/jon/venv/p3/lib/python3.6/site-packages/werkzeug/routing.py", line 1581, in match
    raise NotFound()
werkzeug.exceptions.NotFound: 404 Not Found: The requested URL was not found on the server.  If you entered the URL manually please check your spelling and try again.

[2019-Dec-26 20:54] 127.0.0.1 GET http /favicon.ico? 5xx INTERNAL SERVER ERROR
Traceback (most recent call last):
  File "/home/jon/venv/p3/lib/python3.6/site-packages/flask/app.py", line 1813, in full_dispatch_request
    rv = self.dispatch_request()
  File "/home/jon/venv/p3/lib/python3.6/site-packages/flask/app.py", line 1791, in dispatch_request
    self.raise_routing_exception(req)
  File "/home/jon/venv/p3/lib/python3.6/site-packages/flask/app.py", line 1774, in raise_routing_exception
    raise request.routing_exception
  File "/home/jon/venv/p3/lib/python3.6/site-packages/flask/ctx.py", line 336, in match_request
    self.url_adapter.match(return_rule=True)
  File "/home/jon/venv/p3/lib/python3.6/site-packages/werkzeug/routing.py", line 1581, in match
    raise NotFound()
werkzeug.exceptions.NotFound: 404 Not Found: The requested URL was not found on the server.  If you entered the URL manually please check your spelling and try again.

[2019-Dec-26 20:54] 127.0.0.1 GET http /favicon.ico? 5xx INTERNAL SERVER ERROR
Traceback (most recent call last):
  File "/home/jon/venv/p3/lib/python3.6/site-packages/flask/app.py", line 1813, in full_dispatch_request
    rv = self.dispatch_request()
  File "/home/jon/venv/p3/lib/python3.6/site-packages/flask/app.py", line 1791, in dispatch_request
    self.raise_routing_exception(req)
  File "/home/jon/venv/p3/lib/python3.6/site-packages/flask/app.py", line 1774, in raise_routing_exception
    raise request.routing_exception
  File "/home/jon/venv/p3/lib/python3.6/site-packages/flask/ctx.py", line 336, in match_request
    self.url_adapter.match(return_rule=True)
  File "/home/jon/venv/p3/lib/python3.6/site-packages/werkzeug/routing.py", line 1581, in match
    raise NotFound()
werkzeug.exceptions.NotFound: 404 Not Found: The requested URL was not found on the server.  If you entered the URL manually please check your spelling and try again.

[2019-Dec-26 20:54] 127.0.0.1 GET http /? 200 OK
[2019-Dec-26 20:54] 127.0.0.1 GET http /? 200 OK
[2019-Dec-26 20:54] 127.0.0.1 GET http /easyui? 200 OK
[2019-Dec-26 20:54] 127.0.0.1 GET http /static/css/easyui.css? 200 OK
[2019-Dec-26 20:54] 127.0.0.1 GET http /static/css/icon.css? 200 OK
[2019-Dec-26 20:54] 127.0.0.1 GET http /static/css/demo.css? 200 OK
[2019-Dec-26 20:54] 127.0.0.1 GET http /static/js/jquery.easyui.min.js? 200 OK
[2019-Dec-26 20:54] 127.0.0.1 GET http /static/js/jquery.min.js? 200 OK
[2019-Dec-26 20:54] 127.0.0.1 GET http /static/css/images/combo_arrow.png? 5xx INTERNAL SERVER ERROR
Traceback (most recent call last):
  File "/home/jon/venv/p3/lib/python3.6/site-packages/flask/app.py", line 1813, in full_dispatch_request
    rv = self.dispatch_request()
  File "/home/jon/venv/p3/lib/python3.6/site-packages/flask/app.py", line 1799, in dispatch_request
    return self.view_functions[rule.endpoint](**req.view_args)
  File "/home/jon/venv/p3/lib/python3.6/site-packages/flask/helpers.py", line 976, in send_static_file
    cache_timeout=cache_timeout)
  File "/home/jon/venv/p3/lib/python3.6/site-packages/flask/helpers.py", line 709, in send_from_directory
    raise NotFound()
werkzeug.exceptions.NotFound: 404 Not Found: The requested URL was not found on the server.  If you entered the URL manually please check your spelling and try again.

[2019-Dec-26 20:54] 127.0.0.1 GET http /static/css/images/blank.gif? 5xx INTERNAL SERVER ERROR
Traceback (most recent call last):
  File "/home/jon/venv/p3/lib/python3.6/site-packages/flask/app.py", line 1813, in full_dispatch_request
    rv = self.dispatch_request()
  File "/home/jon/venv/p3/lib/python3.6/site-packages/flask/app.py", line 1799, in dispatch_request
    return self.view_functions[rule.endpoint](**req.view_args)
  File "/home/jon/venv/p3/lib/python3.6/site-packages/flask/helpers.py", line 976, in send_static_file
    cache_timeout=cache_timeout)
  File "/home/jon/venv/p3/lib/python3.6/site-packages/flask/helpers.py", line 709, in send_from_directory
    raise NotFound()
werkzeug.exceptions.NotFound: 404 Not Found: The requested URL was not found on the server.  If you entered the URL manually please check your spelling and try again.

[2019-Dec-26 20:54] 127.0.0.1 GET http /favicon.ico? 5xx INTERNAL SERVER ERROR
Traceback (most recent call last):
  File "/home/jon/venv/p3/lib/python3.6/site-packages/flask/app.py", line 1813, in full_dispatch_request
    rv = self.dispatch_request()
  File "/home/jon/venv/p3/lib/python3.6/site-packages/flask/app.py", line 1791, in dispatch_request
    self.raise_routing_exception(req)
  File "/home/jon/venv/p3/lib/python3.6/site-packages/flask/app.py", line 1774, in raise_routing_exception
    raise request.routing_exception
  File "/home/jon/venv/p3/lib/python3.6/site-packages/flask/ctx.py", line 336, in match_request
    self.url_adapter.match(return_rule=True)
  File "/home/jon/venv/p3/lib/python3.6/site-packages/werkzeug/routing.py", line 1581, in match
    raise NotFound()
werkzeug.exceptions.NotFound: 404 Not Found: The requested URL was not found on the server.  If you entered the URL manually please check your spelling and try again.

[2019-Dec-26 20:54] 127.0.0.1 GET http /? 200 OK
[2019-Dec-26 20:54] 127.0.0.1 GET http /network3? 200 OK
[2019-Dec-26 20:54] 127.0.0.1 GET http /favicon.ico? 5xx INTERNAL SERVER ERROR
Traceback (most recent call last):
  File "/home/jon/venv/p3/lib/python3.6/site-packages/flask/app.py", line 1813, in full_dispatch_request
    rv = self.dispatch_request()
  File "/home/jon/venv/p3/lib/python3.6/site-packages/flask/app.py", line 1791, in dispatch_request
    self.raise_routing_exception(req)
  File "/home/jon/venv/p3/lib/python3.6/site-packages/flask/app.py", line 1774, in raise_routing_exception
    raise request.routing_exception
  File "/home/jon/venv/p3/lib/python3.6/site-packages/flask/ctx.py", line 336, in match_request
    self.url_adapter.match(return_rule=True)
  File "/home/jon/venv/p3/lib/python3.6/site-packages/werkzeug/routing.py", line 1581, in match
    raise NotFound()
werkzeug.exceptions.NotFound: 404 Not Found: The requested URL was not found on the server.  If you entered the URL manually please check your spelling and try again.

[2019-Dec-26 21:18] 127.0.0.1 GET http /? 200 OK
[2019-Dec-26 21:19] 127.0.0.1 GET http /d3? 200 OK
[2019-Dec-26 21:19] 127.0.0.1 GET http /static/css/d3_css.css? 200 OK
[2019-Dec-26 21:19] 127.0.0.1 GET http /favicon.ico? 5xx INTERNAL SERVER ERROR
Traceback (most recent call last):
  File "/home/jon/venv/p3/lib/python3.6/site-packages/flask/app.py", line 1813, in full_dispatch_request
    rv = self.dispatch_request()
  File "/home/jon/venv/p3/lib/python3.6/site-packages/flask/app.py", line 1791, in dispatch_request
    self.raise_routing_exception(req)
  File "/home/jon/venv/p3/lib/python3.6/site-packages/flask/app.py", line 1774, in raise_routing_exception
    raise request.routing_exception
  File "/home/jon/venv/p3/lib/python3.6/site-packages/flask/ctx.py", line 336, in match_request
    self.url_adapter.match(return_rule=True)
  File "/home/jon/venv/p3/lib/python3.6/site-packages/werkzeug/routing.py", line 1581, in match
    raise NotFound()
werkzeug.exceptions.NotFound: 404 Not Found: The requested URL was not found on the server.  If you entered the URL manually please check your spelling and try again.

[2019-Dec-26 21:19] 127.0.0.1 GET http /? 200 OK
[2019-Dec-26 21:19] 127.0.0.1 GET http /doc? 200 OK
[2019-Dec-26 21:19] 127.0.0.1 GET http /static/css/bootstrap.min.css? 200 OK
[2019-Dec-26 21:19] 127.0.0.1 GET http /? 200 OK
[2019-Dec-26 21:30] 127.0.0.1 GET http /multi? 200 OK
[2019-Dec-26 21:30] 127.0.0.1 GET http /favicon.ico? 5xx INTERNAL SERVER ERROR
Traceback (most recent call last):
  File "/home/jon/venv/p3/lib/python3.6/site-packages/flask/app.py", line 1813, in full_dispatch_request
    rv = self.dispatch_request()
  File "/home/jon/venv/p3/lib/python3.6/site-packages/flask/app.py", line 1791, in dispatch_request
    self.raise_routing_exception(req)
  File "/home/jon/venv/p3/lib/python3.6/site-packages/flask/app.py", line 1774, in raise_routing_exception
    raise request.routing_exception
  File "/home/jon/venv/p3/lib/python3.6/site-packages/flask/ctx.py", line 336, in match_request
    self.url_adapter.match(return_rule=True)
  File "/home/jon/venv/p3/lib/python3.6/site-packages/werkzeug/routing.py", line 1581, in match
    raise NotFound()
werkzeug.exceptions.NotFound: 404 Not Found: The requested URL was not found on the server.  If you entered the URL manually please check your spelling and try again.

[2019-Dec-26 21:30] 127.0.0.1 GET http /favicon.ico? 5xx INTERNAL SERVER ERROR
Traceback (most recent call last):
  File "/home/jon/venv/p3/lib/python3.6/site-packages/flask/app.py", line 1813, in full_dispatch_request
    rv = self.dispatch_request()
  File "/home/jon/venv/p3/lib/python3.6/site-packages/flask/app.py", line 1791, in dispatch_request
    self.raise_routing_exception(req)
  File "/home/jon/venv/p3/lib/python3.6/site-packages/flask/app.py", line 1774, in raise_routing_exception
    raise request.routing_exception
  File "/home/jon/venv/p3/lib/python3.6/site-packages/flask/ctx.py", line 336, in match_request
    self.url_adapter.match(return_rule=True)
  File "/home/jon/venv/p3/lib/python3.6/site-packages/werkzeug/routing.py", line 1581, in match
    raise NotFound()
werkzeug.exceptions.NotFound: 404 Not Found: The requested URL was not found on the server.  If you entered the URL manually please check your spelling and try again.

[2019-Dec-26 21:30] 127.0.0.1 GET http /favicon.ico? 5xx INTERNAL SERVER ERROR
Traceback (most recent call last):
  File "/home/jon/venv/p3/lib/python3.6/site-packages/flask/app.py", line 1813, in full_dispatch_request
    rv = self.dispatch_request()
  File "/home/jon/venv/p3/lib/python3.6/site-packages/flask/app.py", line 1791, in dispatch_request
    self.raise_routing_exception(req)
  File "/home/jon/venv/p3/lib/python3.6/site-packages/flask/app.py", line 1774, in raise_routing_exception
    raise request.routing_exception
  File "/home/jon/venv/p3/lib/python3.6/site-packages/flask/ctx.py", line 336, in match_request
    self.url_adapter.match(return_rule=True)
  File "/home/jon/venv/p3/lib/python3.6/site-packages/werkzeug/routing.py", line 1581, in match
    raise NotFound()
werkzeug.exceptions.NotFound: 404 Not Found: The requested URL was not found on the server.  If you entered the URL manually please check your spelling and try again.

[2019-Dec-26 21:31] 127.0.0.1 GET http /favicon.ico? 5xx INTERNAL SERVER ERROR
Traceback (most recent call last):
  File "/home/jon/venv/p3/lib/python3.6/site-packages/flask/app.py", line 1813, in full_dispatch_request
    rv = self.dispatch_request()
  File "/home/jon/venv/p3/lib/python3.6/site-packages/flask/app.py", line 1791, in dispatch_request
    self.raise_routing_exception(req)
  File "/home/jon/venv/p3/lib/python3.6/site-packages/flask/app.py", line 1774, in raise_routing_exception
    raise request.routing_exception
  File "/home/jon/venv/p3/lib/python3.6/site-packages/flask/ctx.py", line 336, in match_request
    self.url_adapter.match(return_rule=True)
  File "/home/jon/venv/p3/lib/python3.6/site-packages/werkzeug/routing.py", line 1581, in match
    raise NotFound()
werkzeug.exceptions.NotFound: 404 Not Found: The requested URL was not found on the server.  If you entered the URL manually please check your spelling and try again.

[2019-Dec-26 21:33] 127.0.0.1 GET http /? 200 OK
[2019-Dec-26 21:33] 127.0.0.1 GET http /multi? 200 OK
[2019-Dec-26 21:33] 127.0.0.1 GET http /favicon.ico? 5xx INTERNAL SERVER ERROR
Traceback (most recent call last):
  File "/home/jon/venv/p3/lib/python3.6/site-packages/flask/app.py", line 1813, in full_dispatch_request
    rv = self.dispatch_request()
  File "/home/jon/venv/p3/lib/python3.6/site-packages/flask/app.py", line 1791, in dispatch_request
    self.raise_routing_exception(req)
  File "/home/jon/venv/p3/lib/python3.6/site-packages/flask/app.py", line 1774, in raise_routing_exception
    raise request.routing_exception
  File "/home/jon/venv/p3/lib/python3.6/site-packages/flask/ctx.py", line 336, in match_request
    self.url_adapter.match(return_rule=True)
  File "/home/jon/venv/p3/lib/python3.6/site-packages/werkzeug/routing.py", line 1581, in match
    raise NotFound()
werkzeug.exceptions.NotFound: 404 Not Found: The requested URL was not found on the server.  If you entered the URL manually please check your spelling and try again.

[2019-Dec-26 21:33] 127.0.0.1 GET http /? 200 OK
[2019-Dec-26 21:34] 127.0.0.1 GET http /? 200 OK
[2019-Dec-26 21:34] 127.0.0.1 GET http /static/favicon.ico? 200 OK
[2019-Dec-26 21:34] 127.0.0.1 GET http /multi? 200 OK
[2019-Dec-26 21:34] 127.0.0.1 GET http /favicon.ico? 5xx INTERNAL SERVER ERROR
Traceback (most recent call last):
  File "/home/jon/venv/p3/lib/python3.6/site-packages/flask/app.py", line 1813, in full_dispatch_request
    rv = self.dispatch_request()
  File "/home/jon/venv/p3/lib/python3.6/site-packages/flask/app.py", line 1791, in dispatch_request
    self.raise_routing_exception(req)
  File "/home/jon/venv/p3/lib/python3.6/site-packages/flask/app.py", line 1774, in raise_routing_exception
    raise request.routing_exception
  File "/home/jon/venv/p3/lib/python3.6/site-packages/flask/ctx.py", line 336, in match_request
    self.url_adapter.match(return_rule=True)
  File "/home/jon/venv/p3/lib/python3.6/site-packages/werkzeug/routing.py", line 1581, in match
    raise NotFound()
werkzeug.exceptions.NotFound: 404 Not Found: The requested URL was not found on the server.  If you entered the URL manually please check your spelling and try again.

[2019-Dec-26 21:34] 127.0.0.1 GET http /? 200 OK
[2019-Dec-26 21:35] 127.0.0.1 GET http /? 200 OK
[2019-Dec-26 21:35] 127.0.0.1 GET http /static/favicon.ico? 200 OK
[2019-Dec-26 21:35] 127.0.0.1 GET http /? 200 OK
[2019-Dec-26 21:35] 127.0.0.1 GET http /static/favicon.ico? 200 OK
[2019-Dec-26 21:38] 127.0.0.1 GET http /? 200 OK
[2019-Dec-26 21:38] 127.0.0.1 GET http /static/favicon.ico? 200 OK
[2019-Dec-26 21:46] 127.0.0.1 GET http /? 200 OK
[2019-Dec-26 21:46] 127.0.0.1 GET http /static/favicon.ico? 200 OK
[2019-Dec-26 21:48] 127.0.0.1 GET http /? 200 OK
[2019-Dec-26 21:48] 127.0.0.1 GET http /static/favicon.ico? 200 OK
[2019-Dec-26 21:49] 127.0.0.1 GET http /? 200 OK
[2019-Dec-26 21:49] 127.0.0.1 GET http /static/favicon.ico? 200 OK
[2019-Dec-26 21:53] 127.0.0.1 GET http /? 200 OK
[2019-Dec-26 21:53] 127.0.0.1 GET http /static/favicon.ico? 200 OK
[2019-Dec-26 21:55] 127.0.0.1 GET http /? 200 OK
[2019-Dec-26 21:55] 127.0.0.1 GET http /static/favicon.ico? 200 OK
[2019-Dec-26 21:55] 127.0.0.1 GET http /static/css/scss_css.css.map? 200 OK
[2019-Dec-26 21:58] 127.0.0.1 GET http /? 200 OK
[2019-Dec-26 21:58] 127.0.0.1 GET http /static/favicon.ico? 200 OK
[2019-Dec-26 22:03] 127.0.0.1 GET http /? 200 OK
[2019-Dec-26 22:03] 127.0.0.1 GET http /static/favicon.ico? 200 OK
[2019-Dec-26 22:03] 127.0.0.1 GET http /multi? 200 OK
[2019-Dec-26 22:03] 127.0.0.1 GET http /favicon.ico? 5xx INTERNAL SERVER ERROR
Traceback (most recent call last):
  File "/home/jon/venv/p3/lib/python3.6/site-packages/flask/app.py", line 1813, in full_dispatch_request
    rv = self.dispatch_request()
  File "/home/jon/venv/p3/lib/python3.6/site-packages/flask/app.py", line 1791, in dispatch_request
    self.raise_routing_exception(req)
  File "/home/jon/venv/p3/lib/python3.6/site-packages/flask/app.py", line 1774, in raise_routing_exception
    raise request.routing_exception
  File "/home/jon/venv/p3/lib/python3.6/site-packages/flask/ctx.py", line 336, in match_request
    self.url_adapter.match(return_rule=True)
  File "/home/jon/venv/p3/lib/python3.6/site-packages/werkzeug/routing.py", line 1581, in match
    raise NotFound()
werkzeug.exceptions.NotFound: 404 Not Found: The requested URL was not found on the server.  If you entered the URL manually please check your spelling and try again.

[2019-Dec-26 22:03] 127.0.0.1 GET http /? 200 OK
[2019-Dec-26 22:03] 127.0.0.1 GET http /d3? 200 OK
[2019-Dec-26 22:03] 127.0.0.1 GET http /favicon.ico? 5xx INTERNAL SERVER ERROR
Traceback (most recent call last):
  File "/home/jon/venv/p3/lib/python3.6/site-packages/flask/app.py", line 1813, in full_dispatch_request
    rv = self.dispatch_request()
  File "/home/jon/venv/p3/lib/python3.6/site-packages/flask/app.py", line 1791, in dispatch_request
    self.raise_routing_exception(req)
  File "/home/jon/venv/p3/lib/python3.6/site-packages/flask/app.py", line 1774, in raise_routing_exception
    raise request.routing_exception
  File "/home/jon/venv/p3/lib/python3.6/site-packages/flask/ctx.py", line 336, in match_request
    self.url_adapter.match(return_rule=True)
  File "/home/jon/venv/p3/lib/python3.6/site-packages/werkzeug/routing.py", line 1581, in match
    raise NotFound()
werkzeug.exceptions.NotFound: 404 Not Found: The requested URL was not found on the server.  If you entered the URL manually please check your spelling and try again.

[2019-Dec-26 22:03] 127.0.0.1 GET http /? 200 OK
[2019-Dec-26 22:03] 127.0.0.1 GET http /network? 200 OK
[2019-Dec-26 22:03] 127.0.0.1 GET http /d3_data? 200 OK
[2019-Dec-26 22:03] 127.0.0.1 GET http /favicon.ico? 5xx INTERNAL SERVER ERROR
Traceback (most recent call last):
  File "/home/jon/venv/p3/lib/python3.6/site-packages/flask/app.py", line 1813, in full_dispatch_request
    rv = self.dispatch_request()
  File "/home/jon/venv/p3/lib/python3.6/site-packages/flask/app.py", line 1791, in dispatch_request
    self.raise_routing_exception(req)
  File "/home/jon/venv/p3/lib/python3.6/site-packages/flask/app.py", line 1774, in raise_routing_exception
    raise request.routing_exception
  File "/home/jon/venv/p3/lib/python3.6/site-packages/flask/ctx.py", line 336, in match_request
    self.url_adapter.match(return_rule=True)
  File "/home/jon/venv/p3/lib/python3.6/site-packages/werkzeug/routing.py", line 1581, in match
    raise NotFound()
werkzeug.exceptions.NotFound: 404 Not Found: The requested URL was not found on the server.  If you entered the URL manually please check your spelling and try again.

[2019-Dec-26 22:03] 127.0.0.1 GET http /? 200 OK
[2019-Dec-26 22:03] 127.0.0.1 GET http /doc? 200 OK
[2019-Dec-26 22:03] 127.0.0.1 GET http /hello? 200 OK
[2019-Dec-26 22:03] 127.0.0.1 GET http /favicon.ico? 5xx INTERNAL SERVER ERROR
Traceback (most recent call last):
  File "/home/jon/venv/p3/lib/python3.6/site-packages/flask/app.py", line 1813, in full_dispatch_request
    rv = self.dispatch_request()
  File "/home/jon/venv/p3/lib/python3.6/site-packages/flask/app.py", line 1791, in dispatch_request
    self.raise_routing_exception(req)
  File "/home/jon/venv/p3/lib/python3.6/site-packages/flask/app.py", line 1774, in raise_routing_exception
    raise request.routing_exception
  File "/home/jon/venv/p3/lib/python3.6/site-packages/flask/ctx.py", line 336, in match_request
    self.url_adapter.match(return_rule=True)
  File "/home/jon/venv/p3/lib/python3.6/site-packages/werkzeug/routing.py", line 1581, in match
    raise NotFound()
werkzeug.exceptions.NotFound: 404 Not Found: The requested URL was not found on the server.  If you entered the URL manually please check your spelling and try again.

[2019-Dec-26 22:04] 127.0.0.1 GET http /? 200 OK
[2019-Dec-26 22:04] 127.0.0.1 GET http /? 200 OK
[2019-Dec-26 22:04] 127.0.0.1 GET http /static/favicon.ico? 200 OK
[2019-Dec-26 22:04] 127.0.0.1 GET http /? 200 OK
[2019-Dec-26 22:04] 127.0.0.1 GET http /static/favicon.ico? 200 OK
[2019-Dec-26 22:04] 127.0.0.1 GET http /? 200 OK
[2019-Dec-26 22:04] 127.0.0.1 GET http /static/favicon.ico? 200 OK
[2019-Dec-26 22:04] 127.0.0.1 GET http /static/css/scss_css.css.map? 200 OK
[2019-Dec-26 22:05] 127.0.0.1 GET http /? 200 OK
[2019-Dec-26 22:05] 127.0.0.1 GET http /static/css/auto-complete.css? 200 OK
[2019-Dec-26 22:05] 127.0.0.1 GET http /static/css/signin.css? 200 OK
[2019-Dec-26 22:05] 127.0.0.1 GET http /static/js/jquery-1.9.0.js? 200 OK
[2019-Dec-26 22:05] 127.0.0.1 GET http /static/css/my_style.css? 200 OK
[2019-Dec-26 22:05] 127.0.0.1 GET http /static/css/scss_css.css? 200 OK
[2019-Dec-26 22:05] 127.0.0.1 GET http /static/js/script.js? 200 OK
[2019-Dec-26 22:05] 127.0.0.1 GET http /static/js/fetch.js? 200 OK
[2019-Dec-26 22:05] 127.0.0.1 GET http /static/js/auto-complete.min.js? 200 OK
[2019-Dec-26 22:05] 127.0.0.1 GET http /static/data/data.json? 200 OK
[2019-Dec-26 22:05] 127.0.0.1 GET http /static/js/autocomplete.js? 200 OK
[2019-Dec-26 22:05] 127.0.0.1 GET http /static/css/scss_css.css.map? 200 OK
[2019-Dec-26 22:05] 127.0.0.1 GET http /static/favicon.ico? 200 OK
[2019-Dec-26 22:05] 127.0.0.1 GET http /multi? 200 OK
[2019-Dec-26 22:05] 127.0.0.1 GET http /favicon.ico? 5xx INTERNAL SERVER ERROR
Traceback (most recent call last):
  File "/home/jon/venv/p3/lib/python3.6/site-packages/flask/app.py", line 1813, in full_dispatch_request
    rv = self.dispatch_request()
  File "/home/jon/venv/p3/lib/python3.6/site-packages/flask/app.py", line 1791, in dispatch_request
    self.raise_routing_exception(req)
  File "/home/jon/venv/p3/lib/python3.6/site-packages/flask/app.py", line 1774, in raise_routing_exception
    raise request.routing_exception
  File "/home/jon/venv/p3/lib/python3.6/site-packages/flask/ctx.py", line 336, in match_request
    self.url_adapter.match(return_rule=True)
  File "/home/jon/venv/p3/lib/python3.6/site-packages/werkzeug/routing.py", line 1581, in match
    raise NotFound()
werkzeug.exceptions.NotFound: 404 Not Found: The requested URL was not found on the server.  If you entered the URL manually please check your spelling and try again.

[2019-Dec-26 22:05] 127.0.0.1 GET http /? 200 OK
[2019-Dec-26 22:07] 127.0.0.1 GET http /? 200 OK
[2019-Dec-26 22:07] 127.0.0.1 GET http /static/favicon.ico? 200 OK
[2019-Dec-26 22:08] 127.0.0.1 GET http /static/css/scss_css.css.map? 200 OK
[2019-Dec-26 22:10] 127.0.0.1 GET http /? 200 OK
[2019-Dec-26 22:10] 127.0.0.1 GET http /static/css/auto-complete.css? 200 OK
[2019-Dec-26 22:10] 127.0.0.1 GET http /static/css/signin.css? 200 OK
[2019-Dec-26 22:10] 127.0.0.1 GET http /static/css/my_style.css? 200 OK
[2019-Dec-26 22:10] 127.0.0.1 GET http /static/js/jquery-1.9.0.js? 200 OK
[2019-Dec-26 22:10] 127.0.0.1 GET http /static/js/script.js? 200 OK
[2019-Dec-26 22:10] 127.0.0.1 GET http /static/js/fetch.js? 200 OK
[2019-Dec-26 22:10] 127.0.0.1 GET http /static/css/scss_css.css? 200 OK
[2019-Dec-26 22:10] 127.0.0.1 GET http /static/js/auto-complete.min.js? 200 OK
[2019-Dec-26 22:10] 127.0.0.1 GET http /static/data/data.json? 200 OK
[2019-Dec-26 22:10] 127.0.0.1 GET http /static/js/autocomplete.js? 200 OK
[2019-Dec-26 22:10] 127.0.0.1 GET http /static/css/scss_css.css.map? 200 OK
[2019-Dec-26 22:10] 127.0.0.1 GET http /static/favicon.ico? 200 OK
[2019-Dec-26 22:10] 127.0.0.1 GET http /static/css/scss_css.css.map? 200 OK
[2019-Dec-26 22:16] 127.0.0.1 GET http /? 200 OK
[2019-Dec-26 22:16] 127.0.0.1 GET http /static/favicon.ico? 200 OK
[2019-Dec-26 22:16] 127.0.0.1 GET http /static/css/scss_css.css.map? 200 OK
[2019-Dec-26 22:17] 127.0.0.1 GET http /? 200 OK
[2019-Dec-26 22:17] 127.0.0.1 GET http /static/favicon.ico? 200 OK
[2019-Dec-26 22:17] 127.0.0.1 GET http /static/css/scss_css.css.map? 200 OK
[2019-Dec-26 22:19] 127.0.0.1 GET http /? 200 OK
[2019-Dec-26 22:19] 127.0.0.1 GET http /static/favicon.ico? 200 OK
[2019-Dec-26 22:19] 127.0.0.1 GET http /static/css/scss_css.css.map? 200 OK
[2019-Dec-26 22:21] 127.0.0.1 GET http /? 200 OK
[2019-Dec-26 22:21] 127.0.0.1 GET http /static/favicon.ico? 200 OK
[2019-Dec-26 22:22] 127.0.0.1 GET http /? 200 OK
[2019-Dec-26 22:22] 127.0.0.1 GET http /static/favicon.ico? 200 OK
[2019-Dec-26 22:22] 127.0.0.1 GET http /? 200 OK
[2019-Dec-26 22:22] 127.0.0.1 GET http /static/favicon.ico? 200 OK
[2019-Dec-26 22:23] 127.0.0.1 GET http /static/css/scss_css.css.map? 200 OK
[2019-Dec-26 22:24] 127.0.0.1 GET http /static/css/scss_css.css.map? 200 OK
[2019-Dec-26 22:26] 127.0.0.1 GET http /tree_view? 200 OK
[2019-Dec-26 22:26] 127.0.0.1 GET http /favicon.ico? 5xx INTERNAL SERVER ERROR
Traceback (most recent call last):
  File "/home/jon/venv/p3/lib/python3.6/site-packages/flask/app.py", line 1813, in full_dispatch_request
    rv = self.dispatch_request()
  File "/home/jon/venv/p3/lib/python3.6/site-packages/flask/app.py", line 1791, in dispatch_request
    self.raise_routing_exception(req)
  File "/home/jon/venv/p3/lib/python3.6/site-packages/flask/app.py", line 1774, in raise_routing_exception
    raise request.routing_exception
  File "/home/jon/venv/p3/lib/python3.6/site-packages/flask/ctx.py", line 336, in match_request
    self.url_adapter.match(return_rule=True)
  File "/home/jon/venv/p3/lib/python3.6/site-packages/werkzeug/routing.py", line 1581, in match
    raise NotFound()
werkzeug.exceptions.NotFound: 404 Not Found: The requested URL was not found on the server.  If you entered the URL manually please check your spelling and try again.

[2019-Dec-26 22:26] 127.0.0.1 GET http /fetch_random_data? 200 OK
[2019-Dec-26 22:26] 127.0.0.1 GET http /fetch_random_data? 200 OK
[2019-Dec-26 22:26] 127.0.0.1 GET http /? 200 OK
[2019-Dec-26 22:26] 127.0.0.1 GET http /? 200 OK
[2019-Dec-26 22:27] 127.0.0.1 GET http /? 200 OK
[2019-Dec-26 22:27] 127.0.0.1 GET http /static/favicon.ico? 200 OK
[2019-Dec-26 22:27] 127.0.0.1 GET http /multi? 200 OK
[2019-Dec-26 22:27] 127.0.0.1 GET http /favicon.ico? 5xx INTERNAL SERVER ERROR
Traceback (most recent call last):
  File "/home/jon/venv/p3/lib/python3.6/site-packages/flask/app.py", line 1813, in full_dispatch_request
    rv = self.dispatch_request()
  File "/home/jon/venv/p3/lib/python3.6/site-packages/flask/app.py", line 1791, in dispatch_request
    self.raise_routing_exception(req)
  File "/home/jon/venv/p3/lib/python3.6/site-packages/flask/app.py", line 1774, in raise_routing_exception
    raise request.routing_exception
  File "/home/jon/venv/p3/lib/python3.6/site-packages/flask/ctx.py", line 336, in match_request
    self.url_adapter.match(return_rule=True)
  File "/home/jon/venv/p3/lib/python3.6/site-packages/werkzeug/routing.py", line 1581, in match
    raise NotFound()
werkzeug.exceptions.NotFound: 404 Not Found: The requested URL was not found on the server.  If you entered the URL manually please check your spelling and try again.

[2019-Dec-26 22:27] 127.0.0.1 GET http /? 200 OK
[2019-Dec-26 22:27] 127.0.0.1 GET http /? 200 OK
[2019-Dec-26 22:27] 127.0.0.1 GET http /? 200 OK
[2019-Dec-26 22:27] 127.0.0.1 GET http /static/favicon.ico? 200 OK
[2019-Dec-26 22:27] 127.0.0.1 GET http /static/css/scss_css.css.map? 200 OK
[2019-Dec-26 22:28] 127.0.0.1 GET http /? 200 OK
[2019-Dec-26 22:28] 127.0.0.1 GET http /static/css/auto-complete.css? 200 OK
[2019-Dec-26 22:28] 127.0.0.1 GET http /static/css/signin.css? 200 OK
[2019-Dec-26 22:28] 127.0.0.1 GET http /static/js/jquery-1.9.0.js? 200 OK
[2019-Dec-26 22:28] 127.0.0.1 GET http /static/js/fetch.js? 200 OK
[2019-Dec-26 22:28] 127.0.0.1 GET http /static/js/script.js? 200 OK
[2019-Dec-26 22:28] 127.0.0.1 GET http /static/js/auto-complete.min.js? 200 OK
[2019-Dec-26 22:28] 127.0.0.1 GET http /static/css/my_style.css? 200 OK
[2019-Dec-26 22:28] 127.0.0.1 GET http /static/css/scss_css.css? 200 OK
[2019-Dec-26 22:28] 127.0.0.1 GET http /static/data/data.json? 200 OK
[2019-Dec-26 22:28] 127.0.0.1 GET http /static/js/autocomplete.js? 200 OK
[2019-Dec-26 22:28] 127.0.0.1 GET http /static/css/scss_css.css.map? 200 OK
[2019-Dec-26 22:28] 127.0.0.1 GET http /static/favicon.ico? 200 OK
[2019-Dec-29 10:33] 127.0.0.1 GET http /? 200 OK
[2019-Dec-29 10:33] 127.0.0.1 GET http /static/css/auto-complete.css? 304 NOT MODIFIED
[2019-Dec-29 10:33] 127.0.0.1 GET http /static/css/scss_css.css? 304 NOT MODIFIED
[2019-Dec-29 10:33] 127.0.0.1 GET http /static/js/script.js? 304 NOT MODIFIED
[2019-Dec-29 10:33] 127.0.0.1 GET http /static/css/my_style.css? 304 NOT MODIFIED
[2019-Dec-29 10:33] 127.0.0.1 GET http /static/css/signin.css? 304 NOT MODIFIED
[2019-Dec-29 10:33] 127.0.0.1 GET http /static/js/fetch.js? 304 NOT MODIFIED
[2019-Dec-29 10:33] 127.0.0.1 GET http /static/js/jquery-1.9.0.js? 304 NOT MODIFIED
[2019-Dec-29 10:33] 127.0.0.1 GET http /static/js/auto-complete.min.js? 304 NOT MODIFIED
[2019-Dec-29 10:33] 127.0.0.1 GET http /static/data/data.json? 304 NOT MODIFIED
[2019-Dec-29 10:33] 127.0.0.1 GET http /static/js/autocomplete.js? 304 NOT MODIFIED
[2019-Dec-29 10:33] 127.0.0.1 GET http /multi? 200 OK
[2019-Dec-29 10:33] 127.0.0.1 GET http /favicon.ico? 5xx INTERNAL SERVER ERROR
Traceback (most recent call last):
  File "/home/jon/venv/p3/lib/python3.6/site-packages/flask/app.py", line 1813, in full_dispatch_request
    rv = self.dispatch_request()
  File "/home/jon/venv/p3/lib/python3.6/site-packages/flask/app.py", line 1791, in dispatch_request
    self.raise_routing_exception(req)
  File "/home/jon/venv/p3/lib/python3.6/site-packages/flask/app.py", line 1774, in raise_routing_exception
    raise request.routing_exception
  File "/home/jon/venv/p3/lib/python3.6/site-packages/flask/ctx.py", line 336, in match_request
    self.url_adapter.match(return_rule=True)
  File "/home/jon/venv/p3/lib/python3.6/site-packages/werkzeug/routing.py", line 1581, in match
    raise NotFound()
werkzeug.exceptions.NotFound: 404 Not Found: The requested URL was not found on the server.  If you entered the URL manually please check your spelling and try again.

[2019-Dec-29 10:33] 127.0.0.1 GET http /? 200 OK
[2019-Dec-29 10:33] 127.0.0.1 GET http /hello? 200 OK
[2019-Dec-29 10:33] 127.0.0.1 GET http /favicon.ico? 5xx INTERNAL SERVER ERROR
Traceback (most recent call last):
  File "/home/jon/venv/p3/lib/python3.6/site-packages/flask/app.py", line 1813, in full_dispatch_request
    rv = self.dispatch_request()
  File "/home/jon/venv/p3/lib/python3.6/site-packages/flask/app.py", line 1791, in dispatch_request
    self.raise_routing_exception(req)
  File "/home/jon/venv/p3/lib/python3.6/site-packages/flask/app.py", line 1774, in raise_routing_exception
    raise request.routing_exception
  File "/home/jon/venv/p3/lib/python3.6/site-packages/flask/ctx.py", line 336, in match_request
    self.url_adapter.match(return_rule=True)
  File "/home/jon/venv/p3/lib/python3.6/site-packages/werkzeug/routing.py", line 1581, in match
    raise NotFound()
werkzeug.exceptions.NotFound: 404 Not Found: The requested URL was not found on the server.  If you entered the URL manually please check your spelling and try again.

[2019-Dec-29 10:33] 127.0.0.1 GET http /? 200 OK
[2019-Dec-29 10:34] 127.0.0.1 GET http /network3? 200 OK
[2019-Dec-29 10:34] 127.0.0.1 GET http /favicon.ico? 5xx INTERNAL SERVER ERROR
Traceback (most recent call last):
  File "/home/jon/venv/p3/lib/python3.6/site-packages/flask/app.py", line 1813, in full_dispatch_request
    rv = self.dispatch_request()
  File "/home/jon/venv/p3/lib/python3.6/site-packages/flask/app.py", line 1791, in dispatch_request
    self.raise_routing_exception(req)
  File "/home/jon/venv/p3/lib/python3.6/site-packages/flask/app.py", line 1774, in raise_routing_exception
    raise request.routing_exception
  File "/home/jon/venv/p3/lib/python3.6/site-packages/flask/ctx.py", line 336, in match_request
    self.url_adapter.match(return_rule=True)
  File "/home/jon/venv/p3/lib/python3.6/site-packages/werkzeug/routing.py", line 1581, in match
    raise NotFound()
werkzeug.exceptions.NotFound: 404 Not Found: The requested URL was not found on the server.  If you entered the URL manually please check your spelling and try again.

[2019-Dec-29 10:35] 127.0.0.1 GET http /? 200 OK
[2019-Dec-29 10:35] 127.0.0.1 GET http /network2? 200 OK
[2019-Dec-29 10:35] 127.0.0.1 GET http /d3_data2? 200 OK
[2019-Dec-29 10:35] 127.0.0.1 GET http /favicon.ico? 5xx INTERNAL SERVER ERROR
Traceback (most recent call last):
  File "/home/jon/venv/p3/lib/python3.6/site-packages/flask/app.py", line 1813, in full_dispatch_request
    rv = self.dispatch_request()
  File "/home/jon/venv/p3/lib/python3.6/site-packages/flask/app.py", line 1791, in dispatch_request
    self.raise_routing_exception(req)
  File "/home/jon/venv/p3/lib/python3.6/site-packages/flask/app.py", line 1774, in raise_routing_exception
    raise request.routing_exception
  File "/home/jon/venv/p3/lib/python3.6/site-packages/flask/ctx.py", line 336, in match_request
    self.url_adapter.match(return_rule=True)
  File "/home/jon/venv/p3/lib/python3.6/site-packages/werkzeug/routing.py", line 1581, in match
    raise NotFound()
werkzeug.exceptions.NotFound: 404 Not Found: The requested URL was not found on the server.  If you entered the URL manually please check your spelling and try again.

[2019-Dec-29 10:35] 127.0.0.1 GET http /? 200 OK
[2019-Dec-29 10:35] 127.0.0.1 GET http /network1? 200 OK
[2019-Dec-29 10:35] 127.0.0.1 GET http /d3_data? 200 OK
[2019-Dec-29 10:35] 127.0.0.1 GET http /favicon.ico? 5xx INTERNAL SERVER ERROR
Traceback (most recent call last):
  File "/home/jon/venv/p3/lib/python3.6/site-packages/flask/app.py", line 1813, in full_dispatch_request
    rv = self.dispatch_request()
  File "/home/jon/venv/p3/lib/python3.6/site-packages/flask/app.py", line 1791, in dispatch_request
    self.raise_routing_exception(req)
  File "/home/jon/venv/p3/lib/python3.6/site-packages/flask/app.py", line 1774, in raise_routing_exception
    raise request.routing_exception
  File "/home/jon/venv/p3/lib/python3.6/site-packages/flask/ctx.py", line 336, in match_request
    self.url_adapter.match(return_rule=True)
  File "/home/jon/venv/p3/lib/python3.6/site-packages/werkzeug/routing.py", line 1581, in match
    raise NotFound()
werkzeug.exceptions.NotFound: 404 Not Found: The requested URL was not found on the server.  If you entered the URL manually please check your spelling and try again.

[2019-Dec-29 10:35] 127.0.0.1 GET http /? 200 OK
[2019-Dec-29 10:35] 127.0.0.1 GET http /network? 200 OK
[2019-Dec-29 10:35] 127.0.0.1 GET http /d3_data? 200 OK
[2019-Dec-29 10:35] 127.0.0.1 GET http /favicon.ico? 5xx INTERNAL SERVER ERROR
Traceback (most recent call last):
  File "/home/jon/venv/p3/lib/python3.6/site-packages/flask/app.py", line 1813, in full_dispatch_request
    rv = self.dispatch_request()
  File "/home/jon/venv/p3/lib/python3.6/site-packages/flask/app.py", line 1791, in dispatch_request
    self.raise_routing_exception(req)
  File "/home/jon/venv/p3/lib/python3.6/site-packages/flask/app.py", line 1774, in raise_routing_exception
    raise request.routing_exception
  File "/home/jon/venv/p3/lib/python3.6/site-packages/flask/ctx.py", line 336, in match_request
    self.url_adapter.match(return_rule=True)
  File "/home/jon/venv/p3/lib/python3.6/site-packages/werkzeug/routing.py", line 1581, in match
    raise NotFound()
werkzeug.exceptions.NotFound: 404 Not Found: The requested URL was not found on the server.  If you entered the URL manually please check your spelling and try again.

[2019-Dec-29 10:35] 127.0.0.1 GET http /? 200 OK
[2019-Dec-29 10:38] 127.0.0.1 GET http /multi? 200 OK
[2019-Dec-29 10:38] 127.0.0.1 GET http /favicon.ico? 5xx INTERNAL SERVER ERROR
Traceback (most recent call last):
  File "/home/jon/venv/p3/lib/python3.6/site-packages/flask/app.py", line 1813, in full_dispatch_request
    rv = self.dispatch_request()
  File "/home/jon/venv/p3/lib/python3.6/site-packages/flask/app.py", line 1791, in dispatch_request
    self.raise_routing_exception(req)
  File "/home/jon/venv/p3/lib/python3.6/site-packages/flask/app.py", line 1774, in raise_routing_exception
    raise request.routing_exception
  File "/home/jon/venv/p3/lib/python3.6/site-packages/flask/ctx.py", line 336, in match_request
    self.url_adapter.match(return_rule=True)
  File "/home/jon/venv/p3/lib/python3.6/site-packages/werkzeug/routing.py", line 1581, in match
    raise NotFound()
werkzeug.exceptions.NotFound: 404 Not Found: The requested URL was not found on the server.  If you entered the URL manually please check your spelling and try again.

[2019-Dec-29 10:38] 127.0.0.1 GET http /? 200 OK
[2019-Dec-29 10:38] 127.0.0.1 GET http /network3? 200 OK
[2019-Dec-29 10:38] 127.0.0.1 GET http /favicon.ico? 5xx INTERNAL SERVER ERROR
Traceback (most recent call last):
  File "/home/jon/venv/p3/lib/python3.6/site-packages/flask/app.py", line 1813, in full_dispatch_request
    rv = self.dispatch_request()
  File "/home/jon/venv/p3/lib/python3.6/site-packages/flask/app.py", line 1791, in dispatch_request
    self.raise_routing_exception(req)
  File "/home/jon/venv/p3/lib/python3.6/site-packages/flask/app.py", line 1774, in raise_routing_exception
    raise request.routing_exception
  File "/home/jon/venv/p3/lib/python3.6/site-packages/flask/ctx.py", line 336, in match_request
    self.url_adapter.match(return_rule=True)
  File "/home/jon/venv/p3/lib/python3.6/site-packages/werkzeug/routing.py", line 1581, in match
    raise NotFound()
werkzeug.exceptions.NotFound: 404 Not Found: The requested URL was not found on the server.  If you entered the URL manually please check your spelling and try again.

[2019-Dec-29 10:38] 127.0.0.1 GET http /? 200 OK
[2019-Dec-29 10:38] 127.0.0.1 GET http /network2? 200 OK
[2019-Dec-29 10:38] 127.0.0.1 GET http /d3_data2? 200 OK
[2019-Dec-29 10:38] 127.0.0.1 GET http /favicon.ico? 5xx INTERNAL SERVER ERROR
Traceback (most recent call last):
  File "/home/jon/venv/p3/lib/python3.6/site-packages/flask/app.py", line 1813, in full_dispatch_request
    rv = self.dispatch_request()
  File "/home/jon/venv/p3/lib/python3.6/site-packages/flask/app.py", line 1791, in dispatch_request
    self.raise_routing_exception(req)
  File "/home/jon/venv/p3/lib/python3.6/site-packages/flask/app.py", line 1774, in raise_routing_exception
    raise request.routing_exception
  File "/home/jon/venv/p3/lib/python3.6/site-packages/flask/ctx.py", line 336, in match_request
    self.url_adapter.match(return_rule=True)
  File "/home/jon/venv/p3/lib/python3.6/site-packages/werkzeug/routing.py", line 1581, in match
    raise NotFound()
werkzeug.exceptions.NotFound: 404 Not Found: The requested URL was not found on the server.  If you entered the URL manually please check your spelling and try again.

[2019-Dec-29 10:38] 127.0.0.1 GET http /? 200 OK
[2019-Dec-29 10:38] 127.0.0.1 GET http /network1? 200 OK
[2019-Dec-29 10:38] 127.0.0.1 GET http /d3_data? 200 OK
[2019-Dec-29 10:38] 127.0.0.1 GET http /favicon.ico? 5xx INTERNAL SERVER ERROR
Traceback (most recent call last):
  File "/home/jon/venv/p3/lib/python3.6/site-packages/flask/app.py", line 1813, in full_dispatch_request
    rv = self.dispatch_request()
  File "/home/jon/venv/p3/lib/python3.6/site-packages/flask/app.py", line 1791, in dispatch_request
    self.raise_routing_exception(req)
  File "/home/jon/venv/p3/lib/python3.6/site-packages/flask/app.py", line 1774, in raise_routing_exception
    raise request.routing_exception
  File "/home/jon/venv/p3/lib/python3.6/site-packages/flask/ctx.py", line 336, in match_request
    self.url_adapter.match(return_rule=True)
  File "/home/jon/venv/p3/lib/python3.6/site-packages/werkzeug/routing.py", line 1581, in match
    raise NotFound()
werkzeug.exceptions.NotFound: 404 Not Found: The requested URL was not found on the server.  If you entered the URL manually please check your spelling and try again.

[2019-Dec-29 10:38] 127.0.0.1 GET http /? 200 OK
[2019-Dec-29 10:38] 127.0.0.1 GET http /easyui? 200 OK
[2019-Dec-29 10:38] 127.0.0.1 GET http /static/css/easyui.css? 304 NOT MODIFIED
[2019-Dec-29 10:38] 127.0.0.1 GET http /static/css/icon.css? 304 NOT MODIFIED
[2019-Dec-29 10:38] 127.0.0.1 GET http /static/css/demo.css? 304 NOT MODIFIED
[2019-Dec-29 10:38] 127.0.0.1 GET http /static/js/jquery.easyui.min.js? 304 NOT MODIFIED
[2019-Dec-29 10:38] 127.0.0.1 GET http /static/js/jquery.min.js? 304 NOT MODIFIED
[2019-Dec-29 10:38] 127.0.0.1 GET http /static/css/images/combo_arrow.png? 5xx INTERNAL SERVER ERROR
Traceback (most recent call last):
  File "/home/jon/venv/p3/lib/python3.6/site-packages/flask/app.py", line 1813, in full_dispatch_request
    rv = self.dispatch_request()
  File "/home/jon/venv/p3/lib/python3.6/site-packages/flask/app.py", line 1799, in dispatch_request
    return self.view_functions[rule.endpoint](**req.view_args)
  File "/home/jon/venv/p3/lib/python3.6/site-packages/flask/helpers.py", line 976, in send_static_file
    cache_timeout=cache_timeout)
  File "/home/jon/venv/p3/lib/python3.6/site-packages/flask/helpers.py", line 709, in send_from_directory
    raise NotFound()
werkzeug.exceptions.NotFound: 404 Not Found: The requested URL was not found on the server.  If you entered the URL manually please check your spelling and try again.

[2019-Dec-29 10:38] 127.0.0.1 GET http /static/css/images/blank.gif? 5xx INTERNAL SERVER ERROR
Traceback (most recent call last):
  File "/home/jon/venv/p3/lib/python3.6/site-packages/flask/app.py", line 1813, in full_dispatch_request
    rv = self.dispatch_request()
  File "/home/jon/venv/p3/lib/python3.6/site-packages/flask/app.py", line 1799, in dispatch_request
    return self.view_functions[rule.endpoint](**req.view_args)
  File "/home/jon/venv/p3/lib/python3.6/site-packages/flask/helpers.py", line 976, in send_static_file
    cache_timeout=cache_timeout)
  File "/home/jon/venv/p3/lib/python3.6/site-packages/flask/helpers.py", line 709, in send_from_directory
    raise NotFound()
werkzeug.exceptions.NotFound: 404 Not Found: The requested URL was not found on the server.  If you entered the URL manually please check your spelling and try again.

[2019-Dec-29 10:38] 127.0.0.1 GET http /favicon.ico? 5xx INTERNAL SERVER ERROR
Traceback (most recent call last):
  File "/home/jon/venv/p3/lib/python3.6/site-packages/flask/app.py", line 1813, in full_dispatch_request
    rv = self.dispatch_request()
  File "/home/jon/venv/p3/lib/python3.6/site-packages/flask/app.py", line 1791, in dispatch_request
    self.raise_routing_exception(req)
  File "/home/jon/venv/p3/lib/python3.6/site-packages/flask/app.py", line 1774, in raise_routing_exception
    raise request.routing_exception
  File "/home/jon/venv/p3/lib/python3.6/site-packages/flask/ctx.py", line 336, in match_request
    self.url_adapter.match(return_rule=True)
  File "/home/jon/venv/p3/lib/python3.6/site-packages/werkzeug/routing.py", line 1581, in match
    raise NotFound()
werkzeug.exceptions.NotFound: 404 Not Found: The requested URL was not found on the server.  If you entered the URL manually please check your spelling and try again.

[2019-Dec-29 10:38] 127.0.0.1 GET http /? 200 OK
[2019-Dec-29 10:38] 127.0.0.1 GET http /easyui? 200 OK
[2019-Dec-29 10:38] 127.0.0.1 GET http /static/css/images/combo_arrow.png? 5xx INTERNAL SERVER ERROR
Traceback (most recent call last):
  File "/home/jon/venv/p3/lib/python3.6/site-packages/flask/app.py", line 1813, in full_dispatch_request
    rv = self.dispatch_request()
  File "/home/jon/venv/p3/lib/python3.6/site-packages/flask/app.py", line 1799, in dispatch_request
    return self.view_functions[rule.endpoint](**req.view_args)
  File "/home/jon/venv/p3/lib/python3.6/site-packages/flask/helpers.py", line 976, in send_static_file
    cache_timeout=cache_timeout)
  File "/home/jon/venv/p3/lib/python3.6/site-packages/flask/helpers.py", line 709, in send_from_directory
    raise NotFound()
werkzeug.exceptions.NotFound: 404 Not Found: The requested URL was not found on the server.  If you entered the URL manually please check your spelling and try again.

[2019-Dec-29 10:38] 127.0.0.1 GET http /static/css/images/blank.gif? 5xx INTERNAL SERVER ERROR
Traceback (most recent call last):
  File "/home/jon/venv/p3/lib/python3.6/site-packages/flask/app.py", line 1813, in full_dispatch_request
    rv = self.dispatch_request()
  File "/home/jon/venv/p3/lib/python3.6/site-packages/flask/app.py", line 1799, in dispatch_request
    return self.view_functions[rule.endpoint](**req.view_args)
  File "/home/jon/venv/p3/lib/python3.6/site-packages/flask/helpers.py", line 976, in send_static_file
    cache_timeout=cache_timeout)
  File "/home/jon/venv/p3/lib/python3.6/site-packages/flask/helpers.py", line 709, in send_from_directory
    raise NotFound()
werkzeug.exceptions.NotFound: 404 Not Found: The requested URL was not found on the server.  If you entered the URL manually please check your spelling and try again.

[2019-Dec-29 10:38] 127.0.0.1 GET http /favicon.ico? 5xx INTERNAL SERVER ERROR
Traceback (most recent call last):
  File "/home/jon/venv/p3/lib/python3.6/site-packages/flask/app.py", line 1813, in full_dispatch_request
    rv = self.dispatch_request()
  File "/home/jon/venv/p3/lib/python3.6/site-packages/flask/app.py", line 1791, in dispatch_request
    self.raise_routing_exception(req)
  File "/home/jon/venv/p3/lib/python3.6/site-packages/flask/app.py", line 1774, in raise_routing_exception
    raise request.routing_exception
  File "/home/jon/venv/p3/lib/python3.6/site-packages/flask/ctx.py", line 336, in match_request
    self.url_adapter.match(return_rule=True)
  File "/home/jon/venv/p3/lib/python3.6/site-packages/werkzeug/routing.py", line 1581, in match
    raise NotFound()
werkzeug.exceptions.NotFound: 404 Not Found: The requested URL was not found on the server.  If you entered the URL manually please check your spelling and try again.

[2019-Dec-29 10:38] 127.0.0.1 GET http /? 200 OK
[2019-Dec-29 10:38] 127.0.0.1 GET http /d3? 200 OK
[2019-Dec-29 10:38] 127.0.0.1 GET http /static/css/d3_css.css? 304 NOT MODIFIED
[2019-Dec-29 10:38] 127.0.0.1 GET http /favicon.ico? 5xx INTERNAL SERVER ERROR
Traceback (most recent call last):
  File "/home/jon/venv/p3/lib/python3.6/site-packages/flask/app.py", line 1813, in full_dispatch_request
    rv = self.dispatch_request()
  File "/home/jon/venv/p3/lib/python3.6/site-packages/flask/app.py", line 1791, in dispatch_request
    self.raise_routing_exception(req)
  File "/home/jon/venv/p3/lib/python3.6/site-packages/flask/app.py", line 1774, in raise_routing_exception
    raise request.routing_exception
  File "/home/jon/venv/p3/lib/python3.6/site-packages/flask/ctx.py", line 336, in match_request
    self.url_adapter.match(return_rule=True)
  File "/home/jon/venv/p3/lib/python3.6/site-packages/werkzeug/routing.py", line 1581, in match
    raise NotFound()
werkzeug.exceptions.NotFound: 404 Not Found: The requested URL was not found on the server.  If you entered the URL manually please check your spelling and try again.

[2019-Dec-29 10:38] 127.0.0.1 GET http /? 200 OK
[2019-Dec-29 10:38] 127.0.0.1 GET http /hello? 200 OK
[2019-Dec-29 10:38] 127.0.0.1 GET http /favicon.ico? 5xx INTERNAL SERVER ERROR
Traceback (most recent call last):
  File "/home/jon/venv/p3/lib/python3.6/site-packages/flask/app.py", line 1813, in full_dispatch_request
    rv = self.dispatch_request()
  File "/home/jon/venv/p3/lib/python3.6/site-packages/flask/app.py", line 1791, in dispatch_request
    self.raise_routing_exception(req)
  File "/home/jon/venv/p3/lib/python3.6/site-packages/flask/app.py", line 1774, in raise_routing_exception
    raise request.routing_exception
  File "/home/jon/venv/p3/lib/python3.6/site-packages/flask/ctx.py", line 336, in match_request
    self.url_adapter.match(return_rule=True)
  File "/home/jon/venv/p3/lib/python3.6/site-packages/werkzeug/routing.py", line 1581, in match
    raise NotFound()
werkzeug.exceptions.NotFound: 404 Not Found: The requested URL was not found on the server.  If you entered the URL manually please check your spelling and try again.

[2019-Dec-29 10:38] 127.0.0.1 GET http /? 200 OK
[2019-Dec-29 10:45] 127.0.0.1 GET http /? 200 OK
[2019-Dec-29 10:45] 127.0.0.1 GET http /easyui? 200 OK
[2019-Dec-29 10:45] 127.0.0.1 GET http /static/css/images/combo_arrow.png? 5xx INTERNAL SERVER ERROR
Traceback (most recent call last):
  File "/home/jon/venv/p3/lib/python3.6/site-packages/flask/app.py", line 1813, in full_dispatch_request
    rv = self.dispatch_request()
  File "/home/jon/venv/p3/lib/python3.6/site-packages/flask/app.py", line 1799, in dispatch_request
    return self.view_functions[rule.endpoint](**req.view_args)
  File "/home/jon/venv/p3/lib/python3.6/site-packages/flask/helpers.py", line 976, in send_static_file
    cache_timeout=cache_timeout)
  File "/home/jon/venv/p3/lib/python3.6/site-packages/flask/helpers.py", line 709, in send_from_directory
    raise NotFound()
werkzeug.exceptions.NotFound: 404 Not Found: The requested URL was not found on the server.  If you entered the URL manually please check your spelling and try again.

[2019-Dec-29 10:45] 127.0.0.1 GET http /static/css/images/blank.gif? 5xx INTERNAL SERVER ERROR
Traceback (most recent call last):
  File "/home/jon/venv/p3/lib/python3.6/site-packages/flask/app.py", line 1813, in full_dispatch_request
    rv = self.dispatch_request()
  File "/home/jon/venv/p3/lib/python3.6/site-packages/flask/app.py", line 1799, in dispatch_request
    return self.view_functions[rule.endpoint](**req.view_args)
  File "/home/jon/venv/p3/lib/python3.6/site-packages/flask/helpers.py", line 976, in send_static_file
    cache_timeout=cache_timeout)
  File "/home/jon/venv/p3/lib/python3.6/site-packages/flask/helpers.py", line 709, in send_from_directory
    raise NotFound()
werkzeug.exceptions.NotFound: 404 Not Found: The requested URL was not found on the server.  If you entered the URL manually please check your spelling and try again.

[2019-Dec-29 10:45] 127.0.0.1 GET http /favicon.ico? 5xx INTERNAL SERVER ERROR
Traceback (most recent call last):
  File "/home/jon/venv/p3/lib/python3.6/site-packages/flask/app.py", line 1813, in full_dispatch_request
    rv = self.dispatch_request()
  File "/home/jon/venv/p3/lib/python3.6/site-packages/flask/app.py", line 1791, in dispatch_request
    self.raise_routing_exception(req)
  File "/home/jon/venv/p3/lib/python3.6/site-packages/flask/app.py", line 1774, in raise_routing_exception
    raise request.routing_exception
  File "/home/jon/venv/p3/lib/python3.6/site-packages/flask/ctx.py", line 336, in match_request
    self.url_adapter.match(return_rule=True)
  File "/home/jon/venv/p3/lib/python3.6/site-packages/werkzeug/routing.py", line 1581, in match
    raise NotFound()
werkzeug.exceptions.NotFound: 404 Not Found: The requested URL was not found on the server.  If you entered the URL manually please check your spelling and try again.

[2019-Dec-29 10:45] 127.0.0.1 GET http /? 200 OK
[2019-Dec-29 10:45] 127.0.0.1 GET http /doc? 200 OK
[2019-Dec-29 10:45] 127.0.0.1 GET http /static/css/bootstrap.min.css? 304 NOT MODIFIED
[2019-Dec-29 10:46] 127.0.0.1 GET http /? 200 OK
[2019-Dec-29 10:49] 127.0.0.1 GET http /? 200 OK
[2019-Dec-29 16:48] 127.0.0.1 GET http /? 200 OK
[2019-Dec-29 16:50] 127.0.0.1 GET http /? 200 OK
[2019-Dec-29 16:50] 127.0.0.1 GET http /multi? 200 OK
[2019-Dec-29 16:50] 127.0.0.1 GET http /favicon.ico? 5xx INTERNAL SERVER ERROR
Traceback (most recent call last):
  File "/home/jon/venv/p3/lib/python3.6/site-packages/flask/app.py", line 1813, in full_dispatch_request
    rv = self.dispatch_request()
  File "/home/jon/venv/p3/lib/python3.6/site-packages/flask/app.py", line 1791, in dispatch_request
    self.raise_routing_exception(req)
  File "/home/jon/venv/p3/lib/python3.6/site-packages/flask/app.py", line 1774, in raise_routing_exception
    raise request.routing_exception
  File "/home/jon/venv/p3/lib/python3.6/site-packages/flask/ctx.py", line 336, in match_request
    self.url_adapter.match(return_rule=True)
  File "/home/jon/venv/p3/lib/python3.6/site-packages/werkzeug/routing.py", line 1581, in match
    raise NotFound()
werkzeug.exceptions.NotFound: 404 Not Found: The requested URL was not found on the server.  If you entered the URL manually please check your spelling and try again.

[2019-Dec-29 16:50] 127.0.0.1 GET http /favicon.ico? 5xx INTERNAL SERVER ERROR
Traceback (most recent call last):
  File "/home/jon/venv/p3/lib/python3.6/site-packages/flask/app.py", line 1813, in full_dispatch_request
    rv = self.dispatch_request()
  File "/home/jon/venv/p3/lib/python3.6/site-packages/flask/app.py", line 1791, in dispatch_request
    self.raise_routing_exception(req)
  File "/home/jon/venv/p3/lib/python3.6/site-packages/flask/app.py", line 1774, in raise_routing_exception
    raise request.routing_exception
  File "/home/jon/venv/p3/lib/python3.6/site-packages/flask/ctx.py", line 336, in match_request
    self.url_adapter.match(return_rule=True)
  File "/home/jon/venv/p3/lib/python3.6/site-packages/werkzeug/routing.py", line 1581, in match
    raise NotFound()
werkzeug.exceptions.NotFound: 404 Not Found: The requested URL was not found on the server.  If you entered the URL manually please check your spelling and try again.

[2019-Dec-29 17:44] 127.0.0.1 GET http /? 200 OK
[2019-Dec-29 17:46] 127.0.0.1 GET http /? 200 OK
[2019-Dec-29 17:46] 127.0.0.1 GET http /static/favicon.ico? 200 OK
[2019-Dec-29 17:47] 127.0.0.1 GET http /? 200 OK
[2019-Dec-29 17:47] 127.0.0.1 GET http /static/favicon.ico? 200 OK
[2019-Dec-29 17:49] 127.0.0.1 GET http /? 200 OK
[2019-Dec-29 17:49] 127.0.0.1 GET http /static/favicon.ico? 200 OK
[2019-Dec-29 17:49] 127.0.0.1 GET http /multi? 200 OK
[2019-Dec-29 17:49] 127.0.0.1 GET http /favicon.ico? 5xx INTERNAL SERVER ERROR
Traceback (most recent call last):
  File "/home/jon/venv/p3/lib/python3.6/site-packages/flask/app.py", line 1813, in full_dispatch_request
    rv = self.dispatch_request()
  File "/home/jon/venv/p3/lib/python3.6/site-packages/flask/app.py", line 1791, in dispatch_request
    self.raise_routing_exception(req)
  File "/home/jon/venv/p3/lib/python3.6/site-packages/flask/app.py", line 1774, in raise_routing_exception
    raise request.routing_exception
  File "/home/jon/venv/p3/lib/python3.6/site-packages/flask/ctx.py", line 336, in match_request
    self.url_adapter.match(return_rule=True)
  File "/home/jon/venv/p3/lib/python3.6/site-packages/werkzeug/routing.py", line 1581, in match
    raise NotFound()
werkzeug.exceptions.NotFound: 404 Not Found: The requested URL was not found on the server.  If you entered the URL manually please check your spelling and try again.

[2019-Dec-29 17:49] 127.0.0.1 GET http /? 200 OK
[2019-Dec-29 17:50] 127.0.0.1 GET http /? 200 OK
[2019-Dec-29 17:50] 127.0.0.1 GET http /static/favicon.ico? 200 OK
[2019-Dec-29 17:55] 127.0.0.1 GET http /? 200 OK
[2019-Dec-29 17:55] 127.0.0.1 GET http /static/favicon.ico? 200 OK
[2019-Dec-29 17:55] 127.0.0.1 GET http /simpledb? 200 OK
[2019-Dec-29 17:55] 127.0.0.1 GET http /favicon.ico? 5xx INTERNAL SERVER ERROR
Traceback (most recent call last):
  File "/home/jon/venv/p3/lib/python3.6/site-packages/flask/app.py", line 1813, in full_dispatch_request
    rv = self.dispatch_request()
  File "/home/jon/venv/p3/lib/python3.6/site-packages/flask/app.py", line 1791, in dispatch_request
    self.raise_routing_exception(req)
  File "/home/jon/venv/p3/lib/python3.6/site-packages/flask/app.py", line 1774, in raise_routing_exception
    raise request.routing_exception
  File "/home/jon/venv/p3/lib/python3.6/site-packages/flask/ctx.py", line 336, in match_request
    self.url_adapter.match(return_rule=True)
  File "/home/jon/venv/p3/lib/python3.6/site-packages/werkzeug/routing.py", line 1581, in match
    raise NotFound()
werkzeug.exceptions.NotFound: 404 Not Found: The requested URL was not found on the server.  If you entered the URL manually please check your spelling and try again.

[2019-Dec-29 17:55] 127.0.0.1 GET http /? 200 OK
[2019-Dec-29 17:56] 127.0.0.1 GET http /test? 200 OK
[2019-Dec-29 17:56] 127.0.0.1 GET http /test_js? 200 OK
[2019-Dec-29 17:56] 127.0.0.1 GET http /favicon.ico? 5xx INTERNAL SERVER ERROR
Traceback (most recent call last):
  File "/home/jon/venv/p3/lib/python3.6/site-packages/flask/app.py", line 1813, in full_dispatch_request
    rv = self.dispatch_request()
  File "/home/jon/venv/p3/lib/python3.6/site-packages/flask/app.py", line 1791, in dispatch_request
    self.raise_routing_exception(req)
  File "/home/jon/venv/p3/lib/python3.6/site-packages/flask/app.py", line 1774, in raise_routing_exception
    raise request.routing_exception
  File "/home/jon/venv/p3/lib/python3.6/site-packages/flask/ctx.py", line 336, in match_request
    self.url_adapter.match(return_rule=True)
  File "/home/jon/venv/p3/lib/python3.6/site-packages/werkzeug/routing.py", line 1581, in match
    raise NotFound()
werkzeug.exceptions.NotFound: 404 Not Found: The requested URL was not found on the server.  If you entered the URL manually please check your spelling and try again.

[2019-Dec-29 17:56] 127.0.0.1 GET http /hello? 200 OK
[2019-Dec-29 17:56] 127.0.0.1 GET http /favicon.ico? 5xx INTERNAL SERVER ERROR
Traceback (most recent call last):
  File "/home/jon/venv/p3/lib/python3.6/site-packages/flask/app.py", line 1813, in full_dispatch_request
    rv = self.dispatch_request()
  File "/home/jon/venv/p3/lib/python3.6/site-packages/flask/app.py", line 1791, in dispatch_request
    self.raise_routing_exception(req)
  File "/home/jon/venv/p3/lib/python3.6/site-packages/flask/app.py", line 1774, in raise_routing_exception
    raise request.routing_exception
  File "/home/jon/venv/p3/lib/python3.6/site-packages/flask/ctx.py", line 336, in match_request
    self.url_adapter.match(return_rule=True)
  File "/home/jon/venv/p3/lib/python3.6/site-packages/werkzeug/routing.py", line 1581, in match
    raise NotFound()
werkzeug.exceptions.NotFound: 404 Not Found: The requested URL was not found on the server.  If you entered the URL manually please check your spelling and try again.

[2019-Dec-29 17:56] 127.0.0.1 GET http /favicon.ico? 5xx INTERNAL SERVER ERROR
Traceback (most recent call last):
  File "/home/jon/venv/p3/lib/python3.6/site-packages/flask/app.py", line 1813, in full_dispatch_request
    rv = self.dispatch_request()
  File "/home/jon/venv/p3/lib/python3.6/site-packages/flask/app.py", line 1791, in dispatch_request
    self.raise_routing_exception(req)
  File "/home/jon/venv/p3/lib/python3.6/site-packages/flask/app.py", line 1774, in raise_routing_exception
    raise request.routing_exception
  File "/home/jon/venv/p3/lib/python3.6/site-packages/flask/ctx.py", line 336, in match_request
    self.url_adapter.match(return_rule=True)
  File "/home/jon/venv/p3/lib/python3.6/site-packages/werkzeug/routing.py", line 1581, in match
    raise NotFound()
werkzeug.exceptions.NotFound: 404 Not Found: The requested URL was not found on the server.  If you entered the URL manually please check your spelling and try again.

[2019-Dec-29 17:56] 127.0.0.1 GET http /favicon.ico? 5xx INTERNAL SERVER ERROR
Traceback (most recent call last):
  File "/home/jon/venv/p3/lib/python3.6/site-packages/flask/app.py", line 1813, in full_dispatch_request
    rv = self.dispatch_request()
  File "/home/jon/venv/p3/lib/python3.6/site-packages/flask/app.py", line 1791, in dispatch_request
    self.raise_routing_exception(req)
  File "/home/jon/venv/p3/lib/python3.6/site-packages/flask/app.py", line 1774, in raise_routing_exception
    raise request.routing_exception
  File "/home/jon/venv/p3/lib/python3.6/site-packages/flask/ctx.py", line 336, in match_request
    self.url_adapter.match(return_rule=True)
  File "/home/jon/venv/p3/lib/python3.6/site-packages/werkzeug/routing.py", line 1581, in match
    raise NotFound()
werkzeug.exceptions.NotFound: 404 Not Found: The requested URL was not found on the server.  If you entered the URL manually please check your spelling and try again.

[2019-Dec-29 17:56] 127.0.0.1 GET http /? 200 OK
[2019-Dec-29 17:57] 127.0.0.1 GET http /simpledb? 5xx INTERNAL SERVER ERROR
Traceback (most recent call last):
  File "/home/jon/venv/p3/lib/python3.6/site-packages/flask/app.py", line 1813, in full_dispatch_request
    rv = self.dispatch_request()
  File "/home/jon/venv/p3/lib/python3.6/site-packages/flask/app.py", line 1799, in dispatch_request
    return self.view_functions[rule.endpoint](**req.view_args)
  File "app.py", line 595, in simpledb
    print(con.schema_extractor.fetch_table_schema(table_name).dumps())
  File "/home/jon/venv/p3/lib/python3.6/site-packages/sqliteschema/_schema.py", line 100, in dumps
    import pytablewriter as ptw
ModuleNotFoundError: No module named 'pytablewriter'

[2019-Dec-29 17:57] 127.0.0.1 GET http /favicon.ico? 5xx INTERNAL SERVER ERROR
Traceback (most recent call last):
  File "/home/jon/venv/p3/lib/python3.6/site-packages/flask/app.py", line 1813, in full_dispatch_request
    rv = self.dispatch_request()
  File "/home/jon/venv/p3/lib/python3.6/site-packages/flask/app.py", line 1791, in dispatch_request
    self.raise_routing_exception(req)
  File "/home/jon/venv/p3/lib/python3.6/site-packages/flask/app.py", line 1774, in raise_routing_exception
    raise request.routing_exception
  File "/home/jon/venv/p3/lib/python3.6/site-packages/flask/ctx.py", line 336, in match_request
    self.url_adapter.match(return_rule=True)
  File "/home/jon/venv/p3/lib/python3.6/site-packages/werkzeug/routing.py", line 1581, in match
    raise NotFound()
werkzeug.exceptions.NotFound: 404 Not Found: The requested URL was not found on the server.  If you entered the URL manually please check your spelling and try again.

[2019-Dec-29 17:58] 127.0.0.1 GET http /simpledb? 5xx INTERNAL SERVER ERROR
Traceback (most recent call last):
  File "/home/jon/venv/p3/lib/python3.6/site-packages/flask/app.py", line 1813, in full_dispatch_request
    rv = self.dispatch_request()
  File "/home/jon/venv/p3/lib/python3.6/site-packages/flask/app.py", line 1799, in dispatch_request
    return self.view_functions[rule.endpoint](**req.view_args)
  File "app.py", line 595, in simpledb
    print(con.schema_extractor.fetch_table_schema(table_name).dumps())
  File "/home/jon/venv/p3/lib/python3.6/site-packages/sqliteschema/_schema.py", line 100, in dumps
    import pytablewriter as ptw
ModuleNotFoundError: No module named 'pytablewriter'

[2019-Dec-29 17:58] 127.0.0.1 GET http /favicon.ico? 5xx INTERNAL SERVER ERROR
Traceback (most recent call last):
  File "/home/jon/venv/p3/lib/python3.6/site-packages/flask/app.py", line 1813, in full_dispatch_request
    rv = self.dispatch_request()
  File "/home/jon/venv/p3/lib/python3.6/site-packages/flask/app.py", line 1791, in dispatch_request
    self.raise_routing_exception(req)
  File "/home/jon/venv/p3/lib/python3.6/site-packages/flask/app.py", line 1774, in raise_routing_exception
    raise request.routing_exception
  File "/home/jon/venv/p3/lib/python3.6/site-packages/flask/ctx.py", line 336, in match_request
    self.url_adapter.match(return_rule=True)
  File "/home/jon/venv/p3/lib/python3.6/site-packages/werkzeug/routing.py", line 1581, in match
    raise NotFound()
werkzeug.exceptions.NotFound: 404 Not Found: The requested URL was not found on the server.  If you entered the URL manually please check your spelling and try again.

[2019-Dec-29 18:01] 127.0.0.1 GET http /simpledb? 5xx INTERNAL SERVER ERROR
Traceback (most recent call last):
  File "/home/jon/venv/p3/lib/python3.6/site-packages/flask/app.py", line 1813, in full_dispatch_request
    rv = self.dispatch_request()
  File "/home/jon/venv/p3/lib/python3.6/site-packages/flask/app.py", line 1799, in dispatch_request
    return self.view_functions[rule.endpoint](**req.view_args)
  File "app.py", line 596, in simpledb
    print(con.schema_extractor.fetch_table_schema(table_name).dumps())
  File "/home/jon/venv/p3/lib/python3.6/site-packages/sqliteschema/_schema.py", line 100, in dumps
    import pytablewriter as ptw
ModuleNotFoundError: No module named 'pytablewriter'

[2019-Dec-29 18:01] 127.0.0.1 GET http /favicon.ico? 5xx INTERNAL SERVER ERROR
Traceback (most recent call last):
  File "/home/jon/venv/p3/lib/python3.6/site-packages/flask/app.py", line 1813, in full_dispatch_request
    rv = self.dispatch_request()
  File "/home/jon/venv/p3/lib/python3.6/site-packages/flask/app.py", line 1791, in dispatch_request
    self.raise_routing_exception(req)
  File "/home/jon/venv/p3/lib/python3.6/site-packages/flask/app.py", line 1774, in raise_routing_exception
    raise request.routing_exception
  File "/home/jon/venv/p3/lib/python3.6/site-packages/flask/ctx.py", line 336, in match_request
    self.url_adapter.match(return_rule=True)
  File "/home/jon/venv/p3/lib/python3.6/site-packages/werkzeug/routing.py", line 1581, in match
    raise NotFound()
werkzeug.exceptions.NotFound: 404 Not Found: The requested URL was not found on the server.  If you entered the URL manually please check your spelling and try again.

[2019-Dec-29 18:01] 127.0.0.1 GET http /simpledb? 5xx INTERNAL SERVER ERROR
Traceback (most recent call last):
  File "/home/jon/venv/p3/lib/python3.6/site-packages/flask/app.py", line 1813, in full_dispatch_request
    rv = self.dispatch_request()
  File "/home/jon/venv/p3/lib/python3.6/site-packages/flask/app.py", line 1799, in dispatch_request
    return self.view_functions[rule.endpoint](**req.view_args)
  File "app.py", line 596, in simpledb
    print(con.schema_extractor.fetch_table_schema(table_name).dumps())
  File "/home/jon/venv/p3/lib/python3.6/site-packages/sqliteschema/_schema.py", line 100, in dumps
    import pytablewriter as ptw
ModuleNotFoundError: No module named 'pytablewriter'

[2019-Dec-29 18:01] 127.0.0.1 GET http /favicon.ico? 5xx INTERNAL SERVER ERROR
Traceback (most recent call last):
  File "/home/jon/venv/p3/lib/python3.6/site-packages/flask/app.py", line 1813, in full_dispatch_request
    rv = self.dispatch_request()
  File "/home/jon/venv/p3/lib/python3.6/site-packages/flask/app.py", line 1791, in dispatch_request
    self.raise_routing_exception(req)
  File "/home/jon/venv/p3/lib/python3.6/site-packages/flask/app.py", line 1774, in raise_routing_exception
    raise request.routing_exception
  File "/home/jon/venv/p3/lib/python3.6/site-packages/flask/ctx.py", line 336, in match_request
    self.url_adapter.match(return_rule=True)
  File "/home/jon/venv/p3/lib/python3.6/site-packages/werkzeug/routing.py", line 1581, in match
    raise NotFound()
werkzeug.exceptions.NotFound: 404 Not Found: The requested URL was not found on the server.  If you entered the URL manually please check your spelling and try again.

[2019-Dec-29 18:02] 127.0.0.1 GET http /simpledb? 5xx INTERNAL SERVER ERROR
Traceback (most recent call last):
  File "/home/jon/venv/p3/lib/python3.6/site-packages/flask/app.py", line 1813, in full_dispatch_request
    rv = self.dispatch_request()
  File "/home/jon/venv/p3/lib/python3.6/site-packages/flask/app.py", line 1799, in dispatch_request
    return self.view_functions[rule.endpoint](**req.view_args)
  File "app.py", line 594, in simpledb
    print(con.schema_extractor.fetch_table_schema(table_name).dumps())
  File "/home/jon/venv/p3/lib/python3.6/site-packages/sqliteschema/_schema.py", line 100, in dumps
    import pytablewriter as ptw
ModuleNotFoundError: No module named 'pytablewriter'

[2019-Dec-29 18:02] 127.0.0.1 GET http /favicon.ico? 5xx INTERNAL SERVER ERROR
Traceback (most recent call last):
  File "/home/jon/venv/p3/lib/python3.6/site-packages/flask/app.py", line 1813, in full_dispatch_request
    rv = self.dispatch_request()
  File "/home/jon/venv/p3/lib/python3.6/site-packages/flask/app.py", line 1791, in dispatch_request
    self.raise_routing_exception(req)
  File "/home/jon/venv/p3/lib/python3.6/site-packages/flask/app.py", line 1774, in raise_routing_exception
    raise request.routing_exception
  File "/home/jon/venv/p3/lib/python3.6/site-packages/flask/ctx.py", line 336, in match_request
    self.url_adapter.match(return_rule=True)
  File "/home/jon/venv/p3/lib/python3.6/site-packages/werkzeug/routing.py", line 1581, in match
    raise NotFound()
werkzeug.exceptions.NotFound: 404 Not Found: The requested URL was not found on the server.  If you entered the URL manually please check your spelling and try again.

[2019-Dec-29 18:08] 127.0.0.1 GET http /simpledb? 5xx INTERNAL SERVER ERROR
Traceback (most recent call last):
  File "/home/jon/venv/p3/lib/python3.6/site-packages/flask/app.py", line 1813, in full_dispatch_request
    rv = self.dispatch_request()
  File "/home/jon/venv/p3/lib/python3.6/site-packages/flask/app.py", line 1799, in dispatch_request
    return self.view_functions[rule.endpoint](**req.view_args)
  File "app.py", line 594, in simpledb
    print(con.schema_extractor.fetch_table_schema(table_name).dumps())
  File "/home/jon/venv/p3/lib/python3.6/site-packages/sqliteschema/_schema.py", line 100, in dumps
    import pytablewriter as ptw
ModuleNotFoundError: No module named 'pytablewriter'

[2019-Dec-29 18:08] 127.0.0.1 GET http /favicon.ico? 5xx INTERNAL SERVER ERROR
Traceback (most recent call last):
  File "/home/jon/venv/p3/lib/python3.6/site-packages/flask/app.py", line 1813, in full_dispatch_request
    rv = self.dispatch_request()
  File "/home/jon/venv/p3/lib/python3.6/site-packages/flask/app.py", line 1791, in dispatch_request
    self.raise_routing_exception(req)
  File "/home/jon/venv/p3/lib/python3.6/site-packages/flask/app.py", line 1774, in raise_routing_exception
    raise request.routing_exception
  File "/home/jon/venv/p3/lib/python3.6/site-packages/flask/ctx.py", line 336, in match_request
    self.url_adapter.match(return_rule=True)
  File "/home/jon/venv/p3/lib/python3.6/site-packages/werkzeug/routing.py", line 1581, in match
    raise NotFound()
werkzeug.exceptions.NotFound: 404 Not Found: The requested URL was not found on the server.  If you entered the URL manually please check your spelling and try again.

[2019-Dec-29 18:10] 127.0.0.1 GET http /simpledb? 5xx INTERNAL SERVER ERROR
Traceback (most recent call last):
  File "/home/jon/venv/p3/lib/python3.6/site-packages/flask/app.py", line 1813, in full_dispatch_request
    rv = self.dispatch_request()
  File "/home/jon/venv/p3/lib/python3.6/site-packages/flask/app.py", line 1799, in dispatch_request
    return self.view_functions[rule.endpoint](**req.view_args)
  File "app.py", line 594, in simpledb
    print(con.schema_extractor.fetch_table_schema(table_name).dumps())
  File "/home/jon/venv/p3/lib/python3.6/site-packages/sqliteschema/_schema.py", line 100, in dumps
    import pytablewriter as ptw
ModuleNotFoundError: No module named 'pytablewriter'

[2019-Dec-29 18:10] 127.0.0.1 GET http /favicon.ico? 5xx INTERNAL SERVER ERROR
Traceback (most recent call last):
  File "/home/jon/venv/p3/lib/python3.6/site-packages/flask/app.py", line 1813, in full_dispatch_request
    rv = self.dispatch_request()
  File "/home/jon/venv/p3/lib/python3.6/site-packages/flask/app.py", line 1791, in dispatch_request
    self.raise_routing_exception(req)
  File "/home/jon/venv/p3/lib/python3.6/site-packages/flask/app.py", line 1774, in raise_routing_exception
    raise request.routing_exception
  File "/home/jon/venv/p3/lib/python3.6/site-packages/flask/ctx.py", line 336, in match_request
    self.url_adapter.match(return_rule=True)
  File "/home/jon/venv/p3/lib/python3.6/site-packages/werkzeug/routing.py", line 1581, in match
    raise NotFound()
werkzeug.exceptions.NotFound: 404 Not Found: The requested URL was not found on the server.  If you entered the URL manually please check your spelling and try again.

[2019-Dec-29 18:10] 127.0.0.1 GET http /simpledb? 5xx INTERNAL SERVER ERROR
Traceback (most recent call last):
  File "/home/jon/venv/p3/lib/python3.6/site-packages/flask/app.py", line 1813, in full_dispatch_request
    rv = self.dispatch_request()
  File "/home/jon/venv/p3/lib/python3.6/site-packages/flask/app.py", line 1799, in dispatch_request
    return self.view_functions[rule.endpoint](**req.view_args)
  File "app.py", line 594, in simpledb
    print(con.schema_extractor.fetch_table_schema(table_name).dumps())
  File "/home/jon/venv/p3/lib/python3.6/site-packages/sqliteschema/_schema.py", line 100, in dumps
    import pytablewriter as ptw
ModuleNotFoundError: No module named 'pytablewriter'

[2019-Dec-29 18:10] 127.0.0.1 GET http /favicon.ico? 5xx INTERNAL SERVER ERROR
Traceback (most recent call last):
  File "/home/jon/venv/p3/lib/python3.6/site-packages/flask/app.py", line 1813, in full_dispatch_request
    rv = self.dispatch_request()
  File "/home/jon/venv/p3/lib/python3.6/site-packages/flask/app.py", line 1791, in dispatch_request
    self.raise_routing_exception(req)
  File "/home/jon/venv/p3/lib/python3.6/site-packages/flask/app.py", line 1774, in raise_routing_exception
    raise request.routing_exception
  File "/home/jon/venv/p3/lib/python3.6/site-packages/flask/ctx.py", line 336, in match_request
    self.url_adapter.match(return_rule=True)
  File "/home/jon/venv/p3/lib/python3.6/site-packages/werkzeug/routing.py", line 1581, in match
    raise NotFound()
werkzeug.exceptions.NotFound: 404 Not Found: The requested URL was not found on the server.  If you entered the URL manually please check your spelling and try again.

[2019-Dec-29 18:11] 127.0.0.1 GET http /simpledb? 5xx INTERNAL SERVER ERROR
Traceback (most recent call last):
  File "/home/jon/venv/p3/lib/python3.6/site-packages/flask/app.py", line 1813, in full_dispatch_request
    rv = self.dispatch_request()
  File "/home/jon/venv/p3/lib/python3.6/site-packages/flask/app.py", line 1799, in dispatch_request
    return self.view_functions[rule.endpoint](**req.view_args)
  File "app.py", line 595, in simpledb
    print(con.schema_extractor.fetch_table_schema(table_name).dumps())
  File "/home/jon/venv/p3/lib/python3.6/site-packages/sqliteschema/_schema.py", line 100, in dumps
    import pytablewriter as ptw
ModuleNotFoundError: No module named 'pytablewriter'

[2019-Dec-29 18:11] 127.0.0.1 GET http /favicon.ico? 5xx INTERNAL SERVER ERROR
Traceback (most recent call last):
  File "/home/jon/venv/p3/lib/python3.6/site-packages/flask/app.py", line 1813, in full_dispatch_request
    rv = self.dispatch_request()
  File "/home/jon/venv/p3/lib/python3.6/site-packages/flask/app.py", line 1791, in dispatch_request
    self.raise_routing_exception(req)
  File "/home/jon/venv/p3/lib/python3.6/site-packages/flask/app.py", line 1774, in raise_routing_exception
    raise request.routing_exception
  File "/home/jon/venv/p3/lib/python3.6/site-packages/flask/ctx.py", line 336, in match_request
    self.url_adapter.match(return_rule=True)
  File "/home/jon/venv/p3/lib/python3.6/site-packages/werkzeug/routing.py", line 1581, in match
    raise NotFound()
werkzeug.exceptions.NotFound: 404 Not Found: The requested URL was not found on the server.  If you entered the URL manually please check your spelling and try again.

[2019-Dec-29 18:11] 127.0.0.1 GET http /simpledb? 5xx INTERNAL SERVER ERROR
Traceback (most recent call last):
  File "/home/jon/venv/p3/lib/python3.6/site-packages/flask/app.py", line 1813, in full_dispatch_request
    rv = self.dispatch_request()
  File "/home/jon/venv/p3/lib/python3.6/site-packages/flask/app.py", line 1799, in dispatch_request
    return self.view_functions[rule.endpoint](**req.view_args)
  File "app.py", line 595, in simpledb
    print(con.schema_extractor.fetch_table_schema(table_name).dumps())
  File "/home/jon/venv/p3/lib/python3.6/site-packages/sqliteschema/_schema.py", line 100, in dumps
    import pytablewriter as ptw
ModuleNotFoundError: No module named 'pytablewriter'

[2019-Dec-29 18:11] 127.0.0.1 GET http /favicon.ico? 5xx INTERNAL SERVER ERROR
Traceback (most recent call last):
  File "/home/jon/venv/p3/lib/python3.6/site-packages/flask/app.py", line 1813, in full_dispatch_request
    rv = self.dispatch_request()
  File "/home/jon/venv/p3/lib/python3.6/site-packages/flask/app.py", line 1791, in dispatch_request
    self.raise_routing_exception(req)
  File "/home/jon/venv/p3/lib/python3.6/site-packages/flask/app.py", line 1774, in raise_routing_exception
    raise request.routing_exception
  File "/home/jon/venv/p3/lib/python3.6/site-packages/flask/ctx.py", line 336, in match_request
    self.url_adapter.match(return_rule=True)
  File "/home/jon/venv/p3/lib/python3.6/site-packages/werkzeug/routing.py", line 1581, in match
    raise NotFound()
werkzeug.exceptions.NotFound: 404 Not Found: The requested URL was not found on the server.  If you entered the URL manually please check your spelling and try again.

[2019-Dec-29 18:11] 127.0.0.1 GET http /simpledb? 5xx INTERNAL SERVER ERROR
Traceback (most recent call last):
  File "/home/jon/venv/p3/lib/python3.6/site-packages/flask/app.py", line 1813, in full_dispatch_request
    rv = self.dispatch_request()
  File "/home/jon/venv/p3/lib/python3.6/site-packages/flask/app.py", line 1799, in dispatch_request
    return self.view_functions[rule.endpoint](**req.view_args)
  File "app.py", line 595, in simpledb
    print(con.schema_extractor.fetch_table_schema(table_name).dumps())
  File "/home/jon/venv/p3/lib/python3.6/site-packages/sqliteschema/_schema.py", line 100, in dumps
    import pytablewriter as ptw
ModuleNotFoundError: No module named 'pytablewriter'

[2019-Dec-29 18:11] 127.0.0.1 GET http /favicon.ico? 5xx INTERNAL SERVER ERROR
Traceback (most recent call last):
  File "/home/jon/venv/p3/lib/python3.6/site-packages/flask/app.py", line 1813, in full_dispatch_request
    rv = self.dispatch_request()
  File "/home/jon/venv/p3/lib/python3.6/site-packages/flask/app.py", line 1791, in dispatch_request
    self.raise_routing_exception(req)
  File "/home/jon/venv/p3/lib/python3.6/site-packages/flask/app.py", line 1774, in raise_routing_exception
    raise request.routing_exception
  File "/home/jon/venv/p3/lib/python3.6/site-packages/flask/ctx.py", line 336, in match_request
    self.url_adapter.match(return_rule=True)
  File "/home/jon/venv/p3/lib/python3.6/site-packages/werkzeug/routing.py", line 1581, in match
    raise NotFound()
werkzeug.exceptions.NotFound: 404 Not Found: The requested URL was not found on the server.  If you entered the URL manually please check your spelling and try again.

[2019-Dec-29 18:11] 127.0.0.1 GET http /simpledb? 5xx INTERNAL SERVER ERROR
Traceback (most recent call last):
  File "/home/jon/venv/p3/lib/python3.6/site-packages/flask/app.py", line 1813, in full_dispatch_request
    rv = self.dispatch_request()
  File "/home/jon/venv/p3/lib/python3.6/site-packages/flask/app.py", line 1799, in dispatch_request
    return self.view_functions[rule.endpoint](**req.view_args)
  File "app.py", line 595, in simpledb
    print(con.schema_extractor.fetch_table_schema(table_name).dumps())
  File "/home/jon/venv/p3/lib/python3.6/site-packages/sqliteschema/_schema.py", line 100, in dumps
    import pytablewriter as ptw
ModuleNotFoundError: No module named 'pytablewriter'

[2019-Dec-29 18:11] 127.0.0.1 GET http /favicon.ico? 5xx INTERNAL SERVER ERROR
Traceback (most recent call last):
  File "/home/jon/venv/p3/lib/python3.6/site-packages/flask/app.py", line 1813, in full_dispatch_request
    rv = self.dispatch_request()
  File "/home/jon/venv/p3/lib/python3.6/site-packages/flask/app.py", line 1791, in dispatch_request
    self.raise_routing_exception(req)
  File "/home/jon/venv/p3/lib/python3.6/site-packages/flask/app.py", line 1774, in raise_routing_exception
    raise request.routing_exception
  File "/home/jon/venv/p3/lib/python3.6/site-packages/flask/ctx.py", line 336, in match_request
    self.url_adapter.match(return_rule=True)
  File "/home/jon/venv/p3/lib/python3.6/site-packages/werkzeug/routing.py", line 1581, in match
    raise NotFound()
werkzeug.exceptions.NotFound: 404 Not Found: The requested URL was not found on the server.  If you entered the URL manually please check your spelling and try again.

[2019-Dec-29 18:12] 127.0.0.1 GET http /simpledb? 5xx INTERNAL SERVER ERROR
Traceback (most recent call last):
  File "/home/jon/venv/p3/lib/python3.6/site-packages/flask/app.py", line 1813, in full_dispatch_request
    rv = self.dispatch_request()
  File "/home/jon/venv/p3/lib/python3.6/site-packages/flask/app.py", line 1799, in dispatch_request
    return self.view_functions[rule.endpoint](**req.view_args)
  File "app.py", line 595, in simpledb
    print(con.schema_extractor.fetch_table_schema(table_name).dumps())
  File "/home/jon/venv/p3/lib/python3.6/site-packages/sqliteschema/_schema.py", line 100, in dumps
    import pytablewriter as ptw
ModuleNotFoundError: No module named 'pytablewriter'

[2019-Dec-29 18:12] 127.0.0.1 GET http /favicon.ico? 5xx INTERNAL SERVER ERROR
Traceback (most recent call last):
  File "/home/jon/venv/p3/lib/python3.6/site-packages/flask/app.py", line 1813, in full_dispatch_request
    rv = self.dispatch_request()
  File "/home/jon/venv/p3/lib/python3.6/site-packages/flask/app.py", line 1791, in dispatch_request
    self.raise_routing_exception(req)
  File "/home/jon/venv/p3/lib/python3.6/site-packages/flask/app.py", line 1774, in raise_routing_exception
    raise request.routing_exception
  File "/home/jon/venv/p3/lib/python3.6/site-packages/flask/ctx.py", line 336, in match_request
    self.url_adapter.match(return_rule=True)
  File "/home/jon/venv/p3/lib/python3.6/site-packages/werkzeug/routing.py", line 1581, in match
    raise NotFound()
werkzeug.exceptions.NotFound: 404 Not Found: The requested URL was not found on the server.  If you entered the URL manually please check your spelling and try again.

[2019-Dec-29 18:13] 127.0.0.1 GET http /simpledb? 5xx INTERNAL SERVER ERROR
Traceback (most recent call last):
  File "/home/jon/venv/p3/lib/python3.6/site-packages/flask/app.py", line 1813, in full_dispatch_request
    rv = self.dispatch_request()
  File "/home/jon/venv/p3/lib/python3.6/site-packages/flask/app.py", line 1799, in dispatch_request
    return self.view_functions[rule.endpoint](**req.view_args)
  File "app.py", line 595, in simpledb
    print(con.schema_extractor.fetch_table_schema(table_name).dumps())
  File "/home/jon/venv/p3/lib/python3.6/site-packages/sqliteschema/_schema.py", line 100, in dumps
    import pytablewriter as ptw
ModuleNotFoundError: No module named 'pytablewriter'

[2019-Dec-29 18:13] 127.0.0.1 GET http /favicon.ico? 5xx INTERNAL SERVER ERROR
Traceback (most recent call last):
  File "/home/jon/venv/p3/lib/python3.6/site-packages/flask/app.py", line 1813, in full_dispatch_request
    rv = self.dispatch_request()
  File "/home/jon/venv/p3/lib/python3.6/site-packages/flask/app.py", line 1791, in dispatch_request
    self.raise_routing_exception(req)
  File "/home/jon/venv/p3/lib/python3.6/site-packages/flask/app.py", line 1774, in raise_routing_exception
    raise request.routing_exception
  File "/home/jon/venv/p3/lib/python3.6/site-packages/flask/ctx.py", line 336, in match_request
    self.url_adapter.match(return_rule=True)
  File "/home/jon/venv/p3/lib/python3.6/site-packages/werkzeug/routing.py", line 1581, in match
    raise NotFound()
werkzeug.exceptions.NotFound: 404 Not Found: The requested URL was not found on the server.  If you entered the URL manually please check your spelling and try again.

[2019-Dec-29 18:13] 127.0.0.1 GET http /simpledb? 5xx INTERNAL SERVER ERROR
Traceback (most recent call last):
  File "/home/jon/venv/p3/lib/python3.6/site-packages/flask/app.py", line 1813, in full_dispatch_request
    rv = self.dispatch_request()
  File "/home/jon/venv/p3/lib/python3.6/site-packages/flask/app.py", line 1799, in dispatch_request
    return self.view_functions[rule.endpoint](**req.view_args)
  File "app.py", line 595, in simpledb
    print(con.schema_extractor.fetch_table_schema(table_name).dumps())
  File "/home/jon/venv/p3/lib/python3.6/site-packages/sqliteschema/_schema.py", line 100, in dumps
    import pytablewriter as ptw
ModuleNotFoundError: No module named 'pytablewriter'

