[2019-Dec-15 21:22] 127.0.0.1 GET http /favicon.ico? 5xx INTERNAL SERVER ERROR
Traceback (most recent call last):
  File "/home/jon/venv/p3/lib/python3.6/site-packages/flask/app.py", line 1813, in full_dispatch_request
    rv = self.dispatch_request()
  File "/home/jon/venv/p3/lib/python3.6/site-packages/flask/app.py", line 1791, in dispatch_request
    self.raise_routing_exception(req)
  File "/home/jon/venv/p3/lib/python3.6/site-packages/flask/app.py", line 1774, in raise_routing_exception
    raise request.routing_exception
  File "/home/jon/venv/p3/lib/python3.6/site-packages/flask/ctx.py", line 336, in match_request
    self.url_adapter.match(return_rule=True)
  File "/home/jon/venv/p3/lib/python3.6/site-packages/werkzeug/routing.py", line 1581, in match
    raise NotFound()
werkzeug.exceptions.NotFound: 404 Not Found: The requested URL was not found on the server.  If you entered the URL manually please check your spelling and try again.

[2019-Dec-15 21:24] 127.0.0.1 GET http /? 200 OK
[2019-Dec-15 21:24] 127.0.0.1 GET http /static/css/signin.css? 200 OK
[2019-Dec-15 21:24] 127.0.0.1 GET http /static/css/auto-complete.css? 200 OK
[2019-Dec-15 21:24] 127.0.0.1 GET http /static/js/jquery-1.9.0.js? 200 OK
[2019-Dec-15 21:24] 127.0.0.1 GET http /static/js/script.js? 200 OK
[2019-Dec-15 21:24] 127.0.0.1 GET http /static/js/fetch.js? 200 OK
[2019-Dec-15 21:24] 127.0.0.1 GET http /static/js/auto-complete.min.js? 200 OK
[2019-Dec-15 21:24] 127.0.0.1 GET http /static/css/scss_css.css? 200 OK
[2019-Dec-15 21:24] 127.0.0.1 GET http /static/css/my_style.css? 200 OK
[2019-Dec-15 21:24] 127.0.0.1 GET http /static/data/data.json? 200 OK
[2019-Dec-15 21:24] 127.0.0.1 GET http /static/js/autocomplete.js? 200 OK
[2019-Dec-15 21:24] 127.0.0.1 GET http /static/css/scss_css.css.map? 200 OK
[2019-Dec-15 21:24] 127.0.0.1 GET http /network2? 200 OK
[2019-Dec-15 21:24] 127.0.0.1 GET http /d3_data2? 200 OK
[2019-Dec-15 21:24] 127.0.0.1 GET http /favicon.ico? 5xx INTERNAL SERVER ERROR
Traceback (most recent call last):
  File "/home/jon/venv/p3/lib/python3.6/site-packages/flask/app.py", line 1813, in full_dispatch_request
    rv = self.dispatch_request()
  File "/home/jon/venv/p3/lib/python3.6/site-packages/flask/app.py", line 1791, in dispatch_request
    self.raise_routing_exception(req)
  File "/home/jon/venv/p3/lib/python3.6/site-packages/flask/app.py", line 1774, in raise_routing_exception
    raise request.routing_exception
  File "/home/jon/venv/p3/lib/python3.6/site-packages/flask/ctx.py", line 336, in match_request
    self.url_adapter.match(return_rule=True)
  File "/home/jon/venv/p3/lib/python3.6/site-packages/werkzeug/routing.py", line 1581, in match
    raise NotFound()
werkzeug.exceptions.NotFound: 404 Not Found: The requested URL was not found on the server.  If you entered the URL manually please check your spelling and try again.

[2019-Dec-15 21:25] 127.0.0.1 GET http /? 200 OK
[2019-Dec-15 21:25] 127.0.0.1 GET http /static/css/auto-complete.css? 200 OK
[2019-Dec-15 21:25] 127.0.0.1 GET http /static/css/signin.css? 200 OK
[2019-Dec-15 21:25] 127.0.0.1 GET http /static/js/jquery-1.9.0.js? 200 OK
[2019-Dec-15 21:25] 127.0.0.1 GET http /static/js/script.js? 200 OK
[2019-Dec-15 21:25] 127.0.0.1 GET http /static/js/fetch.js? 200 OK
[2019-Dec-15 21:25] 127.0.0.1 GET http /static/js/auto-complete.min.js? 200 OK
[2019-Dec-15 21:25] 127.0.0.1 GET http /static/css/my_style.css? 200 OK
[2019-Dec-15 21:25] 127.0.0.1 GET http /static/css/scss_css.css? 200 OK
[2019-Dec-15 21:25] 127.0.0.1 GET http /static/data/data.json? 200 OK
[2019-Dec-15 21:25] 127.0.0.1 GET http /static/js/autocomplete.js? 200 OK
[2019-Dec-15 21:25] 127.0.0.1 GET http /static/css/scss_css.css.map? 200 OK
[2019-Dec-15 21:25] 127.0.0.1 GET http /network2? 200 OK
[2019-Dec-15 21:25] 127.0.0.1 GET http /d3_data2? 200 OK
[2019-Dec-15 21:25] 127.0.0.1 GET http /favicon.ico? 5xx INTERNAL SERVER ERROR
Traceback (most recent call last):
  File "/home/jon/venv/p3/lib/python3.6/site-packages/flask/app.py", line 1813, in full_dispatch_request
    rv = self.dispatch_request()
  File "/home/jon/venv/p3/lib/python3.6/site-packages/flask/app.py", line 1791, in dispatch_request
    self.raise_routing_exception(req)
  File "/home/jon/venv/p3/lib/python3.6/site-packages/flask/app.py", line 1774, in raise_routing_exception
    raise request.routing_exception
  File "/home/jon/venv/p3/lib/python3.6/site-packages/flask/ctx.py", line 336, in match_request
    self.url_adapter.match(return_rule=True)
  File "/home/jon/venv/p3/lib/python3.6/site-packages/werkzeug/routing.py", line 1581, in match
    raise NotFound()
werkzeug.exceptions.NotFound: 404 Not Found: The requested URL was not found on the server.  If you entered the URL manually please check your spelling and try again.

[2019-Dec-15 21:26] 127.0.0.1 GET http /network2? 200 OK
[2019-Dec-15 21:26] 127.0.0.1 GET http /d3_data2? 200 OK
[2019-Dec-15 21:26] 127.0.0.1 GET http /favicon.ico? 5xx INTERNAL SERVER ERROR
Traceback (most recent call last):
  File "/home/jon/venv/p3/lib/python3.6/site-packages/flask/app.py", line 1813, in full_dispatch_request
    rv = self.dispatch_request()
  File "/home/jon/venv/p3/lib/python3.6/site-packages/flask/app.py", line 1791, in dispatch_request
    self.raise_routing_exception(req)
  File "/home/jon/venv/p3/lib/python3.6/site-packages/flask/app.py", line 1774, in raise_routing_exception
    raise request.routing_exception
  File "/home/jon/venv/p3/lib/python3.6/site-packages/flask/ctx.py", line 336, in match_request
    self.url_adapter.match(return_rule=True)
  File "/home/jon/venv/p3/lib/python3.6/site-packages/werkzeug/routing.py", line 1581, in match
    raise NotFound()
werkzeug.exceptions.NotFound: 404 Not Found: The requested URL was not found on the server.  If you entered the URL manually please check your spelling and try again.

[2019-Dec-15 21:26] 127.0.0.1 GET http /network2? 200 OK
[2019-Dec-15 21:26] 127.0.0.1 GET http /d3_data2? 200 OK
[2019-Dec-15 21:26] 127.0.0.1 GET http /favicon.ico? 5xx INTERNAL SERVER ERROR
Traceback (most recent call last):
  File "/home/jon/venv/p3/lib/python3.6/site-packages/flask/app.py", line 1813, in full_dispatch_request
    rv = self.dispatch_request()
  File "/home/jon/venv/p3/lib/python3.6/site-packages/flask/app.py", line 1791, in dispatch_request
    self.raise_routing_exception(req)
  File "/home/jon/venv/p3/lib/python3.6/site-packages/flask/app.py", line 1774, in raise_routing_exception
    raise request.routing_exception
  File "/home/jon/venv/p3/lib/python3.6/site-packages/flask/ctx.py", line 336, in match_request
    self.url_adapter.match(return_rule=True)
  File "/home/jon/venv/p3/lib/python3.6/site-packages/werkzeug/routing.py", line 1581, in match
    raise NotFound()
werkzeug.exceptions.NotFound: 404 Not Found: The requested URL was not found on the server.  If you entered the URL manually please check your spelling and try again.

[2019-Dec-15 21:26] 127.0.0.1 GET http /network2? 200 OK
[2019-Dec-15 21:26] 127.0.0.1 GET http /d3_data2? 200 OK
[2019-Dec-15 21:26] 127.0.0.1 GET http /favicon.ico? 5xx INTERNAL SERVER ERROR
Traceback (most recent call last):
  File "/home/jon/venv/p3/lib/python3.6/site-packages/flask/app.py", line 1813, in full_dispatch_request
    rv = self.dispatch_request()
  File "/home/jon/venv/p3/lib/python3.6/site-packages/flask/app.py", line 1791, in dispatch_request
    self.raise_routing_exception(req)
  File "/home/jon/venv/p3/lib/python3.6/site-packages/flask/app.py", line 1774, in raise_routing_exception
    raise request.routing_exception
  File "/home/jon/venv/p3/lib/python3.6/site-packages/flask/ctx.py", line 336, in match_request
    self.url_adapter.match(return_rule=True)
  File "/home/jon/venv/p3/lib/python3.6/site-packages/werkzeug/routing.py", line 1581, in match
    raise NotFound()
werkzeug.exceptions.NotFound: 404 Not Found: The requested URL was not found on the server.  If you entered the URL manually please check your spelling and try again.

[2019-Dec-15 21:26] 127.0.0.1 GET http /network2? 200 OK
[2019-Dec-15 21:26] 127.0.0.1 GET http /d3_data2? 200 OK
[2019-Dec-15 21:26] 127.0.0.1 GET http /favicon.ico? 5xx INTERNAL SERVER ERROR
Traceback (most recent call last):
  File "/home/jon/venv/p3/lib/python3.6/site-packages/flask/app.py", line 1813, in full_dispatch_request
    rv = self.dispatch_request()
  File "/home/jon/venv/p3/lib/python3.6/site-packages/flask/app.py", line 1791, in dispatch_request
    self.raise_routing_exception(req)
  File "/home/jon/venv/p3/lib/python3.6/site-packages/flask/app.py", line 1774, in raise_routing_exception
    raise request.routing_exception
  File "/home/jon/venv/p3/lib/python3.6/site-packages/flask/ctx.py", line 336, in match_request
    self.url_adapter.match(return_rule=True)
  File "/home/jon/venv/p3/lib/python3.6/site-packages/werkzeug/routing.py", line 1581, in match
    raise NotFound()
werkzeug.exceptions.NotFound: 404 Not Found: The requested URL was not found on the server.  If you entered the URL manually please check your spelling and try again.

[2019-Dec-15 21:26] 127.0.0.1 GET http /network2? 200 OK
[2019-Dec-15 21:26] 127.0.0.1 GET http /d3_data2? 200 OK
[2019-Dec-15 21:26] 127.0.0.1 GET http /favicon.ico? 5xx INTERNAL SERVER ERROR
Traceback (most recent call last):
  File "/home/jon/venv/p3/lib/python3.6/site-packages/flask/app.py", line 1813, in full_dispatch_request
    rv = self.dispatch_request()
  File "/home/jon/venv/p3/lib/python3.6/site-packages/flask/app.py", line 1791, in dispatch_request
    self.raise_routing_exception(req)
  File "/home/jon/venv/p3/lib/python3.6/site-packages/flask/app.py", line 1774, in raise_routing_exception
    raise request.routing_exception
  File "/home/jon/venv/p3/lib/python3.6/site-packages/flask/ctx.py", line 336, in match_request
    self.url_adapter.match(return_rule=True)
  File "/home/jon/venv/p3/lib/python3.6/site-packages/werkzeug/routing.py", line 1581, in match
    raise NotFound()
werkzeug.exceptions.NotFound: 404 Not Found: The requested URL was not found on the server.  If you entered the URL manually please check your spelling and try again.

[2019-Dec-15 21:27] 127.0.0.1 GET http /network2? 200 OK
[2019-Dec-15 21:27] 127.0.0.1 GET http /d3_data2? 200 OK
[2019-Dec-15 21:27] 127.0.0.1 GET http /favicon.ico? 5xx INTERNAL SERVER ERROR
Traceback (most recent call last):
  File "/home/jon/venv/p3/lib/python3.6/site-packages/flask/app.py", line 1813, in full_dispatch_request
    rv = self.dispatch_request()
  File "/home/jon/venv/p3/lib/python3.6/site-packages/flask/app.py", line 1791, in dispatch_request
    self.raise_routing_exception(req)
  File "/home/jon/venv/p3/lib/python3.6/site-packages/flask/app.py", line 1774, in raise_routing_exception
    raise request.routing_exception
  File "/home/jon/venv/p3/lib/python3.6/site-packages/flask/ctx.py", line 336, in match_request
    self.url_adapter.match(return_rule=True)
  File "/home/jon/venv/p3/lib/python3.6/site-packages/werkzeug/routing.py", line 1581, in match
    raise NotFound()
werkzeug.exceptions.NotFound: 404 Not Found: The requested URL was not found on the server.  If you entered the URL manually please check your spelling and try again.

[2019-Dec-15 21:30] 127.0.0.1 GET http /? 200 OK
[2019-Dec-15 21:30] 127.0.0.1 GET http /static/css/signin.css? 200 OK
[2019-Dec-15 21:30] 127.0.0.1 GET http /static/css/auto-complete.css? 200 OK
[2019-Dec-15 21:30] 127.0.0.1 GET http /static/js/jquery-1.9.0.js? 200 OK
[2019-Dec-15 21:30] 127.0.0.1 GET http /static/css/my_style.css? 200 OK
[2019-Dec-15 21:30] 127.0.0.1 GET http /static/css/scss_css.css? 200 OK
[2019-Dec-15 21:30] 127.0.0.1 GET http /static/js/script.js? 200 OK
[2019-Dec-15 21:30] 127.0.0.1 GET http /static/js/fetch.js? 200 OK
[2019-Dec-15 21:30] 127.0.0.1 GET http /static/js/auto-complete.min.js? 200 OK
[2019-Dec-15 21:30] 127.0.0.1 GET http /static/data/data.json? 200 OK
[2019-Dec-15 21:30] 127.0.0.1 GET http /static/js/autocomplete.js? 200 OK
[2019-Dec-15 21:30] 127.0.0.1 GET http /static/css/scss_css.css.map? 200 OK
[2019-Dec-15 21:30] 127.0.0.1 GET http /network3? 200 OK
[2019-Dec-15 21:30] 127.0.0.1 GET http /favicon.ico? 5xx INTERNAL SERVER ERROR
Traceback (most recent call last):
  File "/home/jon/venv/p3/lib/python3.6/site-packages/flask/app.py", line 1813, in full_dispatch_request
    rv = self.dispatch_request()
  File "/home/jon/venv/p3/lib/python3.6/site-packages/flask/app.py", line 1791, in dispatch_request
    self.raise_routing_exception(req)
  File "/home/jon/venv/p3/lib/python3.6/site-packages/flask/app.py", line 1774, in raise_routing_exception
    raise request.routing_exception
  File "/home/jon/venv/p3/lib/python3.6/site-packages/flask/ctx.py", line 336, in match_request
    self.url_adapter.match(return_rule=True)
  File "/home/jon/venv/p3/lib/python3.6/site-packages/werkzeug/routing.py", line 1581, in match
    raise NotFound()
werkzeug.exceptions.NotFound: 404 Not Found: The requested URL was not found on the server.  If you entered the URL manually please check your spelling and try again.

[2019-Dec-15 21:30] 127.0.0.1 GET http /network3? 200 OK
[2019-Dec-15 21:30] 127.0.0.1 GET http /favicon.ico? 5xx INTERNAL SERVER ERROR
Traceback (most recent call last):
  File "/home/jon/venv/p3/lib/python3.6/site-packages/flask/app.py", line 1813, in full_dispatch_request
    rv = self.dispatch_request()
  File "/home/jon/venv/p3/lib/python3.6/site-packages/flask/app.py", line 1791, in dispatch_request
    self.raise_routing_exception(req)
  File "/home/jon/venv/p3/lib/python3.6/site-packages/flask/app.py", line 1774, in raise_routing_exception
    raise request.routing_exception
  File "/home/jon/venv/p3/lib/python3.6/site-packages/flask/ctx.py", line 336, in match_request
    self.url_adapter.match(return_rule=True)
  File "/home/jon/venv/p3/lib/python3.6/site-packages/werkzeug/routing.py", line 1581, in match
    raise NotFound()
werkzeug.exceptions.NotFound: 404 Not Found: The requested URL was not found on the server.  If you entered the URL manually please check your spelling and try again.

[2019-Dec-15 21:31] 127.0.0.1 GET http /? 200 OK
[2019-Dec-15 21:31] 127.0.0.1 GET http /static/css/auto-complete.css? 200 OK
[2019-Dec-15 21:31] 127.0.0.1 GET http /static/css/signin.css? 200 OK
[2019-Dec-15 21:31] 127.0.0.1 GET http /static/js/jquery-1.9.0.js? 200 OK
[2019-Dec-15 21:31] 127.0.0.1 GET http /static/css/my_style.css? 200 OK
[2019-Dec-15 21:31] 127.0.0.1 GET http /static/css/scss_css.css? 200 OK
[2019-Dec-15 21:31] 127.0.0.1 GET http /static/js/script.js? 200 OK
[2019-Dec-15 21:31] 127.0.0.1 GET http /static/js/fetch.js? 200 OK
[2019-Dec-15 21:31] 127.0.0.1 GET http /static/js/auto-complete.min.js? 200 OK
[2019-Dec-15 21:31] 127.0.0.1 GET http /static/data/data.json? 200 OK
[2019-Dec-15 21:31] 127.0.0.1 GET http /static/js/autocomplete.js? 200 OK
[2019-Dec-15 21:31] 127.0.0.1 GET http /static/css/scss_css.css.map? 200 OK
[2019-Dec-15 21:31] 127.0.0.1 GET http /network2? 200 OK
[2019-Dec-15 21:31] 127.0.0.1 GET http /d3_data2? 200 OK
[2019-Dec-15 21:31] 127.0.0.1 GET http /favicon.ico? 5xx INTERNAL SERVER ERROR
Traceback (most recent call last):
  File "/home/jon/venv/p3/lib/python3.6/site-packages/flask/app.py", line 1813, in full_dispatch_request
    rv = self.dispatch_request()
  File "/home/jon/venv/p3/lib/python3.6/site-packages/flask/app.py", line 1791, in dispatch_request
    self.raise_routing_exception(req)
  File "/home/jon/venv/p3/lib/python3.6/site-packages/flask/app.py", line 1774, in raise_routing_exception
    raise request.routing_exception
  File "/home/jon/venv/p3/lib/python3.6/site-packages/flask/ctx.py", line 336, in match_request
    self.url_adapter.match(return_rule=True)
  File "/home/jon/venv/p3/lib/python3.6/site-packages/werkzeug/routing.py", line 1581, in match
    raise NotFound()
werkzeug.exceptions.NotFound: 404 Not Found: The requested URL was not found on the server.  If you entered the URL manually please check your spelling and try again.

[2019-Dec-15 21:32] 127.0.0.1 GET http /? 200 OK
[2019-Dec-15 21:32] 127.0.0.1 GET http /static/css/auto-complete.css? 200 OK
[2019-Dec-15 21:32] 127.0.0.1 GET http /static/css/signin.css? 200 OK
[2019-Dec-15 21:32] 127.0.0.1 GET http /static/js/script.js? 200 OK
[2019-Dec-15 21:32] 127.0.0.1 GET http /static/js/jquery-1.9.0.js? 200 OK
[2019-Dec-15 21:32] 127.0.0.1 GET http /static/css/my_style.css? 200 OK
[2019-Dec-15 21:32] 127.0.0.1 GET http /static/js/fetch.js? 200 OK
[2019-Dec-15 21:32] 127.0.0.1 GET http /static/css/scss_css.css? 200 OK
[2019-Dec-15 21:32] 127.0.0.1 GET http /static/js/auto-complete.min.js? 200 OK
[2019-Dec-15 21:32] 127.0.0.1 GET http /static/data/data.json? 200 OK
[2019-Dec-15 21:32] 127.0.0.1 GET http /static/js/autocomplete.js? 200 OK
[2019-Dec-15 21:32] 127.0.0.1 GET http /static/css/scss_css.css.map? 200 OK
[2019-Dec-15 21:32] 127.0.0.1 GET http /network1? 200 OK
[2019-Dec-15 21:32] 127.0.0.1 GET http /d3_data? 200 OK
[2019-Dec-15 21:32] 127.0.0.1 GET http /favicon.ico? 5xx INTERNAL SERVER ERROR
Traceback (most recent call last):
  File "/home/jon/venv/p3/lib/python3.6/site-packages/flask/app.py", line 1813, in full_dispatch_request
    rv = self.dispatch_request()
  File "/home/jon/venv/p3/lib/python3.6/site-packages/flask/app.py", line 1791, in dispatch_request
    self.raise_routing_exception(req)
  File "/home/jon/venv/p3/lib/python3.6/site-packages/flask/app.py", line 1774, in raise_routing_exception
    raise request.routing_exception
  File "/home/jon/venv/p3/lib/python3.6/site-packages/flask/ctx.py", line 336, in match_request
    self.url_adapter.match(return_rule=True)
  File "/home/jon/venv/p3/lib/python3.6/site-packages/werkzeug/routing.py", line 1581, in match
    raise NotFound()
werkzeug.exceptions.NotFound: 404 Not Found: The requested URL was not found on the server.  If you entered the URL manually please check your spelling and try again.

[2019-Dec-15 21:32] 127.0.0.1 GET http /network1? 200 OK
[2019-Dec-15 21:32] 127.0.0.1 GET http /d3_data? 200 OK
[2019-Dec-15 21:32] 127.0.0.1 GET http /favicon.ico? 5xx INTERNAL SERVER ERROR
Traceback (most recent call last):
  File "/home/jon/venv/p3/lib/python3.6/site-packages/flask/app.py", line 1813, in full_dispatch_request
    rv = self.dispatch_request()
  File "/home/jon/venv/p3/lib/python3.6/site-packages/flask/app.py", line 1791, in dispatch_request
    self.raise_routing_exception(req)
  File "/home/jon/venv/p3/lib/python3.6/site-packages/flask/app.py", line 1774, in raise_routing_exception
    raise request.routing_exception
  File "/home/jon/venv/p3/lib/python3.6/site-packages/flask/ctx.py", line 336, in match_request
    self.url_adapter.match(return_rule=True)
  File "/home/jon/venv/p3/lib/python3.6/site-packages/werkzeug/routing.py", line 1581, in match
    raise NotFound()
werkzeug.exceptions.NotFound: 404 Not Found: The requested URL was not found on the server.  If you entered the URL manually please check your spelling and try again.

[2019-Dec-15 21:33] 127.0.0.1 GET http /? 200 OK
[2019-Dec-15 21:33] 127.0.0.1 GET http /static/css/signin.css? 200 OK
[2019-Dec-15 21:33] 127.0.0.1 GET http /static/css/auto-complete.css? 200 OK
[2019-Dec-15 21:33] 127.0.0.1 GET http /static/css/my_style.css? 200 OK
[2019-Dec-15 21:33] 127.0.0.1 GET http /static/css/scss_css.css? 200 OK
[2019-Dec-15 21:33] 127.0.0.1 GET http /static/js/jquery-1.9.0.js? 200 OK
[2019-Dec-15 21:33] 127.0.0.1 GET http /static/js/script.js? 200 OK
[2019-Dec-15 21:33] 127.0.0.1 GET http /static/js/fetch.js? 200 OK
[2019-Dec-15 21:33] 127.0.0.1 GET http /static/js/autocomplete.js? 200 OK
[2019-Dec-15 21:33] 127.0.0.1 GET http /static/data/data.json? 200 OK
[2019-Dec-15 21:33] 127.0.0.1 GET http /static/js/auto-complete.min.js? 200 OK
[2019-Dec-15 21:33] 127.0.0.1 GET http /static/css/scss_css.css.map? 200 OK
[2019-Dec-15 21:33] 127.0.0.1 GET http /network2? 200 OK
[2019-Dec-15 21:33] 127.0.0.1 GET http /d3_data2? 200 OK
[2019-Dec-15 21:33] 127.0.0.1 GET http /favicon.ico? 5xx INTERNAL SERVER ERROR
Traceback (most recent call last):
  File "/home/jon/venv/p3/lib/python3.6/site-packages/flask/app.py", line 1813, in full_dispatch_request
    rv = self.dispatch_request()
  File "/home/jon/venv/p3/lib/python3.6/site-packages/flask/app.py", line 1791, in dispatch_request
    self.raise_routing_exception(req)
  File "/home/jon/venv/p3/lib/python3.6/site-packages/flask/app.py", line 1774, in raise_routing_exception
    raise request.routing_exception
  File "/home/jon/venv/p3/lib/python3.6/site-packages/flask/ctx.py", line 336, in match_request
    self.url_adapter.match(return_rule=True)
  File "/home/jon/venv/p3/lib/python3.6/site-packages/werkzeug/routing.py", line 1581, in match
    raise NotFound()
werkzeug.exceptions.NotFound: 404 Not Found: The requested URL was not found on the server.  If you entered the URL manually please check your spelling and try again.

[2019-Dec-15 21:33] 127.0.0.1 GET http /? 200 OK
[2019-Dec-15 21:33] 127.0.0.1 GET http /static/css/auto-complete.css? 200 OK
[2019-Dec-15 21:33] 127.0.0.1 GET http /static/css/signin.css? 200 OK
[2019-Dec-15 21:33] 127.0.0.1 GET http /static/js/jquery-1.9.0.js? 200 OK
[2019-Dec-15 21:33] 127.0.0.1 GET http /static/js/script.js? 200 OK
[2019-Dec-15 21:33] 127.0.0.1 GET http /static/js/auto-complete.min.js? 200 OK
[2019-Dec-15 21:33] 127.0.0.1 GET http /static/js/fetch.js? 200 OK
[2019-Dec-15 21:33] 127.0.0.1 GET http /static/css/my_style.css? 200 OK
[2019-Dec-15 21:33] 127.0.0.1 GET http /static/css/scss_css.css? 200 OK
[2019-Dec-15 21:33] 127.0.0.1 GET http /static/data/data.json? 200 OK
[2019-Dec-15 21:33] 127.0.0.1 GET http /static/js/autocomplete.js? 200 OK
[2019-Dec-15 21:33] 127.0.0.1 GET http /static/css/scss_css.css.map? 200 OK
[2019-Dec-15 21:33] 127.0.0.1 GET http /network3? 200 OK
[2019-Dec-15 21:33] 127.0.0.1 GET http /favicon.ico? 5xx INTERNAL SERVER ERROR
Traceback (most recent call last):
  File "/home/jon/venv/p3/lib/python3.6/site-packages/flask/app.py", line 1813, in full_dispatch_request
    rv = self.dispatch_request()
  File "/home/jon/venv/p3/lib/python3.6/site-packages/flask/app.py", line 1791, in dispatch_request
    self.raise_routing_exception(req)
  File "/home/jon/venv/p3/lib/python3.6/site-packages/flask/app.py", line 1774, in raise_routing_exception
    raise request.routing_exception
  File "/home/jon/venv/p3/lib/python3.6/site-packages/flask/ctx.py", line 336, in match_request
    self.url_adapter.match(return_rule=True)
  File "/home/jon/venv/p3/lib/python3.6/site-packages/werkzeug/routing.py", line 1581, in match
    raise NotFound()
werkzeug.exceptions.NotFound: 404 Not Found: The requested URL was not found on the server.  If you entered the URL manually please check your spelling and try again.

[2019-Dec-15 21:34] 127.0.0.1 GET http /network3? 200 OK
[2019-Dec-15 21:34] 127.0.0.1 GET http /favicon.ico? 5xx INTERNAL SERVER ERROR
Traceback (most recent call last):
  File "/home/jon/venv/p3/lib/python3.6/site-packages/flask/app.py", line 1813, in full_dispatch_request
    rv = self.dispatch_request()
  File "/home/jon/venv/p3/lib/python3.6/site-packages/flask/app.py", line 1791, in dispatch_request
    self.raise_routing_exception(req)
  File "/home/jon/venv/p3/lib/python3.6/site-packages/flask/app.py", line 1774, in raise_routing_exception
    raise request.routing_exception
  File "/home/jon/venv/p3/lib/python3.6/site-packages/flask/ctx.py", line 336, in match_request
    self.url_adapter.match(return_rule=True)
  File "/home/jon/venv/p3/lib/python3.6/site-packages/werkzeug/routing.py", line 1581, in match
    raise NotFound()
werkzeug.exceptions.NotFound: 404 Not Found: The requested URL was not found on the server.  If you entered the URL manually please check your spelling and try again.

[2019-Dec-15 22:02] 127.0.0.1 GET http /network3? 200 OK
[2019-Dec-15 22:02] 127.0.0.1 GET http /favicon.ico? 5xx INTERNAL SERVER ERROR
Traceback (most recent call last):
  File "/home/jon/venv/p3/lib/python3.6/site-packages/flask/app.py", line 1813, in full_dispatch_request
    rv = self.dispatch_request()
  File "/home/jon/venv/p3/lib/python3.6/site-packages/flask/app.py", line 1791, in dispatch_request
    self.raise_routing_exception(req)
  File "/home/jon/venv/p3/lib/python3.6/site-packages/flask/app.py", line 1774, in raise_routing_exception
    raise request.routing_exception
  File "/home/jon/venv/p3/lib/python3.6/site-packages/flask/ctx.py", line 336, in match_request
    self.url_adapter.match(return_rule=True)
  File "/home/jon/venv/p3/lib/python3.6/site-packages/werkzeug/routing.py", line 1581, in match
    raise NotFound()
werkzeug.exceptions.NotFound: 404 Not Found: The requested URL was not found on the server.  If you entered the URL manually please check your spelling and try again.

[2019-Dec-16 20:18] 127.0.0.1 GET http /? 200 OK
[2019-Dec-16 20:18] 127.0.0.1 GET http /static/css/auto-complete.css? 304 NOT MODIFIED
[2019-Dec-16 20:18] 127.0.0.1 GET http /static/js/jquery-1.9.0.js? 304 NOT MODIFIED
[2019-Dec-16 20:18] 127.0.0.1 GET http /static/css/signin.css? 304 NOT MODIFIED
[2019-Dec-16 20:18] 127.0.0.1 GET http /static/js/script.js? 304 NOT MODIFIED
[2019-Dec-16 20:18] 127.0.0.1 GET http /static/js/fetch.js? 304 NOT MODIFIED
[2019-Dec-16 20:18] 127.0.0.1 GET http /static/css/my_style.css? 304 NOT MODIFIED
[2019-Dec-16 20:18] 127.0.0.1 GET http /static/css/scss_css.css? 304 NOT MODIFIED
[2019-Dec-16 20:18] 127.0.0.1 GET http /static/js/auto-complete.min.js? 304 NOT MODIFIED
[2019-Dec-16 20:18] 127.0.0.1 GET http /static/data/data.json? 304 NOT MODIFIED
[2019-Dec-16 20:18] 127.0.0.1 GET http /static/js/autocomplete.js? 304 NOT MODIFIED
[2019-Dec-16 20:18] 127.0.0.1 GET http /network2? 200 OK
[2019-Dec-16 20:18] 127.0.0.1 GET http /d3_data2? 200 OK
[2019-Dec-16 20:18] 127.0.0.1 GET http /favicon.ico? 5xx INTERNAL SERVER ERROR
Traceback (most recent call last):
  File "/home/jon/venv/p3/lib/python3.6/site-packages/flask/app.py", line 1813, in full_dispatch_request
    rv = self.dispatch_request()
  File "/home/jon/venv/p3/lib/python3.6/site-packages/flask/app.py", line 1791, in dispatch_request
    self.raise_routing_exception(req)
  File "/home/jon/venv/p3/lib/python3.6/site-packages/flask/app.py", line 1774, in raise_routing_exception
    raise request.routing_exception
  File "/home/jon/venv/p3/lib/python3.6/site-packages/flask/ctx.py", line 336, in match_request
    self.url_adapter.match(return_rule=True)
  File "/home/jon/venv/p3/lib/python3.6/site-packages/werkzeug/routing.py", line 1581, in match
    raise NotFound()
werkzeug.exceptions.NotFound: 404 Not Found: The requested URL was not found on the server.  If you entered the URL manually please check your spelling and try again.

[2019-Dec-16 20:19] 127.0.0.1 GET http /? 200 OK
[2019-Dec-16 20:19] 127.0.0.1 GET http /network3? 200 OK
[2019-Dec-16 20:19] 127.0.0.1 GET http /favicon.ico? 5xx INTERNAL SERVER ERROR
Traceback (most recent call last):
  File "/home/jon/venv/p3/lib/python3.6/site-packages/flask/app.py", line 1813, in full_dispatch_request
    rv = self.dispatch_request()
  File "/home/jon/venv/p3/lib/python3.6/site-packages/flask/app.py", line 1791, in dispatch_request
    self.raise_routing_exception(req)
  File "/home/jon/venv/p3/lib/python3.6/site-packages/flask/app.py", line 1774, in raise_routing_exception
    raise request.routing_exception
  File "/home/jon/venv/p3/lib/python3.6/site-packages/flask/ctx.py", line 336, in match_request
    self.url_adapter.match(return_rule=True)
  File "/home/jon/venv/p3/lib/python3.6/site-packages/werkzeug/routing.py", line 1581, in match
    raise NotFound()
werkzeug.exceptions.NotFound: 404 Not Found: The requested URL was not found on the server.  If you entered the URL manually please check your spelling and try again.

[2019-Dec-16 20:23] 127.0.0.1 GET http /? 200 OK
[2019-Dec-16 20:23] 127.0.0.1 GET http /network2? 200 OK
[2019-Dec-16 20:23] 127.0.0.1 GET http /d3_data2? 200 OK
[2019-Dec-16 20:23] 127.0.0.1 GET http /favicon.ico? 5xx INTERNAL SERVER ERROR
Traceback (most recent call last):
  File "/home/jon/venv/p3/lib/python3.6/site-packages/flask/app.py", line 1813, in full_dispatch_request
    rv = self.dispatch_request()
  File "/home/jon/venv/p3/lib/python3.6/site-packages/flask/app.py", line 1791, in dispatch_request
    self.raise_routing_exception(req)
  File "/home/jon/venv/p3/lib/python3.6/site-packages/flask/app.py", line 1774, in raise_routing_exception
    raise request.routing_exception
  File "/home/jon/venv/p3/lib/python3.6/site-packages/flask/ctx.py", line 336, in match_request
    self.url_adapter.match(return_rule=True)
  File "/home/jon/venv/p3/lib/python3.6/site-packages/werkzeug/routing.py", line 1581, in match
    raise NotFound()
werkzeug.exceptions.NotFound: 404 Not Found: The requested URL was not found on the server.  If you entered the URL manually please check your spelling and try again.

[2019-Dec-16 20:30] 127.0.0.1 GET http /? 200 OK
[2019-Dec-16 20:30] 127.0.0.1 GET http /network3? 200 OK
[2019-Dec-16 20:30] 127.0.0.1 GET http /favicon.ico? 5xx INTERNAL SERVER ERROR
Traceback (most recent call last):
  File "/home/jon/venv/p3/lib/python3.6/site-packages/flask/app.py", line 1813, in full_dispatch_request
    rv = self.dispatch_request()
  File "/home/jon/venv/p3/lib/python3.6/site-packages/flask/app.py", line 1791, in dispatch_request
    self.raise_routing_exception(req)
  File "/home/jon/venv/p3/lib/python3.6/site-packages/flask/app.py", line 1774, in raise_routing_exception
    raise request.routing_exception
  File "/home/jon/venv/p3/lib/python3.6/site-packages/flask/ctx.py", line 336, in match_request
    self.url_adapter.match(return_rule=True)
  File "/home/jon/venv/p3/lib/python3.6/site-packages/werkzeug/routing.py", line 1581, in match
    raise NotFound()
werkzeug.exceptions.NotFound: 404 Not Found: The requested URL was not found on the server.  If you entered the URL manually please check your spelling and try again.

[2019-Dec-16 20:30] 127.0.0.1 GET http /? 200 OK
[2019-Dec-16 20:30] 127.0.0.1 GET http /network2? 200 OK
[2019-Dec-16 20:30] 127.0.0.1 GET http /d3_data2? 200 OK
[2019-Dec-16 20:30] 127.0.0.1 GET http /favicon.ico? 5xx INTERNAL SERVER ERROR
Traceback (most recent call last):
  File "/home/jon/venv/p3/lib/python3.6/site-packages/flask/app.py", line 1813, in full_dispatch_request
    rv = self.dispatch_request()
  File "/home/jon/venv/p3/lib/python3.6/site-packages/flask/app.py", line 1791, in dispatch_request
    self.raise_routing_exception(req)
  File "/home/jon/venv/p3/lib/python3.6/site-packages/flask/app.py", line 1774, in raise_routing_exception
    raise request.routing_exception
  File "/home/jon/venv/p3/lib/python3.6/site-packages/flask/ctx.py", line 336, in match_request
    self.url_adapter.match(return_rule=True)
  File "/home/jon/venv/p3/lib/python3.6/site-packages/werkzeug/routing.py", line 1581, in match
    raise NotFound()
werkzeug.exceptions.NotFound: 404 Not Found: The requested URL was not found on the server.  If you entered the URL manually please check your spelling and try again.

[2019-Dec-16 20:54] 127.0.0.1 GET http /network2? 200 OK
[2019-Dec-16 20:54] 127.0.0.1 GET http /d3_data2? 200 OK
[2019-Dec-16 20:54] 127.0.0.1 GET http /favicon.ico? 5xx INTERNAL SERVER ERROR
Traceback (most recent call last):
  File "/home/jon/venv/p3/lib/python3.6/site-packages/flask/app.py", line 1813, in full_dispatch_request
    rv = self.dispatch_request()
  File "/home/jon/venv/p3/lib/python3.6/site-packages/flask/app.py", line 1791, in dispatch_request
    self.raise_routing_exception(req)
  File "/home/jon/venv/p3/lib/python3.6/site-packages/flask/app.py", line 1774, in raise_routing_exception
    raise request.routing_exception
  File "/home/jon/venv/p3/lib/python3.6/site-packages/flask/ctx.py", line 336, in match_request
    self.url_adapter.match(return_rule=True)
  File "/home/jon/venv/p3/lib/python3.6/site-packages/werkzeug/routing.py", line 1581, in match
    raise NotFound()
werkzeug.exceptions.NotFound: 404 Not Found: The requested URL was not found on the server.  If you entered the URL manually please check your spelling and try again.

[2019-Dec-16 20:59] 127.0.0.1 GET http /network2? 200 OK
[2019-Dec-16 20:59] 127.0.0.1 GET http /d3_data2? 200 OK
[2019-Dec-16 20:59] 127.0.0.1 GET http /favicon.ico? 5xx INTERNAL SERVER ERROR
Traceback (most recent call last):
  File "/home/jon/venv/p3/lib/python3.6/site-packages/flask/app.py", line 1813, in full_dispatch_request
    rv = self.dispatch_request()
  File "/home/jon/venv/p3/lib/python3.6/site-packages/flask/app.py", line 1791, in dispatch_request
    self.raise_routing_exception(req)
  File "/home/jon/venv/p3/lib/python3.6/site-packages/flask/app.py", line 1774, in raise_routing_exception
    raise request.routing_exception
  File "/home/jon/venv/p3/lib/python3.6/site-packages/flask/ctx.py", line 336, in match_request
    self.url_adapter.match(return_rule=True)
  File "/home/jon/venv/p3/lib/python3.6/site-packages/werkzeug/routing.py", line 1581, in match
    raise NotFound()
werkzeug.exceptions.NotFound: 404 Not Found: The requested URL was not found on the server.  If you entered the URL manually please check your spelling and try again.

[2019-Dec-16 21:05] 127.0.0.1 GET http /? 200 OK
[2019-Dec-16 21:05] 127.0.0.1 GET http /static/css/auto-complete.css? 200 OK
[2019-Dec-16 21:05] 127.0.0.1 GET http /static/css/signin.css? 200 OK
[2019-Dec-16 21:05] 127.0.0.1 GET http /static/css/scss_css.css? 200 OK
[2019-Dec-16 21:05] 127.0.0.1 GET http /static/js/script.js? 200 OK
[2019-Dec-16 21:05] 127.0.0.1 GET http /static/js/fetch.js? 200 OK
[2019-Dec-16 21:05] 127.0.0.1 GET http /static/js/jquery-1.9.0.js? 200 OK
[2019-Dec-16 21:05] 127.0.0.1 GET http /static/css/my_style.css? 200 OK
[2019-Dec-16 21:05] 127.0.0.1 GET http /static/js/auto-complete.min.js? 200 OK
[2019-Dec-16 21:05] 127.0.0.1 GET http /static/js/autocomplete.js? 200 OK
[2019-Dec-16 21:05] 127.0.0.1 GET http /static/data/data.json? 200 OK
[2019-Dec-16 21:05] 127.0.0.1 GET http /static/css/scss_css.css.map? 200 OK
[2019-Dec-16 21:05] 127.0.0.1 GET http /network1? 200 OK
[2019-Dec-16 21:05] 127.0.0.1 GET http /d3_data? 200 OK
[2019-Dec-16 21:05] 127.0.0.1 GET http /favicon.ico? 5xx INTERNAL SERVER ERROR
Traceback (most recent call last):
  File "/home/jon/venv/p3/lib/python3.6/site-packages/flask/app.py", line 1813, in full_dispatch_request
    rv = self.dispatch_request()
  File "/home/jon/venv/p3/lib/python3.6/site-packages/flask/app.py", line 1791, in dispatch_request
    self.raise_routing_exception(req)
  File "/home/jon/venv/p3/lib/python3.6/site-packages/flask/app.py", line 1774, in raise_routing_exception
    raise request.routing_exception
  File "/home/jon/venv/p3/lib/python3.6/site-packages/flask/ctx.py", line 336, in match_request
    self.url_adapter.match(return_rule=True)
  File "/home/jon/venv/p3/lib/python3.6/site-packages/werkzeug/routing.py", line 1581, in match
    raise NotFound()
werkzeug.exceptions.NotFound: 404 Not Found: The requested URL was not found on the server.  If you entered the URL manually please check your spelling and try again.

[2019-Dec-16 21:05] 127.0.0.1 GET http /? 200 OK
[2019-Dec-16 21:05] 127.0.0.1 GET http /static/css/auto-complete.css? 200 OK
[2019-Dec-16 21:05] 127.0.0.1 GET http /static/css/signin.css? 200 OK
[2019-Dec-16 21:05] 127.0.0.1 GET http /static/js/jquery-1.9.0.js? 200 OK
[2019-Dec-16 21:05] 127.0.0.1 GET http /static/js/script.js? 200 OK
[2019-Dec-16 21:05] 127.0.0.1 GET http /static/css/scss_css.css? 200 OK
[2019-Dec-16 21:05] 127.0.0.1 GET http /static/js/fetch.js? 200 OK
[2019-Dec-16 21:05] 127.0.0.1 GET http /static/css/my_style.css? 200 OK
[2019-Dec-16 21:05] 127.0.0.1 GET http /static/js/auto-complete.min.js? 200 OK
[2019-Dec-16 21:05] 127.0.0.1 GET http /static/js/autocomplete.js? 200 OK
[2019-Dec-16 21:05] 127.0.0.1 GET http /static/data/data.json? 200 OK
[2019-Dec-16 21:05] 127.0.0.1 GET http /static/css/scss_css.css.map? 200 OK
[2019-Dec-16 21:05] 127.0.0.1 GET http /network2? 200 OK
[2019-Dec-16 21:05] 127.0.0.1 GET http /d3_data2? 200 OK
[2019-Dec-16 21:05] 127.0.0.1 GET http /favicon.ico? 5xx INTERNAL SERVER ERROR
Traceback (most recent call last):
  File "/home/jon/venv/p3/lib/python3.6/site-packages/flask/app.py", line 1813, in full_dispatch_request
    rv = self.dispatch_request()
  File "/home/jon/venv/p3/lib/python3.6/site-packages/flask/app.py", line 1791, in dispatch_request
    self.raise_routing_exception(req)
  File "/home/jon/venv/p3/lib/python3.6/site-packages/flask/app.py", line 1774, in raise_routing_exception
    raise request.routing_exception
  File "/home/jon/venv/p3/lib/python3.6/site-packages/flask/ctx.py", line 336, in match_request
    self.url_adapter.match(return_rule=True)
  File "/home/jon/venv/p3/lib/python3.6/site-packages/werkzeug/routing.py", line 1581, in match
    raise NotFound()
werkzeug.exceptions.NotFound: 404 Not Found: The requested URL was not found on the server.  If you entered the URL manually please check your spelling and try again.

[2019-Dec-16 21:30] 127.0.0.1 GET http /? 200 OK
[2019-Dec-16 21:30] 127.0.0.1 GET http /static/css/auto-complete.css? 200 OK
[2019-Dec-16 21:30] 127.0.0.1 GET http /static/css/signin.css? 200 OK
[2019-Dec-16 21:30] 127.0.0.1 GET http /static/js/script.js? 200 OK
[2019-Dec-16 21:30] 127.0.0.1 GET http /static/js/jquery-1.9.0.js? 200 OK
[2019-Dec-16 21:30] 127.0.0.1 GET http /static/js/fetch.js? 200 OK
[2019-Dec-16 21:30] 127.0.0.1 GET http /static/js/auto-complete.min.js? 200 OK
[2019-Dec-16 21:30] 127.0.0.1 GET http /static/css/my_style.css? 200 OK
[2019-Dec-16 21:30] 127.0.0.1 GET http /static/css/scss_css.css? 200 OK
[2019-Dec-16 21:30] 127.0.0.1 GET http /static/data/data.json? 200 OK
[2019-Dec-16 21:30] 127.0.0.1 GET http /static/js/autocomplete.js? 200 OK
[2019-Dec-16 21:30] 127.0.0.1 GET http /static/css/scss_css.css.map? 200 OK
[2019-Dec-16 21:30] 127.0.0.1 GET http /network3? 200 OK
[2019-Dec-16 21:30] 127.0.0.1 GET http /favicon.ico? 5xx INTERNAL SERVER ERROR
Traceback (most recent call last):
  File "/home/jon/venv/p3/lib/python3.6/site-packages/flask/app.py", line 1813, in full_dispatch_request
    rv = self.dispatch_request()
  File "/home/jon/venv/p3/lib/python3.6/site-packages/flask/app.py", line 1791, in dispatch_request
    self.raise_routing_exception(req)
  File "/home/jon/venv/p3/lib/python3.6/site-packages/flask/app.py", line 1774, in raise_routing_exception
    raise request.routing_exception
  File "/home/jon/venv/p3/lib/python3.6/site-packages/flask/ctx.py", line 336, in match_request
    self.url_adapter.match(return_rule=True)
  File "/home/jon/venv/p3/lib/python3.6/site-packages/werkzeug/routing.py", line 1581, in match
    raise NotFound()
werkzeug.exceptions.NotFound: 404 Not Found: The requested URL was not found on the server.  If you entered the URL manually please check your spelling and try again.

[2019-Dec-16 21:34] 127.0.0.1 GET http /network3? 200 OK
[2019-Dec-16 21:34] 127.0.0.1 GET http /favicon.ico? 5xx INTERNAL SERVER ERROR
Traceback (most recent call last):
  File "/home/jon/venv/p3/lib/python3.6/site-packages/flask/app.py", line 1813, in full_dispatch_request
    rv = self.dispatch_request()
  File "/home/jon/venv/p3/lib/python3.6/site-packages/flask/app.py", line 1791, in dispatch_request
    self.raise_routing_exception(req)
  File "/home/jon/venv/p3/lib/python3.6/site-packages/flask/app.py", line 1774, in raise_routing_exception
    raise request.routing_exception
  File "/home/jon/venv/p3/lib/python3.6/site-packages/flask/ctx.py", line 336, in match_request
    self.url_adapter.match(return_rule=True)
  File "/home/jon/venv/p3/lib/python3.6/site-packages/werkzeug/routing.py", line 1581, in match
    raise NotFound()
werkzeug.exceptions.NotFound: 404 Not Found: The requested URL was not found on the server.  If you entered the URL manually please check your spelling and try again.

[2019-Dec-16 21:37] 127.0.0.1 GET http /network3? 200 OK
[2019-Dec-16 21:37] 127.0.0.1 GET http /favicon.ico? 5xx INTERNAL SERVER ERROR
Traceback (most recent call last):
  File "/home/jon/venv/p3/lib/python3.6/site-packages/flask/app.py", line 1813, in full_dispatch_request
    rv = self.dispatch_request()
  File "/home/jon/venv/p3/lib/python3.6/site-packages/flask/app.py", line 1791, in dispatch_request
    self.raise_routing_exception(req)
  File "/home/jon/venv/p3/lib/python3.6/site-packages/flask/app.py", line 1774, in raise_routing_exception
    raise request.routing_exception
  File "/home/jon/venv/p3/lib/python3.6/site-packages/flask/ctx.py", line 336, in match_request
    self.url_adapter.match(return_rule=True)
  File "/home/jon/venv/p3/lib/python3.6/site-packages/werkzeug/routing.py", line 1581, in match
    raise NotFound()
werkzeug.exceptions.NotFound: 404 Not Found: The requested URL was not found on the server.  If you entered the URL manually please check your spelling and try again.

[2019-Dec-16 21:38] 127.0.0.1 GET http /network3? 200 OK
[2019-Dec-16 21:38] 127.0.0.1 GET http /favicon.ico? 5xx INTERNAL SERVER ERROR
Traceback (most recent call last):
  File "/home/jon/venv/p3/lib/python3.6/site-packages/flask/app.py", line 1813, in full_dispatch_request
    rv = self.dispatch_request()
  File "/home/jon/venv/p3/lib/python3.6/site-packages/flask/app.py", line 1791, in dispatch_request
    self.raise_routing_exception(req)
  File "/home/jon/venv/p3/lib/python3.6/site-packages/flask/app.py", line 1774, in raise_routing_exception
    raise request.routing_exception
  File "/home/jon/venv/p3/lib/python3.6/site-packages/flask/ctx.py", line 336, in match_request
    self.url_adapter.match(return_rule=True)
  File "/home/jon/venv/p3/lib/python3.6/site-packages/werkzeug/routing.py", line 1581, in match
    raise NotFound()
werkzeug.exceptions.NotFound: 404 Not Found: The requested URL was not found on the server.  If you entered the URL manually please check your spelling and try again.

[2019-Dec-16 21:51] 127.0.0.1 GET http /? 200 OK
[2019-Dec-16 21:51] 127.0.0.1 GET http /static/css/auto-complete.css? 200 OK
[2019-Dec-16 21:51] 127.0.0.1 GET http /static/css/signin.css? 200 OK
[2019-Dec-16 21:51] 127.0.0.1 GET http /static/js/jquery-1.9.0.js? 200 OK
[2019-Dec-16 21:51] 127.0.0.1 GET http /static/js/fetch.js? 200 OK
[2019-Dec-16 21:51] 127.0.0.1 GET http /static/js/script.js? 200 OK
[2019-Dec-16 21:51] 127.0.0.1 GET http /static/css/scss_css.css? 200 OK
[2019-Dec-16 21:51] 127.0.0.1 GET http /static/css/my_style.css? 200 OK
[2019-Dec-16 21:51] 127.0.0.1 GET http /static/js/auto-complete.min.js? 200 OK
[2019-Dec-16 21:51] 127.0.0.1 GET http /static/js/autocomplete.js? 200 OK
[2019-Dec-16 21:51] 127.0.0.1 GET http /static/data/data.json? 200 OK
[2019-Dec-16 21:51] 127.0.0.1 GET http /static/css/scss_css.css.map? 200 OK
[2019-Dec-16 21:51] 127.0.0.1 GET http /network3? 200 OK
[2019-Dec-16 21:51] 127.0.0.1 GET http /favicon.ico? 5xx INTERNAL SERVER ERROR
Traceback (most recent call last):
  File "/home/jon/venv/p3/lib/python3.6/site-packages/flask/app.py", line 1813, in full_dispatch_request
    rv = self.dispatch_request()
  File "/home/jon/venv/p3/lib/python3.6/site-packages/flask/app.py", line 1791, in dispatch_request
    self.raise_routing_exception(req)
  File "/home/jon/venv/p3/lib/python3.6/site-packages/flask/app.py", line 1774, in raise_routing_exception
    raise request.routing_exception
  File "/home/jon/venv/p3/lib/python3.6/site-packages/flask/ctx.py", line 336, in match_request
    self.url_adapter.match(return_rule=True)
  File "/home/jon/venv/p3/lib/python3.6/site-packages/werkzeug/routing.py", line 1581, in match
    raise NotFound()
werkzeug.exceptions.NotFound: 404 Not Found: The requested URL was not found on the server.  If you entered the URL manually please check your spelling and try again.

[2019-Dec-16 21:52] 127.0.0.1 GET http /network3? 200 OK
[2019-Dec-16 21:53] 127.0.0.1 GET http /favicon.ico? 5xx INTERNAL SERVER ERROR
Traceback (most recent call last):
  File "/home/jon/venv/p3/lib/python3.6/site-packages/flask/app.py", line 1813, in full_dispatch_request
    rv = self.dispatch_request()
  File "/home/jon/venv/p3/lib/python3.6/site-packages/flask/app.py", line 1791, in dispatch_request
    self.raise_routing_exception(req)
  File "/home/jon/venv/p3/lib/python3.6/site-packages/flask/app.py", line 1774, in raise_routing_exception
    raise request.routing_exception
  File "/home/jon/venv/p3/lib/python3.6/site-packages/flask/ctx.py", line 336, in match_request
    self.url_adapter.match(return_rule=True)
  File "/home/jon/venv/p3/lib/python3.6/site-packages/werkzeug/routing.py", line 1581, in match
    raise NotFound()
werkzeug.exceptions.NotFound: 404 Not Found: The requested URL was not found on the server.  If you entered the URL manually please check your spelling and try again.

[2019-Dec-16 21:53] 127.0.0.1 GET http /network3? 200 OK
[2019-Dec-16 21:53] 127.0.0.1 GET http /favicon.ico? 5xx INTERNAL SERVER ERROR
Traceback (most recent call last):
  File "/home/jon/venv/p3/lib/python3.6/site-packages/flask/app.py", line 1813, in full_dispatch_request
    rv = self.dispatch_request()
  File "/home/jon/venv/p3/lib/python3.6/site-packages/flask/app.py", line 1791, in dispatch_request
    self.raise_routing_exception(req)
  File "/home/jon/venv/p3/lib/python3.6/site-packages/flask/app.py", line 1774, in raise_routing_exception
    raise request.routing_exception
  File "/home/jon/venv/p3/lib/python3.6/site-packages/flask/ctx.py", line 336, in match_request
    self.url_adapter.match(return_rule=True)
  File "/home/jon/venv/p3/lib/python3.6/site-packages/werkzeug/routing.py", line 1581, in match
    raise NotFound()
werkzeug.exceptions.NotFound: 404 Not Found: The requested URL was not found on the server.  If you entered the URL manually please check your spelling and try again.

[2019-Dec-17 20:14] 127.0.0.1 GET http /? 200 OK
[2019-Dec-17 20:14] 127.0.0.1 GET http /static/css/auto-complete.css? 304 NOT MODIFIED
[2019-Dec-17 20:14] 127.0.0.1 GET http /static/css/scss_css.css? 304 NOT MODIFIED
[2019-Dec-17 20:14] 127.0.0.1 GET http /static/css/signin.css? 304 NOT MODIFIED
[2019-Dec-17 20:14] 127.0.0.1 GET http /static/js/fetch.js? 304 NOT MODIFIED
[2019-Dec-17 20:14] 127.0.0.1 GET http /static/js/script.js? 304 NOT MODIFIED
[2019-Dec-17 20:14] 127.0.0.1 GET http /static/js/jquery-1.9.0.js? 304 NOT MODIFIED
[2019-Dec-17 20:14] 127.0.0.1 GET http /static/css/my_style.css? 304 NOT MODIFIED
[2019-Dec-17 20:14] 127.0.0.1 GET http /static/js/auto-complete.min.js? 304 NOT MODIFIED
[2019-Dec-17 20:14] 127.0.0.1 GET http /static/data/data.json? 304 NOT MODIFIED
[2019-Dec-17 20:14] 127.0.0.1 GET http /static/js/autocomplete.js? 304 NOT MODIFIED
[2019-Dec-17 20:14] 127.0.0.1 GET http /? 200 OK
[2019-Dec-17 20:14] 127.0.0.1 GET http /network2? 200 OK
[2019-Dec-17 20:14] 127.0.0.1 GET http /d3_data2? 200 OK
[2019-Dec-17 20:14] 127.0.0.1 GET http /favicon.ico? 5xx INTERNAL SERVER ERROR
Traceback (most recent call last):
  File "/home/jon/venv/p3/lib/python3.6/site-packages/flask/app.py", line 1813, in full_dispatch_request
    rv = self.dispatch_request()
  File "/home/jon/venv/p3/lib/python3.6/site-packages/flask/app.py", line 1791, in dispatch_request
    self.raise_routing_exception(req)
  File "/home/jon/venv/p3/lib/python3.6/site-packages/flask/app.py", line 1774, in raise_routing_exception
    raise request.routing_exception
  File "/home/jon/venv/p3/lib/python3.6/site-packages/flask/ctx.py", line 336, in match_request
    self.url_adapter.match(return_rule=True)
  File "/home/jon/venv/p3/lib/python3.6/site-packages/werkzeug/routing.py", line 1581, in match
    raise NotFound()
werkzeug.exceptions.NotFound: 404 Not Found: The requested URL was not found on the server.  If you entered the URL manually please check your spelling and try again.

[2019-Dec-17 20:17] 127.0.0.1 GET http /? 200 OK
[2019-Dec-17 20:17] 127.0.0.1 GET http /network3? 200 OK
[2019-Dec-17 20:17] 127.0.0.1 GET http /favicon.ico? 5xx INTERNAL SERVER ERROR
Traceback (most recent call last):
  File "/home/jon/venv/p3/lib/python3.6/site-packages/flask/app.py", line 1813, in full_dispatch_request
    rv = self.dispatch_request()
  File "/home/jon/venv/p3/lib/python3.6/site-packages/flask/app.py", line 1791, in dispatch_request
    self.raise_routing_exception(req)
  File "/home/jon/venv/p3/lib/python3.6/site-packages/flask/app.py", line 1774, in raise_routing_exception
    raise request.routing_exception
  File "/home/jon/venv/p3/lib/python3.6/site-packages/flask/ctx.py", line 336, in match_request
    self.url_adapter.match(return_rule=True)
  File "/home/jon/venv/p3/lib/python3.6/site-packages/werkzeug/routing.py", line 1581, in match
    raise NotFound()
werkzeug.exceptions.NotFound: 404 Not Found: The requested URL was not found on the server.  If you entered the URL manually please check your spelling and try again.

[2019-Dec-17 20:31] 127.0.0.1 GET http /network3? 200 OK
[2019-Dec-17 20:31] 127.0.0.1 GET http /favicon.ico? 5xx INTERNAL SERVER ERROR
Traceback (most recent call last):
  File "/home/jon/venv/p3/lib/python3.6/site-packages/flask/app.py", line 1813, in full_dispatch_request
    rv = self.dispatch_request()
  File "/home/jon/venv/p3/lib/python3.6/site-packages/flask/app.py", line 1791, in dispatch_request
    self.raise_routing_exception(req)
  File "/home/jon/venv/p3/lib/python3.6/site-packages/flask/app.py", line 1774, in raise_routing_exception
    raise request.routing_exception
  File "/home/jon/venv/p3/lib/python3.6/site-packages/flask/ctx.py", line 336, in match_request
    self.url_adapter.match(return_rule=True)
  File "/home/jon/venv/p3/lib/python3.6/site-packages/werkzeug/routing.py", line 1581, in match
    raise NotFound()
werkzeug.exceptions.NotFound: 404 Not Found: The requested URL was not found on the server.  If you entered the URL manually please check your spelling and try again.

[2019-Dec-17 20:32] 127.0.0.1 GET http /network3? 200 OK
[2019-Dec-17 20:32] 127.0.0.1 GET http /favicon.ico? 5xx INTERNAL SERVER ERROR
Traceback (most recent call last):
  File "/home/jon/venv/p3/lib/python3.6/site-packages/flask/app.py", line 1813, in full_dispatch_request
    rv = self.dispatch_request()
  File "/home/jon/venv/p3/lib/python3.6/site-packages/flask/app.py", line 1791, in dispatch_request
    self.raise_routing_exception(req)
  File "/home/jon/venv/p3/lib/python3.6/site-packages/flask/app.py", line 1774, in raise_routing_exception
    raise request.routing_exception
  File "/home/jon/venv/p3/lib/python3.6/site-packages/flask/ctx.py", line 336, in match_request
    self.url_adapter.match(return_rule=True)
  File "/home/jon/venv/p3/lib/python3.6/site-packages/werkzeug/routing.py", line 1581, in match
    raise NotFound()
werkzeug.exceptions.NotFound: 404 Not Found: The requested URL was not found on the server.  If you entered the URL manually please check your spelling and try again.

[2019-Dec-17 20:33] 127.0.0.1 GET http /network3? 200 OK
[2019-Dec-17 20:33] 127.0.0.1 GET http /favicon.ico? 5xx INTERNAL SERVER ERROR
Traceback (most recent call last):
  File "/home/jon/venv/p3/lib/python3.6/site-packages/flask/app.py", line 1813, in full_dispatch_request
    rv = self.dispatch_request()
  File "/home/jon/venv/p3/lib/python3.6/site-packages/flask/app.py", line 1791, in dispatch_request
    self.raise_routing_exception(req)
  File "/home/jon/venv/p3/lib/python3.6/site-packages/flask/app.py", line 1774, in raise_routing_exception
    raise request.routing_exception
  File "/home/jon/venv/p3/lib/python3.6/site-packages/flask/ctx.py", line 336, in match_request
    self.url_adapter.match(return_rule=True)
  File "/home/jon/venv/p3/lib/python3.6/site-packages/werkzeug/routing.py", line 1581, in match
    raise NotFound()
werkzeug.exceptions.NotFound: 404 Not Found: The requested URL was not found on the server.  If you entered the URL manually please check your spelling and try again.

[2019-Dec-17 20:34] 127.0.0.1 GET http /network3? 200 OK
[2019-Dec-17 20:34] 127.0.0.1 GET http /favicon.ico? 5xx INTERNAL SERVER ERROR
Traceback (most recent call last):
  File "/home/jon/venv/p3/lib/python3.6/site-packages/flask/app.py", line 1813, in full_dispatch_request
    rv = self.dispatch_request()
  File "/home/jon/venv/p3/lib/python3.6/site-packages/flask/app.py", line 1791, in dispatch_request
    self.raise_routing_exception(req)
  File "/home/jon/venv/p3/lib/python3.6/site-packages/flask/app.py", line 1774, in raise_routing_exception
    raise request.routing_exception
  File "/home/jon/venv/p3/lib/python3.6/site-packages/flask/ctx.py", line 336, in match_request
    self.url_adapter.match(return_rule=True)
  File "/home/jon/venv/p3/lib/python3.6/site-packages/werkzeug/routing.py", line 1581, in match
    raise NotFound()
werkzeug.exceptions.NotFound: 404 Not Found: The requested URL was not found on the server.  If you entered the URL manually please check your spelling and try again.

[2019-Dec-17 20:37] 127.0.0.1 GET http /network3? 200 OK
[2019-Dec-17 20:37] 127.0.0.1 GET http /favicon.ico? 5xx INTERNAL SERVER ERROR
Traceback (most recent call last):
  File "/home/jon/venv/p3/lib/python3.6/site-packages/flask/app.py", line 1813, in full_dispatch_request
    rv = self.dispatch_request()
  File "/home/jon/venv/p3/lib/python3.6/site-packages/flask/app.py", line 1791, in dispatch_request
    self.raise_routing_exception(req)
  File "/home/jon/venv/p3/lib/python3.6/site-packages/flask/app.py", line 1774, in raise_routing_exception
    raise request.routing_exception
  File "/home/jon/venv/p3/lib/python3.6/site-packages/flask/ctx.py", line 336, in match_request
    self.url_adapter.match(return_rule=True)
  File "/home/jon/venv/p3/lib/python3.6/site-packages/werkzeug/routing.py", line 1581, in match
    raise NotFound()
werkzeug.exceptions.NotFound: 404 Not Found: The requested URL was not found on the server.  If you entered the URL manually please check your spelling and try again.

[2019-Dec-17 20:43] 127.0.0.1 GET http /network3? 200 OK
[2019-Dec-17 20:43] 127.0.0.1 GET http /favicon.ico? 5xx INTERNAL SERVER ERROR
Traceback (most recent call last):
  File "/home/jon/venv/p3/lib/python3.6/site-packages/flask/app.py", line 1813, in full_dispatch_request
    rv = self.dispatch_request()
  File "/home/jon/venv/p3/lib/python3.6/site-packages/flask/app.py", line 1791, in dispatch_request
    self.raise_routing_exception(req)
  File "/home/jon/venv/p3/lib/python3.6/site-packages/flask/app.py", line 1774, in raise_routing_exception
    raise request.routing_exception
  File "/home/jon/venv/p3/lib/python3.6/site-packages/flask/ctx.py", line 336, in match_request
    self.url_adapter.match(return_rule=True)
  File "/home/jon/venv/p3/lib/python3.6/site-packages/werkzeug/routing.py", line 1581, in match
    raise NotFound()
werkzeug.exceptions.NotFound: 404 Not Found: The requested URL was not found on the server.  If you entered the URL manually please check your spelling and try again.

[2019-Dec-17 20:46] 127.0.0.1 GET http /network3? 200 OK
[2019-Dec-17 20:46] 127.0.0.1 GET http /favicon.ico? 5xx INTERNAL SERVER ERROR
Traceback (most recent call last):
  File "/home/jon/venv/p3/lib/python3.6/site-packages/flask/app.py", line 1813, in full_dispatch_request
    rv = self.dispatch_request()
  File "/home/jon/venv/p3/lib/python3.6/site-packages/flask/app.py", line 1791, in dispatch_request
    self.raise_routing_exception(req)
  File "/home/jon/venv/p3/lib/python3.6/site-packages/flask/app.py", line 1774, in raise_routing_exception
    raise request.routing_exception
  File "/home/jon/venv/p3/lib/python3.6/site-packages/flask/ctx.py", line 336, in match_request
    self.url_adapter.match(return_rule=True)
  File "/home/jon/venv/p3/lib/python3.6/site-packages/werkzeug/routing.py", line 1581, in match
    raise NotFound()
werkzeug.exceptions.NotFound: 404 Not Found: The requested URL was not found on the server.  If you entered the URL manually please check your spelling and try again.

[2019-Dec-17 20:48] 127.0.0.1 GET http /? 200 OK
[2019-Dec-17 20:48] 127.0.0.1 GET http /static/css/auto-complete.css? 200 OK
[2019-Dec-17 20:48] 127.0.0.1 GET http /static/css/signin.css? 200 OK
[2019-Dec-17 20:48] 127.0.0.1 GET http /static/js/jquery-1.9.0.js? 200 OK
[2019-Dec-17 20:48] 127.0.0.1 GET http /static/css/my_style.css? 200 OK
[2019-Dec-17 20:48] 127.0.0.1 GET http /static/js/script.js? 200 OK
[2019-Dec-17 20:48] 127.0.0.1 GET http /static/js/fetch.js? 200 OK
[2019-Dec-17 20:48] 127.0.0.1 GET http /static/css/scss_css.css? 200 OK
[2019-Dec-17 20:48] 127.0.0.1 GET http /static/js/auto-complete.min.js? 200 OK
[2019-Dec-17 20:48] 127.0.0.1 GET http /static/js/autocomplete.js? 200 OK
[2019-Dec-17 20:48] 127.0.0.1 GET http /static/data/data.json? 200 OK
[2019-Dec-17 20:48] 127.0.0.1 GET http /static/css/scss_css.css.map? 200 OK
[2019-Dec-17 20:48] 127.0.0.1 GET http /network2? 200 OK
[2019-Dec-17 20:48] 127.0.0.1 GET http /d3_data2? 200 OK
[2019-Dec-17 20:48] 127.0.0.1 GET http /favicon.ico? 5xx INTERNAL SERVER ERROR
Traceback (most recent call last):
  File "/home/jon/venv/p3/lib/python3.6/site-packages/flask/app.py", line 1813, in full_dispatch_request
    rv = self.dispatch_request()
  File "/home/jon/venv/p3/lib/python3.6/site-packages/flask/app.py", line 1791, in dispatch_request
    self.raise_routing_exception(req)
  File "/home/jon/venv/p3/lib/python3.6/site-packages/flask/app.py", line 1774, in raise_routing_exception
    raise request.routing_exception
  File "/home/jon/venv/p3/lib/python3.6/site-packages/flask/ctx.py", line 336, in match_request
    self.url_adapter.match(return_rule=True)
  File "/home/jon/venv/p3/lib/python3.6/site-packages/werkzeug/routing.py", line 1581, in match
    raise NotFound()
werkzeug.exceptions.NotFound: 404 Not Found: The requested URL was not found on the server.  If you entered the URL manually please check your spelling and try again.

[2019-Dec-17 20:52] 127.0.0.1 GET http /? 200 OK
[2019-Dec-17 20:52] 127.0.0.1 GET http /static/css/auto-complete.css? 200 OK
[2019-Dec-17 20:52] 127.0.0.1 GET http /static/js/jquery-1.9.0.js? 200 OK
[2019-Dec-17 20:52] 127.0.0.1 GET http /static/css/scss_css.css? 200 OK
[2019-Dec-17 20:52] 127.0.0.1 GET http /static/js/script.js? 200 OK
[2019-Dec-17 20:52] 127.0.0.1 GET http /static/css/my_style.css? 200 OK
[2019-Dec-17 20:52] 127.0.0.1 GET http /static/css/signin.css? 200 OK
[2019-Dec-17 20:52] 127.0.0.1 GET http /static/js/fetch.js? 200 OK
[2019-Dec-17 20:52] 127.0.0.1 GET http /static/data/data.json? 200 OK
[2019-Dec-17 20:52] 127.0.0.1 GET http /static/js/auto-complete.min.js? 200 OK
[2019-Dec-17 20:52] 127.0.0.1 GET http /static/js/autocomplete.js? 200 OK
[2019-Dec-17 20:52] 127.0.0.1 GET http /static/css/scss_css.css.map? 200 OK
[2019-Dec-17 20:52] 127.0.0.1 GET http /network3? 200 OK
[2019-Dec-17 20:52] 127.0.0.1 GET http /favicon.ico? 5xx INTERNAL SERVER ERROR
Traceback (most recent call last):
  File "/home/jon/venv/p3/lib/python3.6/site-packages/flask/app.py", line 1813, in full_dispatch_request
    rv = self.dispatch_request()
  File "/home/jon/venv/p3/lib/python3.6/site-packages/flask/app.py", line 1791, in dispatch_request
    self.raise_routing_exception(req)
  File "/home/jon/venv/p3/lib/python3.6/site-packages/flask/app.py", line 1774, in raise_routing_exception
    raise request.routing_exception
  File "/home/jon/venv/p3/lib/python3.6/site-packages/flask/ctx.py", line 336, in match_request
    self.url_adapter.match(return_rule=True)
  File "/home/jon/venv/p3/lib/python3.6/site-packages/werkzeug/routing.py", line 1581, in match
    raise NotFound()
werkzeug.exceptions.NotFound: 404 Not Found: The requested URL was not found on the server.  If you entered the URL manually please check your spelling and try again.

[2019-Dec-17 20:52] 127.0.0.1 GET http /? 200 OK
[2019-Dec-17 20:52] 127.0.0.1 GET http /network2? 200 OK
[2019-Dec-17 20:52] 127.0.0.1 GET http /d3_data2? 200 OK
[2019-Dec-17 20:52] 127.0.0.1 GET http /favicon.ico? 5xx INTERNAL SERVER ERROR
Traceback (most recent call last):
  File "/home/jon/venv/p3/lib/python3.6/site-packages/flask/app.py", line 1813, in full_dispatch_request
    rv = self.dispatch_request()
  File "/home/jon/venv/p3/lib/python3.6/site-packages/flask/app.py", line 1791, in dispatch_request
    self.raise_routing_exception(req)
  File "/home/jon/venv/p3/lib/python3.6/site-packages/flask/app.py", line 1774, in raise_routing_exception
    raise request.routing_exception
  File "/home/jon/venv/p3/lib/python3.6/site-packages/flask/ctx.py", line 336, in match_request
    self.url_adapter.match(return_rule=True)
  File "/home/jon/venv/p3/lib/python3.6/site-packages/werkzeug/routing.py", line 1581, in match
    raise NotFound()
werkzeug.exceptions.NotFound: 404 Not Found: The requested URL was not found on the server.  If you entered the URL manually please check your spelling and try again.

[2019-Dec-17 20:53] 127.0.0.1 GET http /network3? 200 OK
[2019-Dec-17 20:53] 127.0.0.1 GET http /favicon.ico? 5xx INTERNAL SERVER ERROR
Traceback (most recent call last):
  File "/home/jon/venv/p3/lib/python3.6/site-packages/flask/app.py", line 1813, in full_dispatch_request
    rv = self.dispatch_request()
  File "/home/jon/venv/p3/lib/python3.6/site-packages/flask/app.py", line 1791, in dispatch_request
    self.raise_routing_exception(req)
  File "/home/jon/venv/p3/lib/python3.6/site-packages/flask/app.py", line 1774, in raise_routing_exception
    raise request.routing_exception
  File "/home/jon/venv/p3/lib/python3.6/site-packages/flask/ctx.py", line 336, in match_request
    self.url_adapter.match(return_rule=True)
  File "/home/jon/venv/p3/lib/python3.6/site-packages/werkzeug/routing.py", line 1581, in match
    raise NotFound()
werkzeug.exceptions.NotFound: 404 Not Found: The requested URL was not found on the server.  If you entered the URL manually please check your spelling and try again.

[2019-Dec-17 20:53] 127.0.0.1 GET http /network3? 200 OK
[2019-Dec-17 20:53] 127.0.0.1 GET http /favicon.ico? 5xx INTERNAL SERVER ERROR
Traceback (most recent call last):
  File "/home/jon/venv/p3/lib/python3.6/site-packages/flask/app.py", line 1813, in full_dispatch_request
    rv = self.dispatch_request()
  File "/home/jon/venv/p3/lib/python3.6/site-packages/flask/app.py", line 1791, in dispatch_request
    self.raise_routing_exception(req)
  File "/home/jon/venv/p3/lib/python3.6/site-packages/flask/app.py", line 1774, in raise_routing_exception
    raise request.routing_exception
  File "/home/jon/venv/p3/lib/python3.6/site-packages/flask/ctx.py", line 336, in match_request
    self.url_adapter.match(return_rule=True)
  File "/home/jon/venv/p3/lib/python3.6/site-packages/werkzeug/routing.py", line 1581, in match
    raise NotFound()
werkzeug.exceptions.NotFound: 404 Not Found: The requested URL was not found on the server.  If you entered the URL manually please check your spelling and try again.

[2019-Dec-17 20:54] 127.0.0.1 GET http /network3? 200 OK
[2019-Dec-17 20:54] 127.0.0.1 GET http /favicon.ico? 5xx INTERNAL SERVER ERROR
Traceback (most recent call last):
  File "/home/jon/venv/p3/lib/python3.6/site-packages/flask/app.py", line 1813, in full_dispatch_request
    rv = self.dispatch_request()
  File "/home/jon/venv/p3/lib/python3.6/site-packages/flask/app.py", line 1791, in dispatch_request
    self.raise_routing_exception(req)
  File "/home/jon/venv/p3/lib/python3.6/site-packages/flask/app.py", line 1774, in raise_routing_exception
    raise request.routing_exception
  File "/home/jon/venv/p3/lib/python3.6/site-packages/flask/ctx.py", line 336, in match_request
    self.url_adapter.match(return_rule=True)
  File "/home/jon/venv/p3/lib/python3.6/site-packages/werkzeug/routing.py", line 1581, in match
    raise NotFound()
werkzeug.exceptions.NotFound: 404 Not Found: The requested URL was not found on the server.  If you entered the URL manually please check your spelling and try again.

[2019-Dec-17 20:54] 127.0.0.1 GET http /network3? 200 OK
[2019-Dec-17 20:54] 127.0.0.1 GET http /favicon.ico? 5xx INTERNAL SERVER ERROR
Traceback (most recent call last):
  File "/home/jon/venv/p3/lib/python3.6/site-packages/flask/app.py", line 1813, in full_dispatch_request
    rv = self.dispatch_request()
  File "/home/jon/venv/p3/lib/python3.6/site-packages/flask/app.py", line 1791, in dispatch_request
    self.raise_routing_exception(req)
  File "/home/jon/venv/p3/lib/python3.6/site-packages/flask/app.py", line 1774, in raise_routing_exception
    raise request.routing_exception
  File "/home/jon/venv/p3/lib/python3.6/site-packages/flask/ctx.py", line 336, in match_request
    self.url_adapter.match(return_rule=True)
  File "/home/jon/venv/p3/lib/python3.6/site-packages/werkzeug/routing.py", line 1581, in match
    raise NotFound()
werkzeug.exceptions.NotFound: 404 Not Found: The requested URL was not found on the server.  If you entered the URL manually please check your spelling and try again.

[2019-Dec-17 21:01] 127.0.0.1 GET http /network3? 200 OK
[2019-Dec-17 21:01] 127.0.0.1 GET http /favicon.ico? 5xx INTERNAL SERVER ERROR
Traceback (most recent call last):
  File "/home/jon/venv/p3/lib/python3.6/site-packages/flask/app.py", line 1813, in full_dispatch_request
    rv = self.dispatch_request()
  File "/home/jon/venv/p3/lib/python3.6/site-packages/flask/app.py", line 1791, in dispatch_request
    self.raise_routing_exception(req)
  File "/home/jon/venv/p3/lib/python3.6/site-packages/flask/app.py", line 1774, in raise_routing_exception
    raise request.routing_exception
  File "/home/jon/venv/p3/lib/python3.6/site-packages/flask/ctx.py", line 336, in match_request
    self.url_adapter.match(return_rule=True)
  File "/home/jon/venv/p3/lib/python3.6/site-packages/werkzeug/routing.py", line 1581, in match
    raise NotFound()
werkzeug.exceptions.NotFound: 404 Not Found: The requested URL was not found on the server.  If you entered the URL manually please check your spelling and try again.

[2019-Dec-17 21:15] 127.0.0.1 GET http /network3? 200 OK
[2019-Dec-17 21:15] 127.0.0.1 GET http /favicon.ico? 5xx INTERNAL SERVER ERROR
Traceback (most recent call last):
  File "/home/jon/venv/p3/lib/python3.6/site-packages/flask/app.py", line 1813, in full_dispatch_request
    rv = self.dispatch_request()
  File "/home/jon/venv/p3/lib/python3.6/site-packages/flask/app.py", line 1791, in dispatch_request
    self.raise_routing_exception(req)
  File "/home/jon/venv/p3/lib/python3.6/site-packages/flask/app.py", line 1774, in raise_routing_exception
    raise request.routing_exception
  File "/home/jon/venv/p3/lib/python3.6/site-packages/flask/ctx.py", line 336, in match_request
    self.url_adapter.match(return_rule=True)
  File "/home/jon/venv/p3/lib/python3.6/site-packages/werkzeug/routing.py", line 1581, in match
    raise NotFound()
werkzeug.exceptions.NotFound: 404 Not Found: The requested URL was not found on the server.  If you entered the URL manually please check your spelling and try again.

[2019-Dec-17 21:15] 127.0.0.1 GET http /network3? 200 OK
[2019-Dec-17 21:15] 127.0.0.1 GET http /favicon.ico? 5xx INTERNAL SERVER ERROR
Traceback (most recent call last):
  File "/home/jon/venv/p3/lib/python3.6/site-packages/flask/app.py", line 1813, in full_dispatch_request
    rv = self.dispatch_request()
  File "/home/jon/venv/p3/lib/python3.6/site-packages/flask/app.py", line 1791, in dispatch_request
    self.raise_routing_exception(req)
  File "/home/jon/venv/p3/lib/python3.6/site-packages/flask/app.py", line 1774, in raise_routing_exception
    raise request.routing_exception
  File "/home/jon/venv/p3/lib/python3.6/site-packages/flask/ctx.py", line 336, in match_request
    self.url_adapter.match(return_rule=True)
  File "/home/jon/venv/p3/lib/python3.6/site-packages/werkzeug/routing.py", line 1581, in match
    raise NotFound()
werkzeug.exceptions.NotFound: 404 Not Found: The requested URL was not found on the server.  If you entered the URL manually please check your spelling and try again.

[2019-Dec-17 21:16] 127.0.0.1 GET http /network3? 200 OK
[2019-Dec-17 21:16] 127.0.0.1 GET http /favicon.ico? 5xx INTERNAL SERVER ERROR
Traceback (most recent call last):
  File "/home/jon/venv/p3/lib/python3.6/site-packages/flask/app.py", line 1813, in full_dispatch_request
    rv = self.dispatch_request()
  File "/home/jon/venv/p3/lib/python3.6/site-packages/flask/app.py", line 1791, in dispatch_request
    self.raise_routing_exception(req)
  File "/home/jon/venv/p3/lib/python3.6/site-packages/flask/app.py", line 1774, in raise_routing_exception
    raise request.routing_exception
  File "/home/jon/venv/p3/lib/python3.6/site-packages/flask/ctx.py", line 336, in match_request
    self.url_adapter.match(return_rule=True)
  File "/home/jon/venv/p3/lib/python3.6/site-packages/werkzeug/routing.py", line 1581, in match
    raise NotFound()
werkzeug.exceptions.NotFound: 404 Not Found: The requested URL was not found on the server.  If you entered the URL manually please check your spelling and try again.

[2019-Dec-17 21:17] 127.0.0.1 GET http /network3? 200 OK
[2019-Dec-17 21:17] 127.0.0.1 GET http /favicon.ico? 5xx INTERNAL SERVER ERROR
Traceback (most recent call last):
  File "/home/jon/venv/p3/lib/python3.6/site-packages/flask/app.py", line 1813, in full_dispatch_request
    rv = self.dispatch_request()
  File "/home/jon/venv/p3/lib/python3.6/site-packages/flask/app.py", line 1791, in dispatch_request
    self.raise_routing_exception(req)
  File "/home/jon/venv/p3/lib/python3.6/site-packages/flask/app.py", line 1774, in raise_routing_exception
    raise request.routing_exception
  File "/home/jon/venv/p3/lib/python3.6/site-packages/flask/ctx.py", line 336, in match_request
    self.url_adapter.match(return_rule=True)
  File "/home/jon/venv/p3/lib/python3.6/site-packages/werkzeug/routing.py", line 1581, in match
    raise NotFound()
werkzeug.exceptions.NotFound: 404 Not Found: The requested URL was not found on the server.  If you entered the URL manually please check your spelling and try again.

[2019-Dec-17 21:20] 127.0.0.1 GET http /? 200 OK
[2019-Dec-17 21:20] 127.0.0.1 GET http /static/css/auto-complete.css? 200 OK
[2019-Dec-17 21:20] 127.0.0.1 GET http /static/css/signin.css? 200 OK
[2019-Dec-17 21:20] 127.0.0.1 GET http /static/js/jquery-1.9.0.js? 200 OK
[2019-Dec-17 21:20] 127.0.0.1 GET http /static/js/script.js? 200 OK
[2019-Dec-17 21:20] 127.0.0.1 GET http /static/css/my_style.css? 200 OK
[2019-Dec-17 21:20] 127.0.0.1 GET http /static/css/scss_css.css? 200 OK
[2019-Dec-17 21:20] 127.0.0.1 GET http /static/data/data.json? 200 OK
[2019-Dec-17 21:20] 127.0.0.1 GET http /static/js/fetch.js? 200 OK
[2019-Dec-17 21:20] 127.0.0.1 GET http /static/js/auto-complete.min.js? 200 OK
[2019-Dec-17 21:20] 127.0.0.1 GET http /static/js/autocomplete.js? 200 OK
[2019-Dec-17 21:20] 127.0.0.1 GET http /static/css/scss_css.css.map? 200 OK
[2019-Dec-17 21:20] 127.0.0.1 GET http /network2? 200 OK
[2019-Dec-17 21:20] 127.0.0.1 GET http /d3_data2? 200 OK
[2019-Dec-17 21:20] 127.0.0.1 GET http /favicon.ico? 5xx INTERNAL SERVER ERROR
Traceback (most recent call last):
  File "/home/jon/venv/p3/lib/python3.6/site-packages/flask/app.py", line 1813, in full_dispatch_request
    rv = self.dispatch_request()
  File "/home/jon/venv/p3/lib/python3.6/site-packages/flask/app.py", line 1791, in dispatch_request
    self.raise_routing_exception(req)
  File "/home/jon/venv/p3/lib/python3.6/site-packages/flask/app.py", line 1774, in raise_routing_exception
    raise request.routing_exception
  File "/home/jon/venv/p3/lib/python3.6/site-packages/flask/ctx.py", line 336, in match_request
    self.url_adapter.match(return_rule=True)
  File "/home/jon/venv/p3/lib/python3.6/site-packages/werkzeug/routing.py", line 1581, in match
    raise NotFound()
werkzeug.exceptions.NotFound: 404 Not Found: The requested URL was not found on the server.  If you entered the URL manually please check your spelling and try again.

[2019-Dec-17 21:21] 127.0.0.1 GET http /? 200 OK
[2019-Dec-17 21:21] 127.0.0.1 GET http /static/css/auto-complete.css? 200 OK
[2019-Dec-17 21:21] 127.0.0.1 GET http /static/css/signin.css? 200 OK
[2019-Dec-17 21:21] 127.0.0.1 GET http /static/js/jquery-1.9.0.js? 200 OK
[2019-Dec-17 21:21] 127.0.0.1 GET http /static/js/script.js? 200 OK
[2019-Dec-17 21:21] 127.0.0.1 GET http /static/css/my_style.css? 200 OK
[2019-Dec-17 21:21] 127.0.0.1 GET http /static/js/fetch.js? 200 OK
[2019-Dec-17 21:21] 127.0.0.1 GET http /static/css/scss_css.css? 200 OK
[2019-Dec-17 21:21] 127.0.0.1 GET http /static/js/auto-complete.min.js? 200 OK
[2019-Dec-17 21:21] 127.0.0.1 GET http /static/data/data.json? 200 OK
[2019-Dec-17 21:21] 127.0.0.1 GET http /static/js/autocomplete.js? 200 OK
[2019-Dec-17 21:21] 127.0.0.1 GET http /static/css/scss_css.css.map? 200 OK
[2019-Dec-17 21:21] 127.0.0.1 GET http /network3? 200 OK
[2019-Dec-17 21:21] 127.0.0.1 GET http /favicon.ico? 5xx INTERNAL SERVER ERROR
Traceback (most recent call last):
  File "/home/jon/venv/p3/lib/python3.6/site-packages/flask/app.py", line 1813, in full_dispatch_request
    rv = self.dispatch_request()
  File "/home/jon/venv/p3/lib/python3.6/site-packages/flask/app.py", line 1791, in dispatch_request
    self.raise_routing_exception(req)
  File "/home/jon/venv/p3/lib/python3.6/site-packages/flask/app.py", line 1774, in raise_routing_exception
    raise request.routing_exception
  File "/home/jon/venv/p3/lib/python3.6/site-packages/flask/ctx.py", line 336, in match_request
    self.url_adapter.match(return_rule=True)
  File "/home/jon/venv/p3/lib/python3.6/site-packages/werkzeug/routing.py", line 1581, in match
    raise NotFound()
werkzeug.exceptions.NotFound: 404 Not Found: The requested URL was not found on the server.  If you entered the URL manually please check your spelling and try again.

[2019-Dec-17 21:30] 127.0.0.1 GET http /network3? 200 OK
[2019-Dec-17 21:30] 127.0.0.1 GET http /favicon.ico? 5xx INTERNAL SERVER ERROR
Traceback (most recent call last):
  File "/home/jon/venv/p3/lib/python3.6/site-packages/flask/app.py", line 1813, in full_dispatch_request
    rv = self.dispatch_request()
  File "/home/jon/venv/p3/lib/python3.6/site-packages/flask/app.py", line 1791, in dispatch_request
    self.raise_routing_exception(req)
  File "/home/jon/venv/p3/lib/python3.6/site-packages/flask/app.py", line 1774, in raise_routing_exception
    raise request.routing_exception
  File "/home/jon/venv/p3/lib/python3.6/site-packages/flask/ctx.py", line 336, in match_request
    self.url_adapter.match(return_rule=True)
  File "/home/jon/venv/p3/lib/python3.6/site-packages/werkzeug/routing.py", line 1581, in match
    raise NotFound()
werkzeug.exceptions.NotFound: 404 Not Found: The requested URL was not found on the server.  If you entered the URL manually please check your spelling and try again.

[2019-Dec-17 21:31] 127.0.0.1 GET http /network3? 200 OK
[2019-Dec-17 21:31] 127.0.0.1 GET http /favicon.ico? 5xx INTERNAL SERVER ERROR
Traceback (most recent call last):
  File "/home/jon/venv/p3/lib/python3.6/site-packages/flask/app.py", line 1813, in full_dispatch_request
    rv = self.dispatch_request()
  File "/home/jon/venv/p3/lib/python3.6/site-packages/flask/app.py", line 1791, in dispatch_request
    self.raise_routing_exception(req)
  File "/home/jon/venv/p3/lib/python3.6/site-packages/flask/app.py", line 1774, in raise_routing_exception
    raise request.routing_exception
  File "/home/jon/venv/p3/lib/python3.6/site-packages/flask/ctx.py", line 336, in match_request
    self.url_adapter.match(return_rule=True)
  File "/home/jon/venv/p3/lib/python3.6/site-packages/werkzeug/routing.py", line 1581, in match
    raise NotFound()
werkzeug.exceptions.NotFound: 404 Not Found: The requested URL was not found on the server.  If you entered the URL manually please check your spelling and try again.

[2019-Dec-17 21:32] 127.0.0.1 GET http /network3? 200 OK
[2019-Dec-17 21:32] 127.0.0.1 GET http /favicon.ico? 5xx INTERNAL SERVER ERROR
Traceback (most recent call last):
  File "/home/jon/venv/p3/lib/python3.6/site-packages/flask/app.py", line 1813, in full_dispatch_request
    rv = self.dispatch_request()
  File "/home/jon/venv/p3/lib/python3.6/site-packages/flask/app.py", line 1791, in dispatch_request
    self.raise_routing_exception(req)
  File "/home/jon/venv/p3/lib/python3.6/site-packages/flask/app.py", line 1774, in raise_routing_exception
    raise request.routing_exception
  File "/home/jon/venv/p3/lib/python3.6/site-packages/flask/ctx.py", line 336, in match_request
    self.url_adapter.match(return_rule=True)
  File "/home/jon/venv/p3/lib/python3.6/site-packages/werkzeug/routing.py", line 1581, in match
    raise NotFound()
werkzeug.exceptions.NotFound: 404 Not Found: The requested URL was not found on the server.  If you entered the URL manually please check your spelling and try again.

[2019-Dec-17 21:35] 127.0.0.1 GET http /network3? 200 OK
[2019-Dec-17 21:35] 127.0.0.1 GET http /favicon.ico? 5xx INTERNAL SERVER ERROR
Traceback (most recent call last):
  File "/home/jon/venv/p3/lib/python3.6/site-packages/flask/app.py", line 1813, in full_dispatch_request
    rv = self.dispatch_request()
  File "/home/jon/venv/p3/lib/python3.6/site-packages/flask/app.py", line 1791, in dispatch_request
    self.raise_routing_exception(req)
  File "/home/jon/venv/p3/lib/python3.6/site-packages/flask/app.py", line 1774, in raise_routing_exception
    raise request.routing_exception
  File "/home/jon/venv/p3/lib/python3.6/site-packages/flask/ctx.py", line 336, in match_request
    self.url_adapter.match(return_rule=True)
  File "/home/jon/venv/p3/lib/python3.6/site-packages/werkzeug/routing.py", line 1581, in match
    raise NotFound()
werkzeug.exceptions.NotFound: 404 Not Found: The requested URL was not found on the server.  If you entered the URL manually please check your spelling and try again.

[2019-Dec-17 21:36] 127.0.0.1 GET http /network3? 200 OK
[2019-Dec-17 21:36] 127.0.0.1 GET http /favicon.ico? 5xx INTERNAL SERVER ERROR
Traceback (most recent call last):
  File "/home/jon/venv/p3/lib/python3.6/site-packages/flask/app.py", line 1813, in full_dispatch_request
    rv = self.dispatch_request()
  File "/home/jon/venv/p3/lib/python3.6/site-packages/flask/app.py", line 1791, in dispatch_request
    self.raise_routing_exception(req)
  File "/home/jon/venv/p3/lib/python3.6/site-packages/flask/app.py", line 1774, in raise_routing_exception
    raise request.routing_exception
  File "/home/jon/venv/p3/lib/python3.6/site-packages/flask/ctx.py", line 336, in match_request
    self.url_adapter.match(return_rule=True)
  File "/home/jon/venv/p3/lib/python3.6/site-packages/werkzeug/routing.py", line 1581, in match
    raise NotFound()
werkzeug.exceptions.NotFound: 404 Not Found: The requested URL was not found on the server.  If you entered the URL manually please check your spelling and try again.

[2019-Dec-17 21:36] 127.0.0.1 GET http /network3? 200 OK
[2019-Dec-17 21:36] 127.0.0.1 GET http /favicon.ico? 5xx INTERNAL SERVER ERROR
Traceback (most recent call last):
  File "/home/jon/venv/p3/lib/python3.6/site-packages/flask/app.py", line 1813, in full_dispatch_request
    rv = self.dispatch_request()
  File "/home/jon/venv/p3/lib/python3.6/site-packages/flask/app.py", line 1791, in dispatch_request
    self.raise_routing_exception(req)
  File "/home/jon/venv/p3/lib/python3.6/site-packages/flask/app.py", line 1774, in raise_routing_exception
    raise request.routing_exception
  File "/home/jon/venv/p3/lib/python3.6/site-packages/flask/ctx.py", line 336, in match_request
    self.url_adapter.match(return_rule=True)
  File "/home/jon/venv/p3/lib/python3.6/site-packages/werkzeug/routing.py", line 1581, in match
    raise NotFound()
werkzeug.exceptions.NotFound: 404 Not Found: The requested URL was not found on the server.  If you entered the URL manually please check your spelling and try again.

[2019-Dec-17 21:37] 127.0.0.1 GET http /network3? 200 OK
[2019-Dec-17 21:37] 127.0.0.1 GET http /favicon.ico? 5xx INTERNAL SERVER ERROR
Traceback (most recent call last):
  File "/home/jon/venv/p3/lib/python3.6/site-packages/flask/app.py", line 1813, in full_dispatch_request
    rv = self.dispatch_request()
  File "/home/jon/venv/p3/lib/python3.6/site-packages/flask/app.py", line 1791, in dispatch_request
    self.raise_routing_exception(req)
  File "/home/jon/venv/p3/lib/python3.6/site-packages/flask/app.py", line 1774, in raise_routing_exception
    raise request.routing_exception
  File "/home/jon/venv/p3/lib/python3.6/site-packages/flask/ctx.py", line 336, in match_request
    self.url_adapter.match(return_rule=True)
  File "/home/jon/venv/p3/lib/python3.6/site-packages/werkzeug/routing.py", line 1581, in match
    raise NotFound()
werkzeug.exceptions.NotFound: 404 Not Found: The requested URL was not found on the server.  If you entered the URL manually please check your spelling and try again.

[2019-Dec-17 21:38] 127.0.0.1 GET http /network3? 200 OK
[2019-Dec-17 21:38] 127.0.0.1 GET http /favicon.ico? 5xx INTERNAL SERVER ERROR
Traceback (most recent call last):
  File "/home/jon/venv/p3/lib/python3.6/site-packages/flask/app.py", line 1813, in full_dispatch_request
    rv = self.dispatch_request()
  File "/home/jon/venv/p3/lib/python3.6/site-packages/flask/app.py", line 1791, in dispatch_request
    self.raise_routing_exception(req)
  File "/home/jon/venv/p3/lib/python3.6/site-packages/flask/app.py", line 1774, in raise_routing_exception
    raise request.routing_exception
  File "/home/jon/venv/p3/lib/python3.6/site-packages/flask/ctx.py", line 336, in match_request
    self.url_adapter.match(return_rule=True)
  File "/home/jon/venv/p3/lib/python3.6/site-packages/werkzeug/routing.py", line 1581, in match
    raise NotFound()
werkzeug.exceptions.NotFound: 404 Not Found: The requested URL was not found on the server.  If you entered the URL manually please check your spelling and try again.

[2019-Dec-17 21:44] 127.0.0.1 GET http /network3? 200 OK
[2019-Dec-17 21:44] 127.0.0.1 GET http /favicon.ico? 5xx INTERNAL SERVER ERROR
Traceback (most recent call last):
  File "/home/jon/venv/p3/lib/python3.6/site-packages/flask/app.py", line 1813, in full_dispatch_request
    rv = self.dispatch_request()
  File "/home/jon/venv/p3/lib/python3.6/site-packages/flask/app.py", line 1791, in dispatch_request
    self.raise_routing_exception(req)
  File "/home/jon/venv/p3/lib/python3.6/site-packages/flask/app.py", line 1774, in raise_routing_exception
    raise request.routing_exception
  File "/home/jon/venv/p3/lib/python3.6/site-packages/flask/ctx.py", line 336, in match_request
    self.url_adapter.match(return_rule=True)
  File "/home/jon/venv/p3/lib/python3.6/site-packages/werkzeug/routing.py", line 1581, in match
    raise NotFound()
werkzeug.exceptions.NotFound: 404 Not Found: The requested URL was not found on the server.  If you entered the URL manually please check your spelling and try again.

[2019-Dec-17 21:45] 127.0.0.1 GET http /network3? 200 OK
[2019-Dec-17 21:45] 127.0.0.1 GET http /favicon.ico? 5xx INTERNAL SERVER ERROR
Traceback (most recent call last):
  File "/home/jon/venv/p3/lib/python3.6/site-packages/flask/app.py", line 1813, in full_dispatch_request
    rv = self.dispatch_request()
  File "/home/jon/venv/p3/lib/python3.6/site-packages/flask/app.py", line 1791, in dispatch_request
    self.raise_routing_exception(req)
  File "/home/jon/venv/p3/lib/python3.6/site-packages/flask/app.py", line 1774, in raise_routing_exception
    raise request.routing_exception
  File "/home/jon/venv/p3/lib/python3.6/site-packages/flask/ctx.py", line 336, in match_request
    self.url_adapter.match(return_rule=True)
  File "/home/jon/venv/p3/lib/python3.6/site-packages/werkzeug/routing.py", line 1581, in match
    raise NotFound()
werkzeug.exceptions.NotFound: 404 Not Found: The requested URL was not found on the server.  If you entered the URL manually please check your spelling and try again.

[2019-Dec-17 21:47] 127.0.0.1 GET http /network3? 200 OK
[2019-Dec-17 21:47] 127.0.0.1 GET http /favicon.ico? 5xx INTERNAL SERVER ERROR
Traceback (most recent call last):
  File "/home/jon/venv/p3/lib/python3.6/site-packages/flask/app.py", line 1813, in full_dispatch_request
    rv = self.dispatch_request()
  File "/home/jon/venv/p3/lib/python3.6/site-packages/flask/app.py", line 1791, in dispatch_request
    self.raise_routing_exception(req)
  File "/home/jon/venv/p3/lib/python3.6/site-packages/flask/app.py", line 1774, in raise_routing_exception
    raise request.routing_exception
  File "/home/jon/venv/p3/lib/python3.6/site-packages/flask/ctx.py", line 336, in match_request
    self.url_adapter.match(return_rule=True)
  File "/home/jon/venv/p3/lib/python3.6/site-packages/werkzeug/routing.py", line 1581, in match
    raise NotFound()
werkzeug.exceptions.NotFound: 404 Not Found: The requested URL was not found on the server.  If you entered the URL manually please check your spelling and try again.

[2019-Dec-17 21:49] 127.0.0.1 GET http /network3? 200 OK
[2019-Dec-17 21:49] 127.0.0.1 GET http /favicon.ico? 5xx INTERNAL SERVER ERROR
Traceback (most recent call last):
  File "/home/jon/venv/p3/lib/python3.6/site-packages/flask/app.py", line 1813, in full_dispatch_request
    rv = self.dispatch_request()
  File "/home/jon/venv/p3/lib/python3.6/site-packages/flask/app.py", line 1791, in dispatch_request
    self.raise_routing_exception(req)
  File "/home/jon/venv/p3/lib/python3.6/site-packages/flask/app.py", line 1774, in raise_routing_exception
    raise request.routing_exception
  File "/home/jon/venv/p3/lib/python3.6/site-packages/flask/ctx.py", line 336, in match_request
    self.url_adapter.match(return_rule=True)
  File "/home/jon/venv/p3/lib/python3.6/site-packages/werkzeug/routing.py", line 1581, in match
    raise NotFound()
werkzeug.exceptions.NotFound: 404 Not Found: The requested URL was not found on the server.  If you entered the URL manually please check your spelling and try again.

[2019-Dec-17 21:51] 127.0.0.1 GET http /network3? 200 OK
[2019-Dec-17 21:51] 127.0.0.1 GET http /favicon.ico? 5xx INTERNAL SERVER ERROR
Traceback (most recent call last):
  File "/home/jon/venv/p3/lib/python3.6/site-packages/flask/app.py", line 1813, in full_dispatch_request
    rv = self.dispatch_request()
  File "/home/jon/venv/p3/lib/python3.6/site-packages/flask/app.py", line 1791, in dispatch_request
    self.raise_routing_exception(req)
  File "/home/jon/venv/p3/lib/python3.6/site-packages/flask/app.py", line 1774, in raise_routing_exception
    raise request.routing_exception
  File "/home/jon/venv/p3/lib/python3.6/site-packages/flask/ctx.py", line 336, in match_request
    self.url_adapter.match(return_rule=True)
  File "/home/jon/venv/p3/lib/python3.6/site-packages/werkzeug/routing.py", line 1581, in match
    raise NotFound()
werkzeug.exceptions.NotFound: 404 Not Found: The requested URL was not found on the server.  If you entered the URL manually please check your spelling and try again.

[2019-Dec-17 21:55] 127.0.0.1 GET http /network3? 200 OK
[2019-Dec-17 21:55] 127.0.0.1 GET http /favicon.ico? 5xx INTERNAL SERVER ERROR
Traceback (most recent call last):
  File "/home/jon/venv/p3/lib/python3.6/site-packages/flask/app.py", line 1813, in full_dispatch_request
    rv = self.dispatch_request()
  File "/home/jon/venv/p3/lib/python3.6/site-packages/flask/app.py", line 1791, in dispatch_request
    self.raise_routing_exception(req)
  File "/home/jon/venv/p3/lib/python3.6/site-packages/flask/app.py", line 1774, in raise_routing_exception
    raise request.routing_exception
  File "/home/jon/venv/p3/lib/python3.6/site-packages/flask/ctx.py", line 336, in match_request
    self.url_adapter.match(return_rule=True)
  File "/home/jon/venv/p3/lib/python3.6/site-packages/werkzeug/routing.py", line 1581, in match
    raise NotFound()
werkzeug.exceptions.NotFound: 404 Not Found: The requested URL was not found on the server.  If you entered the URL manually please check your spelling and try again.

[2019-Dec-17 21:57] 127.0.0.1 GET http /network3? 200 OK
[2019-Dec-17 21:57] 127.0.0.1 GET http /favicon.ico? 5xx INTERNAL SERVER ERROR
Traceback (most recent call last):
  File "/home/jon/venv/p3/lib/python3.6/site-packages/flask/app.py", line 1813, in full_dispatch_request
    rv = self.dispatch_request()
  File "/home/jon/venv/p3/lib/python3.6/site-packages/flask/app.py", line 1791, in dispatch_request
    self.raise_routing_exception(req)
  File "/home/jon/venv/p3/lib/python3.6/site-packages/flask/app.py", line 1774, in raise_routing_exception
    raise request.routing_exception
  File "/home/jon/venv/p3/lib/python3.6/site-packages/flask/ctx.py", line 336, in match_request
    self.url_adapter.match(return_rule=True)
  File "/home/jon/venv/p3/lib/python3.6/site-packages/werkzeug/routing.py", line 1581, in match
    raise NotFound()
werkzeug.exceptions.NotFound: 404 Not Found: The requested URL was not found on the server.  If you entered the URL manually please check your spelling and try again.

[2019-Dec-17 21:57] 127.0.0.1 GET http /network3? 200 OK
[2019-Dec-17 21:57] 127.0.0.1 GET http /favicon.ico? 5xx INTERNAL SERVER ERROR
Traceback (most recent call last):
  File "/home/jon/venv/p3/lib/python3.6/site-packages/flask/app.py", line 1813, in full_dispatch_request
    rv = self.dispatch_request()
  File "/home/jon/venv/p3/lib/python3.6/site-packages/flask/app.py", line 1791, in dispatch_request
    self.raise_routing_exception(req)
  File "/home/jon/venv/p3/lib/python3.6/site-packages/flask/app.py", line 1774, in raise_routing_exception
    raise request.routing_exception
  File "/home/jon/venv/p3/lib/python3.6/site-packages/flask/ctx.py", line 336, in match_request
    self.url_adapter.match(return_rule=True)
  File "/home/jon/venv/p3/lib/python3.6/site-packages/werkzeug/routing.py", line 1581, in match
    raise NotFound()
werkzeug.exceptions.NotFound: 404 Not Found: The requested URL was not found on the server.  If you entered the URL manually please check your spelling and try again.

[2019-Dec-17 22:00] 127.0.0.1 GET http /network3? 200 OK
[2019-Dec-17 22:00] 127.0.0.1 GET http /favicon.ico? 5xx INTERNAL SERVER ERROR
Traceback (most recent call last):
  File "/home/jon/venv/p3/lib/python3.6/site-packages/flask/app.py", line 1813, in full_dispatch_request
    rv = self.dispatch_request()
  File "/home/jon/venv/p3/lib/python3.6/site-packages/flask/app.py", line 1791, in dispatch_request
    self.raise_routing_exception(req)
  File "/home/jon/venv/p3/lib/python3.6/site-packages/flask/app.py", line 1774, in raise_routing_exception
    raise request.routing_exception
  File "/home/jon/venv/p3/lib/python3.6/site-packages/flask/ctx.py", line 336, in match_request
    self.url_adapter.match(return_rule=True)
  File "/home/jon/venv/p3/lib/python3.6/site-packages/werkzeug/routing.py", line 1581, in match
    raise NotFound()
werkzeug.exceptions.NotFound: 404 Not Found: The requested URL was not found on the server.  If you entered the URL manually please check your spelling and try again.

[2019-Dec-17 22:01] 127.0.0.1 GET http /? 200 OK
[2019-Dec-17 22:01] 127.0.0.1 GET http /static/css/auto-complete.css? 200 OK
[2019-Dec-17 22:01] 127.0.0.1 GET http /static/css/signin.css? 200 OK
[2019-Dec-17 22:01] 127.0.0.1 GET http /static/js/jquery-1.9.0.js? 200 OK
[2019-Dec-17 22:01] 127.0.0.1 GET http /static/js/auto-complete.min.js? 200 OK
[2019-Dec-17 22:01] 127.0.0.1 GET http /static/js/fetch.js? 200 OK
[2019-Dec-17 22:01] 127.0.0.1 GET http /static/js/script.js? 200 OK
[2019-Dec-17 22:01] 127.0.0.1 GET http /static/css/my_style.css? 200 OK
[2019-Dec-17 22:01] 127.0.0.1 GET http /static/css/scss_css.css? 200 OK
[2019-Dec-17 22:01] 127.0.0.1 GET http /static/data/data.json? 200 OK
[2019-Dec-17 22:01] 127.0.0.1 GET http /static/js/autocomplete.js? 200 OK
[2019-Dec-17 22:01] 127.0.0.1 GET http /static/css/scss_css.css.map? 200 OK
[2019-Dec-17 22:01] 127.0.0.1 GET http /network3? 200 OK
[2019-Dec-17 22:01] 127.0.0.1 GET http /favicon.ico? 5xx INTERNAL SERVER ERROR
Traceback (most recent call last):
  File "/home/jon/venv/p3/lib/python3.6/site-packages/flask/app.py", line 1813, in full_dispatch_request
    rv = self.dispatch_request()
  File "/home/jon/venv/p3/lib/python3.6/site-packages/flask/app.py", line 1791, in dispatch_request
    self.raise_routing_exception(req)
  File "/home/jon/venv/p3/lib/python3.6/site-packages/flask/app.py", line 1774, in raise_routing_exception
    raise request.routing_exception
  File "/home/jon/venv/p3/lib/python3.6/site-packages/flask/ctx.py", line 336, in match_request
    self.url_adapter.match(return_rule=True)
  File "/home/jon/venv/p3/lib/python3.6/site-packages/werkzeug/routing.py", line 1581, in match
    raise NotFound()
werkzeug.exceptions.NotFound: 404 Not Found: The requested URL was not found on the server.  If you entered the URL manually please check your spelling and try again.

[2019-Dec-17 22:01] 127.0.0.1 GET http /network3? 200 OK
[2019-Dec-17 22:01] 127.0.0.1 GET http /favicon.ico? 5xx INTERNAL SERVER ERROR
Traceback (most recent call last):
  File "/home/jon/venv/p3/lib/python3.6/site-packages/flask/app.py", line 1813, in full_dispatch_request
    rv = self.dispatch_request()
  File "/home/jon/venv/p3/lib/python3.6/site-packages/flask/app.py", line 1791, in dispatch_request
    self.raise_routing_exception(req)
  File "/home/jon/venv/p3/lib/python3.6/site-packages/flask/app.py", line 1774, in raise_routing_exception
    raise request.routing_exception
  File "/home/jon/venv/p3/lib/python3.6/site-packages/flask/ctx.py", line 336, in match_request
    self.url_adapter.match(return_rule=True)
  File "/home/jon/venv/p3/lib/python3.6/site-packages/werkzeug/routing.py", line 1581, in match
    raise NotFound()
werkzeug.exceptions.NotFound: 404 Not Found: The requested URL was not found on the server.  If you entered the URL manually please check your spelling and try again.

[2019-Dec-17 22:02] 127.0.0.1 GET http /network3? 200 OK
[2019-Dec-17 22:02] 127.0.0.1 GET http /favicon.ico? 5xx INTERNAL SERVER ERROR
Traceback (most recent call last):
  File "/home/jon/venv/p3/lib/python3.6/site-packages/flask/app.py", line 1813, in full_dispatch_request
    rv = self.dispatch_request()
  File "/home/jon/venv/p3/lib/python3.6/site-packages/flask/app.py", line 1791, in dispatch_request
    self.raise_routing_exception(req)
  File "/home/jon/venv/p3/lib/python3.6/site-packages/flask/app.py", line 1774, in raise_routing_exception
    raise request.routing_exception
  File "/home/jon/venv/p3/lib/python3.6/site-packages/flask/ctx.py", line 336, in match_request
    self.url_adapter.match(return_rule=True)
  File "/home/jon/venv/p3/lib/python3.6/site-packages/werkzeug/routing.py", line 1581, in match
    raise NotFound()
werkzeug.exceptions.NotFound: 404 Not Found: The requested URL was not found on the server.  If you entered the URL manually please check your spelling and try again.

[2019-Dec-17 22:03] 127.0.0.1 GET http /network3? 200 OK
[2019-Dec-17 22:03] 127.0.0.1 GET http /favicon.ico? 5xx INTERNAL SERVER ERROR
Traceback (most recent call last):
  File "/home/jon/venv/p3/lib/python3.6/site-packages/flask/app.py", line 1813, in full_dispatch_request
    rv = self.dispatch_request()
  File "/home/jon/venv/p3/lib/python3.6/site-packages/flask/app.py", line 1791, in dispatch_request
    self.raise_routing_exception(req)
  File "/home/jon/venv/p3/lib/python3.6/site-packages/flask/app.py", line 1774, in raise_routing_exception
    raise request.routing_exception
  File "/home/jon/venv/p3/lib/python3.6/site-packages/flask/ctx.py", line 336, in match_request
    self.url_adapter.match(return_rule=True)
  File "/home/jon/venv/p3/lib/python3.6/site-packages/werkzeug/routing.py", line 1581, in match
    raise NotFound()
werkzeug.exceptions.NotFound: 404 Not Found: The requested URL was not found on the server.  If you entered the URL manually please check your spelling and try again.

