[2019-Dec-13 22:25] 127.0.0.1 GET http /favicon.ico? 5xx INTERNAL SERVER ERROR
Traceback (most recent call last):
  File "/home/jon/venv/p3/lib/python3.6/site-packages/flask/app.py", line 1813, in full_dispatch_request
    rv = self.dispatch_request()
  File "/home/jon/venv/p3/lib/python3.6/site-packages/flask/app.py", line 1791, in dispatch_request
    self.raise_routing_exception(req)
  File "/home/jon/venv/p3/lib/python3.6/site-packages/flask/app.py", line 1774, in raise_routing_exception
    raise request.routing_exception
  File "/home/jon/venv/p3/lib/python3.6/site-packages/flask/ctx.py", line 336, in match_request
    self.url_adapter.match(return_rule=True)
  File "/home/jon/venv/p3/lib/python3.6/site-packages/werkzeug/routing.py", line 1581, in match
    raise NotFound()
werkzeug.exceptions.NotFound: 404 Not Found: The requested URL was not found on the server.  If you entered the URL manually please check your spelling and try again.

[2019-Dec-13 22:26] 127.0.0.1 GET http /network? 200 OK
[2019-Dec-13 22:26] 127.0.0.1 GET http /favicon.ico? 5xx INTERNAL SERVER ERROR
Traceback (most recent call last):
  File "/home/jon/venv/p3/lib/python3.6/site-packages/flask/app.py", line 1813, in full_dispatch_request
    rv = self.dispatch_request()
  File "/home/jon/venv/p3/lib/python3.6/site-packages/flask/app.py", line 1791, in dispatch_request
    self.raise_routing_exception(req)
  File "/home/jon/venv/p3/lib/python3.6/site-packages/flask/app.py", line 1774, in raise_routing_exception
    raise request.routing_exception
  File "/home/jon/venv/p3/lib/python3.6/site-packages/flask/ctx.py", line 336, in match_request
    self.url_adapter.match(return_rule=True)
  File "/home/jon/venv/p3/lib/python3.6/site-packages/werkzeug/routing.py", line 1581, in match
    raise NotFound()
werkzeug.exceptions.NotFound: 404 Not Found: The requested URL was not found on the server.  If you entered the URL manually please check your spelling and try again.

[2019-Dec-13 22:30] 127.0.0.1 GET http /? 200 OK
[2019-Dec-13 22:30] 127.0.0.1 GET http /network? 200 OK
[2019-Dec-13 22:30] 127.0.0.1 GET http /favicon.ico? 5xx INTERNAL SERVER ERROR
Traceback (most recent call last):
  File "/home/jon/venv/p3/lib/python3.6/site-packages/flask/app.py", line 1813, in full_dispatch_request
    rv = self.dispatch_request()
  File "/home/jon/venv/p3/lib/python3.6/site-packages/flask/app.py", line 1791, in dispatch_request
    self.raise_routing_exception(req)
  File "/home/jon/venv/p3/lib/python3.6/site-packages/flask/app.py", line 1774, in raise_routing_exception
    raise request.routing_exception
  File "/home/jon/venv/p3/lib/python3.6/site-packages/flask/ctx.py", line 336, in match_request
    self.url_adapter.match(return_rule=True)
  File "/home/jon/venv/p3/lib/python3.6/site-packages/werkzeug/routing.py", line 1581, in match
    raise NotFound()
werkzeug.exceptions.NotFound: 404 Not Found: The requested URL was not found on the server.  If you entered the URL manually please check your spelling and try again.

[2019-Dec-13 22:30] 127.0.0.1 GET http /? 200 OK
[2019-Dec-13 22:30] 127.0.0.1 GET http /static/css/auto-complete.css? 200 OK
[2019-Dec-13 22:30] 127.0.0.1 GET http /static/css/signin.css? 200 OK
[2019-Dec-13 22:30] 127.0.0.1 GET http /static/css/my_style.css? 200 OK
[2019-Dec-13 22:30] 127.0.0.1 GET http /static/js/jquery-1.9.0.js? 200 OK
[2019-Dec-13 22:30] 127.0.0.1 GET http /static/css/scss_css.css? 200 OK
[2019-Dec-13 22:30] 127.0.0.1 GET http /static/js/script.js? 200 OK
[2019-Dec-13 22:30] 127.0.0.1 GET http /static/js/fetch.js? 200 OK
[2019-Dec-13 22:30] 127.0.0.1 GET http /static/js/auto-complete.min.js? 200 OK
[2019-Dec-13 22:30] 127.0.0.1 GET http /static/data/data.json? 200 OK
[2019-Dec-13 22:30] 127.0.0.1 GET http /static/js/autocomplete.js? 200 OK
[2019-Dec-13 22:30] 127.0.0.1 GET http /static/css/scss_css.css.map? 200 OK
[2019-Dec-13 22:30] 127.0.0.1 GET http /network? 200 OK
[2019-Dec-13 22:30] 127.0.0.1 GET http /favicon.ico? 5xx INTERNAL SERVER ERROR
Traceback (most recent call last):
  File "/home/jon/venv/p3/lib/python3.6/site-packages/flask/app.py", line 1813, in full_dispatch_request
    rv = self.dispatch_request()
  File "/home/jon/venv/p3/lib/python3.6/site-packages/flask/app.py", line 1791, in dispatch_request
    self.raise_routing_exception(req)
  File "/home/jon/venv/p3/lib/python3.6/site-packages/flask/app.py", line 1774, in raise_routing_exception
    raise request.routing_exception
  File "/home/jon/venv/p3/lib/python3.6/site-packages/flask/ctx.py", line 336, in match_request
    self.url_adapter.match(return_rule=True)
  File "/home/jon/venv/p3/lib/python3.6/site-packages/werkzeug/routing.py", line 1581, in match
    raise NotFound()
werkzeug.exceptions.NotFound: 404 Not Found: The requested URL was not found on the server.  If you entered the URL manually please check your spelling and try again.

[2019-Dec-13 22:30] 127.0.0.1 GET http /network? 200 OK
[2019-Dec-13 22:30] 127.0.0.1 GET http /favicon.ico? 5xx INTERNAL SERVER ERROR
Traceback (most recent call last):
  File "/home/jon/venv/p3/lib/python3.6/site-packages/flask/app.py", line 1813, in full_dispatch_request
    rv = self.dispatch_request()
  File "/home/jon/venv/p3/lib/python3.6/site-packages/flask/app.py", line 1791, in dispatch_request
    self.raise_routing_exception(req)
  File "/home/jon/venv/p3/lib/python3.6/site-packages/flask/app.py", line 1774, in raise_routing_exception
    raise request.routing_exception
  File "/home/jon/venv/p3/lib/python3.6/site-packages/flask/ctx.py", line 336, in match_request
    self.url_adapter.match(return_rule=True)
  File "/home/jon/venv/p3/lib/python3.6/site-packages/werkzeug/routing.py", line 1581, in match
    raise NotFound()
werkzeug.exceptions.NotFound: 404 Not Found: The requested URL was not found on the server.  If you entered the URL manually please check your spelling and try again.

[2019-Dec-13 22:30] 127.0.0.1 GET http /network? 200 OK
[2019-Dec-13 22:30] 127.0.0.1 GET http /favicon.ico? 5xx INTERNAL SERVER ERROR
Traceback (most recent call last):
  File "/home/jon/venv/p3/lib/python3.6/site-packages/flask/app.py", line 1813, in full_dispatch_request
    rv = self.dispatch_request()
  File "/home/jon/venv/p3/lib/python3.6/site-packages/flask/app.py", line 1791, in dispatch_request
    self.raise_routing_exception(req)
  File "/home/jon/venv/p3/lib/python3.6/site-packages/flask/app.py", line 1774, in raise_routing_exception
    raise request.routing_exception
  File "/home/jon/venv/p3/lib/python3.6/site-packages/flask/ctx.py", line 336, in match_request
    self.url_adapter.match(return_rule=True)
  File "/home/jon/venv/p3/lib/python3.6/site-packages/werkzeug/routing.py", line 1581, in match
    raise NotFound()
werkzeug.exceptions.NotFound: 404 Not Found: The requested URL was not found on the server.  If you entered the URL manually please check your spelling and try again.

[2019-Dec-13 22:36] 127.0.0.1 GET http /? 200 OK
[2019-Dec-13 22:36] 127.0.0.1 GET http /static/css/auto-complete.css? 200 OK
[2019-Dec-13 22:36] 127.0.0.1 GET http /static/css/signin.css? 200 OK
[2019-Dec-13 22:36] 127.0.0.1 GET http /static/js/jquery-1.9.0.js? 200 OK
[2019-Dec-13 22:36] 127.0.0.1 GET http /static/css/my_style.css? 200 OK
[2019-Dec-13 22:36] 127.0.0.1 GET http /static/css/scss_css.css? 200 OK
[2019-Dec-13 22:36] 127.0.0.1 GET http /static/js/script.js? 200 OK
[2019-Dec-13 22:36] 127.0.0.1 GET http /static/js/fetch.js? 200 OK
[2019-Dec-13 22:36] 127.0.0.1 GET http /static/js/auto-complete.min.js? 200 OK
[2019-Dec-13 22:36] 127.0.0.1 GET http /static/js/autocomplete.js? 200 OK
[2019-Dec-13 22:36] 127.0.0.1 GET http /static/data/data.json? 200 OK
[2019-Dec-13 22:36] 127.0.0.1 GET http /static/css/scss_css.css.map? 200 OK
[2019-Dec-13 22:36] 127.0.0.1 GET http /network? 5xx INTERNAL SERVER ERROR
Traceback (most recent call last):
  File "/home/jon/venv/p3/lib/python3.6/site-packages/flask/app.py", line 1813, in full_dispatch_request
    rv = self.dispatch_request()
  File "/home/jon/venv/p3/lib/python3.6/site-packages/flask/app.py", line 1799, in dispatch_request
    return self.view_functions[rule.endpoint](**req.view_args)
  File "app.py", line 355, in d3_network
    return render_template('network.html', json_data = json_data)
NameError: name 'json_data' is not defined

[2019-Dec-13 22:36] 127.0.0.1 GET http /favicon.ico? 5xx INTERNAL SERVER ERROR
Traceback (most recent call last):
  File "/home/jon/venv/p3/lib/python3.6/site-packages/flask/app.py", line 1813, in full_dispatch_request
    rv = self.dispatch_request()
  File "/home/jon/venv/p3/lib/python3.6/site-packages/flask/app.py", line 1791, in dispatch_request
    self.raise_routing_exception(req)
  File "/home/jon/venv/p3/lib/python3.6/site-packages/flask/app.py", line 1774, in raise_routing_exception
    raise request.routing_exception
  File "/home/jon/venv/p3/lib/python3.6/site-packages/flask/ctx.py", line 336, in match_request
    self.url_adapter.match(return_rule=True)
  File "/home/jon/venv/p3/lib/python3.6/site-packages/werkzeug/routing.py", line 1581, in match
    raise NotFound()
werkzeug.exceptions.NotFound: 404 Not Found: The requested URL was not found on the server.  If you entered the URL manually please check your spelling and try again.

[2019-Dec-13 22:38] 127.0.0.1 GET http /? 200 OK
[2019-Dec-13 22:38] 127.0.0.1 GET http /static/css/auto-complete.css? 200 OK
[2019-Dec-13 22:38] 127.0.0.1 GET http /static/css/signin.css? 200 OK
[2019-Dec-13 22:38] 127.0.0.1 GET http /static/css/my_style.css? 200 OK
[2019-Dec-13 22:38] 127.0.0.1 GET http /static/js/jquery-1.9.0.js? 200 OK
[2019-Dec-13 22:38] 127.0.0.1 GET http /static/css/scss_css.css? 200 OK
[2019-Dec-13 22:38] 127.0.0.1 GET http /static/js/script.js? 200 OK
[2019-Dec-13 22:38] 127.0.0.1 GET http /static/js/fetch.js? 200 OK
[2019-Dec-13 22:38] 127.0.0.1 GET http /static/js/auto-complete.min.js? 200 OK
[2019-Dec-13 22:38] 127.0.0.1 GET http /static/data/data.json? 200 OK
[2019-Dec-13 22:38] 127.0.0.1 GET http /static/js/autocomplete.js? 200 OK
[2019-Dec-13 22:38] 127.0.0.1 GET http /static/css/scss_css.css.map? 200 OK
[2019-Dec-13 22:38] 127.0.0.1 GET http /network? 200 OK
[2019-Dec-13 22:38] 127.0.0.1 GET http /d3_data? 200 OK
[2019-Dec-13 22:38] 127.0.0.1 GET http /favicon.ico? 5xx INTERNAL SERVER ERROR
Traceback (most recent call last):
  File "/home/jon/venv/p3/lib/python3.6/site-packages/flask/app.py", line 1813, in full_dispatch_request
    rv = self.dispatch_request()
  File "/home/jon/venv/p3/lib/python3.6/site-packages/flask/app.py", line 1791, in dispatch_request
    self.raise_routing_exception(req)
  File "/home/jon/venv/p3/lib/python3.6/site-packages/flask/app.py", line 1774, in raise_routing_exception
    raise request.routing_exception
  File "/home/jon/venv/p3/lib/python3.6/site-packages/flask/ctx.py", line 336, in match_request
    self.url_adapter.match(return_rule=True)
  File "/home/jon/venv/p3/lib/python3.6/site-packages/werkzeug/routing.py", line 1581, in match
    raise NotFound()
werkzeug.exceptions.NotFound: 404 Not Found: The requested URL was not found on the server.  If you entered the URL manually please check your spelling and try again.

[2019-Dec-13 22:40] 127.0.0.1 GET http /? 200 OK
[2019-Dec-13 22:40] 127.0.0.1 GET http /static/css/auto-complete.css? 200 OK
[2019-Dec-13 22:40] 127.0.0.1 GET http /static/css/signin.css? 200 OK
[2019-Dec-13 22:40] 127.0.0.1 GET http /static/js/jquery-1.9.0.js? 200 OK
[2019-Dec-13 22:40] 127.0.0.1 GET http /static/css/my_style.css? 200 OK
[2019-Dec-13 22:40] 127.0.0.1 GET http /static/js/script.js? 200 OK
[2019-Dec-13 22:40] 127.0.0.1 GET http /static/css/scss_css.css? 200 OK
[2019-Dec-13 22:40] 127.0.0.1 GET http /static/js/fetch.js? 200 OK
[2019-Dec-13 22:40] 127.0.0.1 GET http /static/js/auto-complete.min.js? 200 OK
[2019-Dec-13 22:40] 127.0.0.1 GET http /static/data/data.json? 200 OK
[2019-Dec-13 22:40] 127.0.0.1 GET http /static/js/autocomplete.js? 200 OK
[2019-Dec-13 22:40] 127.0.0.1 GET http /static/css/scss_css.css.map? 200 OK
[2019-Dec-13 22:41] 127.0.0.1 GET http /tree_view? 200 OK
[2019-Dec-13 22:41] 127.0.0.1 GET http /static/js/jquery-1.9.0.js? 200 OK
[2019-Dec-13 22:41] 127.0.0.1 GET http /static/css/d3_css.css? 200 OK
[2019-Dec-13 22:41] 127.0.0.1 GET http /favicon.ico? 5xx INTERNAL SERVER ERROR
Traceback (most recent call last):
  File "/home/jon/venv/p3/lib/python3.6/site-packages/flask/app.py", line 1813, in full_dispatch_request
    rv = self.dispatch_request()
  File "/home/jon/venv/p3/lib/python3.6/site-packages/flask/app.py", line 1791, in dispatch_request
    self.raise_routing_exception(req)
  File "/home/jon/venv/p3/lib/python3.6/site-packages/flask/app.py", line 1774, in raise_routing_exception
    raise request.routing_exception
  File "/home/jon/venv/p3/lib/python3.6/site-packages/flask/ctx.py", line 336, in match_request
    self.url_adapter.match(return_rule=True)
  File "/home/jon/venv/p3/lib/python3.6/site-packages/werkzeug/routing.py", line 1581, in match
    raise NotFound()
werkzeug.exceptions.NotFound: 404 Not Found: The requested URL was not found on the server.  If you entered the URL manually please check your spelling and try again.

[2019-Dec-13 22:41] 127.0.0.1 GET http /fetch_random_data? 200 OK
[2019-Dec-13 22:41] 127.0.0.1 GET http /? 200 OK
[2019-Dec-13 22:41] 127.0.0.1 GET http /static/css/auto-complete.css? 200 OK
[2019-Dec-13 22:41] 127.0.0.1 GET http /static/css/signin.css? 200 OK
[2019-Dec-13 22:41] 127.0.0.1 GET http /static/js/jquery-1.9.0.js? 200 OK
[2019-Dec-13 22:41] 127.0.0.1 GET http /static/js/script.js? 200 OK
[2019-Dec-13 22:41] 127.0.0.1 GET http /static/js/fetch.js? 200 OK
[2019-Dec-13 22:41] 127.0.0.1 GET http /static/js/auto-complete.min.js? 200 OK
[2019-Dec-13 22:41] 127.0.0.1 GET http /static/css/my_style.css? 200 OK
[2019-Dec-13 22:41] 127.0.0.1 GET http /static/css/scss_css.css? 200 OK
[2019-Dec-13 22:41] 127.0.0.1 GET http /static/data/data.json? 200 OK
[2019-Dec-13 22:41] 127.0.0.1 GET http /static/js/autocomplete.js? 200 OK
[2019-Dec-13 22:41] 127.0.0.1 GET http /static/css/scss_css.css.map? 200 OK
[2019-Dec-13 22:41] 127.0.0.1 GET http /tree_view? 200 OK
[2019-Dec-13 22:41] 127.0.0.1 GET http /static/js/jquery-1.9.0.js? 200 OK
[2019-Dec-13 22:41] 127.0.0.1 GET http /static/css/d3_css.css? 200 OK
[2019-Dec-13 22:41] 127.0.0.1 GET http /favicon.ico? 5xx INTERNAL SERVER ERROR
Traceback (most recent call last):
  File "/home/jon/venv/p3/lib/python3.6/site-packages/flask/app.py", line 1813, in full_dispatch_request
    rv = self.dispatch_request()
  File "/home/jon/venv/p3/lib/python3.6/site-packages/flask/app.py", line 1791, in dispatch_request
    self.raise_routing_exception(req)
  File "/home/jon/venv/p3/lib/python3.6/site-packages/flask/app.py", line 1774, in raise_routing_exception
    raise request.routing_exception
  File "/home/jon/venv/p3/lib/python3.6/site-packages/flask/ctx.py", line 336, in match_request
    self.url_adapter.match(return_rule=True)
  File "/home/jon/venv/p3/lib/python3.6/site-packages/werkzeug/routing.py", line 1581, in match
    raise NotFound()
werkzeug.exceptions.NotFound: 404 Not Found: The requested URL was not found on the server.  If you entered the URL manually please check your spelling and try again.

[2019-Dec-13 22:41] 127.0.0.1 GET http /? 200 OK
[2019-Dec-13 22:41] 127.0.0.1 GET http /static/css/auto-complete.css? 200 OK
[2019-Dec-13 22:41] 127.0.0.1 GET http /static/css/signin.css? 200 OK
[2019-Dec-13 22:41] 127.0.0.1 GET http /static/js/jquery-1.9.0.js? 200 OK
[2019-Dec-13 22:41] 127.0.0.1 GET http /static/js/script.js? 200 OK
[2019-Dec-13 22:41] 127.0.0.1 GET http /static/js/fetch.js? 200 OK
[2019-Dec-13 22:41] 127.0.0.1 GET http /static/css/my_style.css? 200 OK
[2019-Dec-13 22:41] 127.0.0.1 GET http /static/css/scss_css.css? 200 OK
[2019-Dec-13 22:41] 127.0.0.1 GET http /static/js/auto-complete.min.js? 200 OK
[2019-Dec-13 22:41] 127.0.0.1 GET http /static/data/data.json? 200 OK
[2019-Dec-13 22:41] 127.0.0.1 GET http /static/js/autocomplete.js? 200 OK
[2019-Dec-13 22:41] 127.0.0.1 GET http /static/css/scss_css.css.map? 200 OK
[2019-Dec-13 22:41] 127.0.0.1 GET http /network? 200 OK
[2019-Dec-13 22:41] 127.0.0.1 GET http /d3_data? 200 OK
[2019-Dec-13 22:41] 127.0.0.1 GET http /favicon.ico? 5xx INTERNAL SERVER ERROR
Traceback (most recent call last):
  File "/home/jon/venv/p3/lib/python3.6/site-packages/flask/app.py", line 1813, in full_dispatch_request
    rv = self.dispatch_request()
  File "/home/jon/venv/p3/lib/python3.6/site-packages/flask/app.py", line 1791, in dispatch_request
    self.raise_routing_exception(req)
  File "/home/jon/venv/p3/lib/python3.6/site-packages/flask/app.py", line 1774, in raise_routing_exception
    raise request.routing_exception
  File "/home/jon/venv/p3/lib/python3.6/site-packages/flask/ctx.py", line 336, in match_request
    self.url_adapter.match(return_rule=True)
  File "/home/jon/venv/p3/lib/python3.6/site-packages/werkzeug/routing.py", line 1581, in match
    raise NotFound()
werkzeug.exceptions.NotFound: 404 Not Found: The requested URL was not found on the server.  If you entered the URL manually please check your spelling and try again.

[2019-Dec-13 22:51] 127.0.0.1 GET http /network? 200 OK
[2019-Dec-13 22:51] 127.0.0.1 GET http /d3_data? 200 OK
[2019-Dec-13 22:51] 127.0.0.1 GET http /favicon.ico? 5xx INTERNAL SERVER ERROR
Traceback (most recent call last):
  File "/home/jon/venv/p3/lib/python3.6/site-packages/flask/app.py", line 1813, in full_dispatch_request
    rv = self.dispatch_request()
  File "/home/jon/venv/p3/lib/python3.6/site-packages/flask/app.py", line 1791, in dispatch_request
    self.raise_routing_exception(req)
  File "/home/jon/venv/p3/lib/python3.6/site-packages/flask/app.py", line 1774, in raise_routing_exception
    raise request.routing_exception
  File "/home/jon/venv/p3/lib/python3.6/site-packages/flask/ctx.py", line 336, in match_request
    self.url_adapter.match(return_rule=True)
  File "/home/jon/venv/p3/lib/python3.6/site-packages/werkzeug/routing.py", line 1581, in match
    raise NotFound()
werkzeug.exceptions.NotFound: 404 Not Found: The requested URL was not found on the server.  If you entered the URL manually please check your spelling and try again.

[2019-Dec-13 22:52] 127.0.0.1 GET http /? 200 OK
[2019-Dec-13 22:52] 127.0.0.1 GET http /static/css/auto-complete.css? 200 OK
[2019-Dec-13 22:52] 127.0.0.1 GET http /static/css/signin.css? 200 OK
[2019-Dec-13 22:52] 127.0.0.1 GET http /static/js/jquery-1.9.0.js? 200 OK
[2019-Dec-13 22:52] 127.0.0.1 GET http /static/css/my_style.css? 200 OK
[2019-Dec-13 22:52] 127.0.0.1 GET http /static/js/fetch.js? 200 OK
[2019-Dec-13 22:52] 127.0.0.1 GET http /static/css/scss_css.css? 200 OK
[2019-Dec-13 22:52] 127.0.0.1 GET http /static/js/script.js? 200 OK
[2019-Dec-13 22:52] 127.0.0.1 GET http /static/js/auto-complete.min.js? 200 OK
[2019-Dec-13 22:52] 127.0.0.1 GET http /static/data/data.json? 200 OK
[2019-Dec-13 22:52] 127.0.0.1 GET http /static/js/autocomplete.js? 200 OK
[2019-Dec-13 22:52] 127.0.0.1 GET http /static/css/scss_css.css.map? 200 OK
[2019-Dec-13 22:52] 127.0.0.1 GET http /network? 200 OK
[2019-Dec-13 22:52] 127.0.0.1 GET http /d3_data? 200 OK
[2019-Dec-13 22:52] 127.0.0.1 GET http /favicon.ico? 5xx INTERNAL SERVER ERROR
Traceback (most recent call last):
  File "/home/jon/venv/p3/lib/python3.6/site-packages/flask/app.py", line 1813, in full_dispatch_request
    rv = self.dispatch_request()
  File "/home/jon/venv/p3/lib/python3.6/site-packages/flask/app.py", line 1791, in dispatch_request
    self.raise_routing_exception(req)
  File "/home/jon/venv/p3/lib/python3.6/site-packages/flask/app.py", line 1774, in raise_routing_exception
    raise request.routing_exception
  File "/home/jon/venv/p3/lib/python3.6/site-packages/flask/ctx.py", line 336, in match_request
    self.url_adapter.match(return_rule=True)
  File "/home/jon/venv/p3/lib/python3.6/site-packages/werkzeug/routing.py", line 1581, in match
    raise NotFound()
werkzeug.exceptions.NotFound: 404 Not Found: The requested URL was not found on the server.  If you entered the URL manually please check your spelling and try again.

[2019-Dec-13 23:22] 127.0.0.1 GET http /? 200 OK
[2019-Dec-13 23:22] 127.0.0.1 GET http /static/css/signin.css? 200 OK
[2019-Dec-13 23:22] 127.0.0.1 GET http /static/js/jquery-1.9.0.js? 200 OK
[2019-Dec-13 23:22] 127.0.0.1 GET http /static/css/my_style.css? 200 OK
[2019-Dec-13 23:22] 127.0.0.1 GET http /static/js/script.js? 200 OK
[2019-Dec-13 23:22] 127.0.0.1 GET http /static/css/auto-complete.css? 200 OK
[2019-Dec-13 23:22] 127.0.0.1 GET http /static/js/fetch.js? 200 OK
[2019-Dec-13 23:22] 127.0.0.1 GET http /static/js/auto-complete.min.js? 200 OK
[2019-Dec-13 23:22] 127.0.0.1 GET http /static/css/scss_css.css? 200 OK
[2019-Dec-13 23:22] 127.0.0.1 GET http /static/data/data.json? 200 OK
[2019-Dec-13 23:22] 127.0.0.1 GET http /static/js/autocomplete.js? 200 OK
[2019-Dec-13 23:22] 127.0.0.1 GET http /static/css/scss_css.css.map? 200 OK
[2019-Dec-13 23:22] 127.0.0.1 GET http /network? 200 OK
[2019-Dec-13 23:22] 127.0.0.1 GET http /d3_data? 200 OK
[2019-Dec-13 23:22] 127.0.0.1 GET http /favicon.ico? 5xx INTERNAL SERVER ERROR
Traceback (most recent call last):
  File "/home/jon/venv/p3/lib/python3.6/site-packages/flask/app.py", line 1813, in full_dispatch_request
    rv = self.dispatch_request()
  File "/home/jon/venv/p3/lib/python3.6/site-packages/flask/app.py", line 1791, in dispatch_request
    self.raise_routing_exception(req)
  File "/home/jon/venv/p3/lib/python3.6/site-packages/flask/app.py", line 1774, in raise_routing_exception
    raise request.routing_exception
  File "/home/jon/venv/p3/lib/python3.6/site-packages/flask/ctx.py", line 336, in match_request
    self.url_adapter.match(return_rule=True)
  File "/home/jon/venv/p3/lib/python3.6/site-packages/werkzeug/routing.py", line 1581, in match
    raise NotFound()
werkzeug.exceptions.NotFound: 404 Not Found: The requested URL was not found on the server.  If you entered the URL manually please check your spelling and try again.

[2019-Dec-14 18:37] 127.0.0.1 GET http /network? 200 OK
[2019-Dec-14 18:37] 127.0.0.1 GET http /d3_data? 200 OK
[2019-Dec-14 18:37] 127.0.0.1 GET http /favicon.ico? 5xx INTERNAL SERVER ERROR
Traceback (most recent call last):
  File "/home/jon/venv/p3/lib/python3.6/site-packages/flask/app.py", line 1813, in full_dispatch_request
    rv = self.dispatch_request()
  File "/home/jon/venv/p3/lib/python3.6/site-packages/flask/app.py", line 1791, in dispatch_request
    self.raise_routing_exception(req)
  File "/home/jon/venv/p3/lib/python3.6/site-packages/flask/app.py", line 1774, in raise_routing_exception
    raise request.routing_exception
  File "/home/jon/venv/p3/lib/python3.6/site-packages/flask/ctx.py", line 336, in match_request
    self.url_adapter.match(return_rule=True)
  File "/home/jon/venv/p3/lib/python3.6/site-packages/werkzeug/routing.py", line 1581, in match
    raise NotFound()
werkzeug.exceptions.NotFound: 404 Not Found: The requested URL was not found on the server.  If you entered the URL manually please check your spelling and try again.

[2019-Dec-14 18:38] 127.0.0.1 GET http /? 200 OK
[2019-Dec-14 18:38] 127.0.0.1 GET http /static/css/auto-complete.css? 304 NOT MODIFIED
[2019-Dec-14 18:38] 127.0.0.1 GET http /static/css/signin.css? 304 NOT MODIFIED
[2019-Dec-14 18:38] 127.0.0.1 GET http /static/css/my_style.css? 304 NOT MODIFIED
[2019-Dec-14 18:38] 127.0.0.1 GET http /static/js/jquery-1.9.0.js? 304 NOT MODIFIED
[2019-Dec-14 18:38] 127.0.0.1 GET http /static/css/scss_css.css? 304 NOT MODIFIED
[2019-Dec-14 18:38] 127.0.0.1 GET http /static/js/script.js? 304 NOT MODIFIED
[2019-Dec-14 18:38] 127.0.0.1 GET http /static/js/fetch.js? 304 NOT MODIFIED
[2019-Dec-14 18:38] 127.0.0.1 GET http /static/js/auto-complete.min.js? 304 NOT MODIFIED
[2019-Dec-14 18:38] 127.0.0.1 GET http /static/data/data.json? 304 NOT MODIFIED
[2019-Dec-14 18:38] 127.0.0.1 GET http /static/js/autocomplete.js? 304 NOT MODIFIED
[2019-Dec-14 18:38] 127.0.0.1 GET http /tree_view? 200 OK
[2019-Dec-14 18:38] 127.0.0.1 GET http /static/css/d3_css.css? 304 NOT MODIFIED
[2019-Dec-14 18:38] 127.0.0.1 GET http /favicon.ico? 5xx INTERNAL SERVER ERROR
Traceback (most recent call last):
  File "/home/jon/venv/p3/lib/python3.6/site-packages/flask/app.py", line 1813, in full_dispatch_request
    rv = self.dispatch_request()
  File "/home/jon/venv/p3/lib/python3.6/site-packages/flask/app.py", line 1791, in dispatch_request
    self.raise_routing_exception(req)
  File "/home/jon/venv/p3/lib/python3.6/site-packages/flask/app.py", line 1774, in raise_routing_exception
    raise request.routing_exception
  File "/home/jon/venv/p3/lib/python3.6/site-packages/flask/ctx.py", line 336, in match_request
    self.url_adapter.match(return_rule=True)
  File "/home/jon/venv/p3/lib/python3.6/site-packages/werkzeug/routing.py", line 1581, in match
    raise NotFound()
werkzeug.exceptions.NotFound: 404 Not Found: The requested URL was not found on the server.  If you entered the URL manually please check your spelling and try again.

[2019-Dec-14 18:38] 127.0.0.1 GET http /fetch_random_data? 200 OK
[2019-Dec-14 18:38] 127.0.0.1 GET http /? 200 OK
[2019-Dec-14 18:38] 127.0.0.1 GET http /network? 200 OK
[2019-Dec-14 18:38] 127.0.0.1 GET http /d3_data? 200 OK
[2019-Dec-14 18:38] 127.0.0.1 GET http /favicon.ico? 5xx INTERNAL SERVER ERROR
Traceback (most recent call last):
  File "/home/jon/venv/p3/lib/python3.6/site-packages/flask/app.py", line 1813, in full_dispatch_request
    rv = self.dispatch_request()
  File "/home/jon/venv/p3/lib/python3.6/site-packages/flask/app.py", line 1791, in dispatch_request
    self.raise_routing_exception(req)
  File "/home/jon/venv/p3/lib/python3.6/site-packages/flask/app.py", line 1774, in raise_routing_exception
    raise request.routing_exception
  File "/home/jon/venv/p3/lib/python3.6/site-packages/flask/ctx.py", line 336, in match_request
    self.url_adapter.match(return_rule=True)
  File "/home/jon/venv/p3/lib/python3.6/site-packages/werkzeug/routing.py", line 1581, in match
    raise NotFound()
werkzeug.exceptions.NotFound: 404 Not Found: The requested URL was not found on the server.  If you entered the URL manually please check your spelling and try again.

[2019-Dec-14 18:40] 127.0.0.1 GET http /network? 200 OK
[2019-Dec-14 18:40] 127.0.0.1 GET http /d3_data? 200 OK
[2019-Dec-14 18:40] 127.0.0.1 GET http /favicon.ico? 5xx INTERNAL SERVER ERROR
Traceback (most recent call last):
  File "/home/jon/venv/p3/lib/python3.6/site-packages/flask/app.py", line 1813, in full_dispatch_request
    rv = self.dispatch_request()
  File "/home/jon/venv/p3/lib/python3.6/site-packages/flask/app.py", line 1791, in dispatch_request
    self.raise_routing_exception(req)
  File "/home/jon/venv/p3/lib/python3.6/site-packages/flask/app.py", line 1774, in raise_routing_exception
    raise request.routing_exception
  File "/home/jon/venv/p3/lib/python3.6/site-packages/flask/ctx.py", line 336, in match_request
    self.url_adapter.match(return_rule=True)
  File "/home/jon/venv/p3/lib/python3.6/site-packages/werkzeug/routing.py", line 1581, in match
    raise NotFound()
werkzeug.exceptions.NotFound: 404 Not Found: The requested URL was not found on the server.  If you entered the URL manually please check your spelling and try again.

[2019-Dec-14 18:41] 127.0.0.1 GET http /network? 200 OK
[2019-Dec-14 18:41] 127.0.0.1 GET http /d3_data? 200 OK
[2019-Dec-14 18:41] 127.0.0.1 GET http /favicon.ico? 5xx INTERNAL SERVER ERROR
Traceback (most recent call last):
  File "/home/jon/venv/p3/lib/python3.6/site-packages/flask/app.py", line 1813, in full_dispatch_request
    rv = self.dispatch_request()
  File "/home/jon/venv/p3/lib/python3.6/site-packages/flask/app.py", line 1791, in dispatch_request
    self.raise_routing_exception(req)
  File "/home/jon/venv/p3/lib/python3.6/site-packages/flask/app.py", line 1774, in raise_routing_exception
    raise request.routing_exception
  File "/home/jon/venv/p3/lib/python3.6/site-packages/flask/ctx.py", line 336, in match_request
    self.url_adapter.match(return_rule=True)
  File "/home/jon/venv/p3/lib/python3.6/site-packages/werkzeug/routing.py", line 1581, in match
    raise NotFound()
werkzeug.exceptions.NotFound: 404 Not Found: The requested URL was not found on the server.  If you entered the URL manually please check your spelling and try again.

[2019-Dec-14 18:41] 127.0.0.1 GET http /network? 200 OK
[2019-Dec-14 18:41] 127.0.0.1 GET http /d3_data? 200 OK
[2019-Dec-14 18:41] 127.0.0.1 GET http /favicon.ico? 5xx INTERNAL SERVER ERROR
Traceback (most recent call last):
  File "/home/jon/venv/p3/lib/python3.6/site-packages/flask/app.py", line 1813, in full_dispatch_request
    rv = self.dispatch_request()
  File "/home/jon/venv/p3/lib/python3.6/site-packages/flask/app.py", line 1791, in dispatch_request
    self.raise_routing_exception(req)
  File "/home/jon/venv/p3/lib/python3.6/site-packages/flask/app.py", line 1774, in raise_routing_exception
    raise request.routing_exception
  File "/home/jon/venv/p3/lib/python3.6/site-packages/flask/ctx.py", line 336, in match_request
    self.url_adapter.match(return_rule=True)
  File "/home/jon/venv/p3/lib/python3.6/site-packages/werkzeug/routing.py", line 1581, in match
    raise NotFound()
werkzeug.exceptions.NotFound: 404 Not Found: The requested URL was not found on the server.  If you entered the URL manually please check your spelling and try again.

[2019-Dec-14 18:42] 127.0.0.1 GET http /? 200 OK
[2019-Dec-14 18:42] 127.0.0.1 GET http /static/css/auto-complete.css? 200 OK
[2019-Dec-14 18:42] 127.0.0.1 GET http /static/css/signin.css? 200 OK
[2019-Dec-14 18:42] 127.0.0.1 GET http /static/js/jquery-1.9.0.js? 200 OK
[2019-Dec-14 18:42] 127.0.0.1 GET http /static/js/script.js? 200 OK
[2019-Dec-14 18:42] 127.0.0.1 GET http /static/js/fetch.js? 200 OK
[2019-Dec-14 18:42] 127.0.0.1 GET http /static/js/auto-complete.min.js? 200 OK
[2019-Dec-14 18:42] 127.0.0.1 GET http /static/css/my_style.css? 200 OK
[2019-Dec-14 18:42] 127.0.0.1 GET http /static/css/scss_css.css? 200 OK
[2019-Dec-14 18:42] 127.0.0.1 GET http /static/js/autocomplete.js? 200 OK
[2019-Dec-14 18:42] 127.0.0.1 GET http /static/data/data.json? 200 OK
[2019-Dec-14 18:42] 127.0.0.1 GET http /static/css/scss_css.css.map? 200 OK
[2019-Dec-14 18:42] 127.0.0.1 GET http /test? 200 OK
[2019-Dec-14 18:42] 127.0.0.1 GET http /static/css/bootstrap.min.css? 200 OK
[2019-Dec-14 18:42] 127.0.0.1 GET http /static/js/script.js? 200 OK
[2019-Dec-14 18:42] 127.0.0.1 GET http /static/css/auto-complete.css? 200 OK
[2019-Dec-14 18:42] 127.0.0.1 GET http /static/css/signin.css? 200 OK
[2019-Dec-14 18:42] 127.0.0.1 GET http /static/js/jquery-1.9.0.js? 200 OK
[2019-Dec-14 18:42] 127.0.0.1 GET http /static/css/my_style.css? 200 OK
[2019-Dec-14 18:42] 127.0.0.1 GET http /static/js/fetch.js? 200 OK
[2019-Dec-14 18:42] 127.0.0.1 GET http /static/js/auto-complete.min.js? 200 OK
[2019-Dec-14 18:42] 127.0.0.1 GET http /static/data/data.json? 200 OK
[2019-Dec-14 18:42] 127.0.0.1 GET http /test_js? 200 OK
[2019-Dec-14 18:42] 127.0.0.1 GET http /favicon.ico? 5xx INTERNAL SERVER ERROR
Traceback (most recent call last):
  File "/home/jon/venv/p3/lib/python3.6/site-packages/flask/app.py", line 1813, in full_dispatch_request
    rv = self.dispatch_request()
  File "/home/jon/venv/p3/lib/python3.6/site-packages/flask/app.py", line 1791, in dispatch_request
    self.raise_routing_exception(req)
  File "/home/jon/venv/p3/lib/python3.6/site-packages/flask/app.py", line 1774, in raise_routing_exception
    raise request.routing_exception
  File "/home/jon/venv/p3/lib/python3.6/site-packages/flask/ctx.py", line 336, in match_request
    self.url_adapter.match(return_rule=True)
  File "/home/jon/venv/p3/lib/python3.6/site-packages/werkzeug/routing.py", line 1581, in match
    raise NotFound()
werkzeug.exceptions.NotFound: 404 Not Found: The requested URL was not found on the server.  If you entered the URL manually please check your spelling and try again.

[2019-Dec-14 18:42] 127.0.0.1 GET http /favicon.ico? 5xx INTERNAL SERVER ERROR
Traceback (most recent call last):
  File "/home/jon/venv/p3/lib/python3.6/site-packages/flask/app.py", line 1813, in full_dispatch_request
    rv = self.dispatch_request()
  File "/home/jon/venv/p3/lib/python3.6/site-packages/flask/app.py", line 1791, in dispatch_request
    self.raise_routing_exception(req)
  File "/home/jon/venv/p3/lib/python3.6/site-packages/flask/app.py", line 1774, in raise_routing_exception
    raise request.routing_exception
  File "/home/jon/venv/p3/lib/python3.6/site-packages/flask/ctx.py", line 336, in match_request
    self.url_adapter.match(return_rule=True)
  File "/home/jon/venv/p3/lib/python3.6/site-packages/werkzeug/routing.py", line 1581, in match
    raise NotFound()
werkzeug.exceptions.NotFound: 404 Not Found: The requested URL was not found on the server.  If you entered the URL manually please check your spelling and try again.

[2019-Dec-14 18:42] 127.0.0.1 GET http /favicon.ico? 5xx INTERNAL SERVER ERROR
Traceback (most recent call last):
  File "/home/jon/venv/p3/lib/python3.6/site-packages/flask/app.py", line 1813, in full_dispatch_request
    rv = self.dispatch_request()
  File "/home/jon/venv/p3/lib/python3.6/site-packages/flask/app.py", line 1791, in dispatch_request
    self.raise_routing_exception(req)
  File "/home/jon/venv/p3/lib/python3.6/site-packages/flask/app.py", line 1774, in raise_routing_exception
    raise request.routing_exception
  File "/home/jon/venv/p3/lib/python3.6/site-packages/flask/ctx.py", line 336, in match_request
    self.url_adapter.match(return_rule=True)
  File "/home/jon/venv/p3/lib/python3.6/site-packages/werkzeug/routing.py", line 1581, in match
    raise NotFound()
werkzeug.exceptions.NotFound: 404 Not Found: The requested URL was not found on the server.  If you entered the URL manually please check your spelling and try again.

[2019-Dec-14 18:42] 127.0.0.1 GET http /favicon.ico? 5xx INTERNAL SERVER ERROR
Traceback (most recent call last):
  File "/home/jon/venv/p3/lib/python3.6/site-packages/flask/app.py", line 1813, in full_dispatch_request
    rv = self.dispatch_request()
  File "/home/jon/venv/p3/lib/python3.6/site-packages/flask/app.py", line 1791, in dispatch_request
    self.raise_routing_exception(req)
  File "/home/jon/venv/p3/lib/python3.6/site-packages/flask/app.py", line 1774, in raise_routing_exception
    raise request.routing_exception
  File "/home/jon/venv/p3/lib/python3.6/site-packages/flask/ctx.py", line 336, in match_request
    self.url_adapter.match(return_rule=True)
  File "/home/jon/venv/p3/lib/python3.6/site-packages/werkzeug/routing.py", line 1581, in match
    raise NotFound()
werkzeug.exceptions.NotFound: 404 Not Found: The requested URL was not found on the server.  If you entered the URL manually please check your spelling and try again.

[2019-Dec-14 18:42] 127.0.0.1 GET http /? 200 OK
[2019-Dec-14 18:42] 127.0.0.1 GET http /static/css/auto-complete.css? 200 OK
[2019-Dec-14 18:42] 127.0.0.1 GET http /static/js/jquery-1.9.0.js? 200 OK
[2019-Dec-14 18:42] 127.0.0.1 GET http /static/css/signin.css? 200 OK
[2019-Dec-14 18:42] 127.0.0.1 GET http /static/js/script.js? 200 OK
[2019-Dec-14 18:42] 127.0.0.1 GET http /static/js/fetch.js? 200 OK
[2019-Dec-14 18:42] 127.0.0.1 GET http /static/js/auto-complete.min.js? 200 OK
[2019-Dec-14 18:42] 127.0.0.1 GET http /static/css/my_style.css? 200 OK
[2019-Dec-14 18:42] 127.0.0.1 GET http /static/css/scss_css.css? 200 OK
[2019-Dec-14 18:42] 127.0.0.1 GET http /static/data/data.json? 200 OK
[2019-Dec-14 18:42] 127.0.0.1 GET http /static/js/autocomplete.js? 200 OK
[2019-Dec-14 18:42] 127.0.0.1 GET http /static/css/scss_css.css.map? 200 OK
[2019-Dec-14 18:42] 127.0.0.1 GET http /network? 200 OK
[2019-Dec-14 18:42] 127.0.0.1 GET http /d3_data? 200 OK
[2019-Dec-14 18:42] 127.0.0.1 GET http /favicon.ico? 5xx INTERNAL SERVER ERROR
Traceback (most recent call last):
  File "/home/jon/venv/p3/lib/python3.6/site-packages/flask/app.py", line 1813, in full_dispatch_request
    rv = self.dispatch_request()
  File "/home/jon/venv/p3/lib/python3.6/site-packages/flask/app.py", line 1791, in dispatch_request
    self.raise_routing_exception(req)
  File "/home/jon/venv/p3/lib/python3.6/site-packages/flask/app.py", line 1774, in raise_routing_exception
    raise request.routing_exception
  File "/home/jon/venv/p3/lib/python3.6/site-packages/flask/ctx.py", line 336, in match_request
    self.url_adapter.match(return_rule=True)
  File "/home/jon/venv/p3/lib/python3.6/site-packages/werkzeug/routing.py", line 1581, in match
    raise NotFound()
werkzeug.exceptions.NotFound: 404 Not Found: The requested URL was not found on the server.  If you entered the URL manually please check your spelling and try again.

[2019-Dec-14 18:51] 127.0.0.1 GET http /path? 5xx INTERNAL SERVER ERROR
Traceback (most recent call last):
  File "/home/jon/venv/p3/lib/python3.6/site-packages/flask/app.py", line 1813, in full_dispatch_request
    rv = self.dispatch_request()
  File "/home/jon/venv/p3/lib/python3.6/site-packages/flask/app.py", line 1799, in dispatch_request
    return self.view_functions[rule.endpoint](**req.view_args)
  File "app.py", line 269, in path
    return json.dumps(json_data)
NameError: name 'json_data' is not defined

[2019-Dec-14 18:51] 127.0.0.1 GET http /favicon.ico? 5xx INTERNAL SERVER ERROR
Traceback (most recent call last):
  File "/home/jon/venv/p3/lib/python3.6/site-packages/flask/app.py", line 1813, in full_dispatch_request
    rv = self.dispatch_request()
  File "/home/jon/venv/p3/lib/python3.6/site-packages/flask/app.py", line 1791, in dispatch_request
    self.raise_routing_exception(req)
  File "/home/jon/venv/p3/lib/python3.6/site-packages/flask/app.py", line 1774, in raise_routing_exception
    raise request.routing_exception
  File "/home/jon/venv/p3/lib/python3.6/site-packages/flask/ctx.py", line 336, in match_request
    self.url_adapter.match(return_rule=True)
  File "/home/jon/venv/p3/lib/python3.6/site-packages/werkzeug/routing.py", line 1581, in match
    raise NotFound()
werkzeug.exceptions.NotFound: 404 Not Found: The requested URL was not found on the server.  If you entered the URL manually please check your spelling and try again.

[2019-Dec-14 18:52] 127.0.0.1 GET http /path? 200 OK
[2019-Dec-14 18:52] 127.0.0.1 GET http /favicon.ico? 5xx INTERNAL SERVER ERROR
Traceback (most recent call last):
  File "/home/jon/venv/p3/lib/python3.6/site-packages/flask/app.py", line 1813, in full_dispatch_request
    rv = self.dispatch_request()
  File "/home/jon/venv/p3/lib/python3.6/site-packages/flask/app.py", line 1791, in dispatch_request
    self.raise_routing_exception(req)
  File "/home/jon/venv/p3/lib/python3.6/site-packages/flask/app.py", line 1774, in raise_routing_exception
    raise request.routing_exception
  File "/home/jon/venv/p3/lib/python3.6/site-packages/flask/ctx.py", line 336, in match_request
    self.url_adapter.match(return_rule=True)
  File "/home/jon/venv/p3/lib/python3.6/site-packages/werkzeug/routing.py", line 1581, in match
    raise NotFound()
werkzeug.exceptions.NotFound: 404 Not Found: The requested URL was not found on the server.  If you entered the URL manually please check your spelling and try again.

[2019-Dec-14 18:55] 127.0.0.1 GET http /? 200 OK
[2019-Dec-14 18:55] 127.0.0.1 GET http /network? 200 OK
[2019-Dec-14 18:55] 127.0.0.1 GET http /d3_data? 5xx INTERNAL SERVER ERROR
Traceback (most recent call last):
  File "/home/jon/venv/p3/lib/python3.6/site-packages/flask/app.py", line 1813, in full_dispatch_request
    rv = self.dispatch_request()
  File "/home/jon/venv/p3/lib/python3.6/site-packages/flask/app.py", line 1799, in dispatch_request
    return self.view_functions[rule.endpoint](**req.view_args)
  File "app.py", line 260, in d3_data
    with open ("/static/data/d3_data.json", r) as f:
NameError: name 'r' is not defined

[2019-Dec-14 18:55] 127.0.0.1 GET http /favicon.ico? 5xx INTERNAL SERVER ERROR
Traceback (most recent call last):
  File "/home/jon/venv/p3/lib/python3.6/site-packages/flask/app.py", line 1813, in full_dispatch_request
    rv = self.dispatch_request()
  File "/home/jon/venv/p3/lib/python3.6/site-packages/flask/app.py", line 1791, in dispatch_request
    self.raise_routing_exception(req)
  File "/home/jon/venv/p3/lib/python3.6/site-packages/flask/app.py", line 1774, in raise_routing_exception
    raise request.routing_exception
  File "/home/jon/venv/p3/lib/python3.6/site-packages/flask/ctx.py", line 336, in match_request
    self.url_adapter.match(return_rule=True)
  File "/home/jon/venv/p3/lib/python3.6/site-packages/werkzeug/routing.py", line 1581, in match
    raise NotFound()
werkzeug.exceptions.NotFound: 404 Not Found: The requested URL was not found on the server.  If you entered the URL manually please check your spelling and try again.

[2019-Dec-14 18:55] 127.0.0.1 GET http /? 200 OK
[2019-Dec-14 18:55] 127.0.0.1 GET http /static/css/auto-complete.css? 200 OK
[2019-Dec-14 18:55] 127.0.0.1 GET http /static/css/signin.css? 200 OK
[2019-Dec-14 18:55] 127.0.0.1 GET http /static/js/jquery-1.9.0.js? 200 OK
[2019-Dec-14 18:55] 127.0.0.1 GET http /static/css/my_style.css? 200 OK
[2019-Dec-14 18:55] 127.0.0.1 GET http /static/js/script.js? 200 OK
[2019-Dec-14 18:55] 127.0.0.1 GET http /static/css/scss_css.css? 200 OK
[2019-Dec-14 18:55] 127.0.0.1 GET http /static/js/fetch.js? 200 OK
[2019-Dec-14 18:55] 127.0.0.1 GET http /static/js/auto-complete.min.js? 200 OK
[2019-Dec-14 18:55] 127.0.0.1 GET http /static/data/data.json? 200 OK
[2019-Dec-14 18:55] 127.0.0.1 GET http /static/js/autocomplete.js? 200 OK
[2019-Dec-14 18:55] 127.0.0.1 GET http /static/css/scss_css.css.map? 200 OK
[2019-Dec-14 18:55] 127.0.0.1 GET http /network? 200 OK
[2019-Dec-14 18:55] 127.0.0.1 GET http /d3_data? 5xx INTERNAL SERVER ERROR
Traceback (most recent call last):
  File "/home/jon/venv/p3/lib/python3.6/site-packages/flask/app.py", line 1813, in full_dispatch_request
    rv = self.dispatch_request()
  File "/home/jon/venv/p3/lib/python3.6/site-packages/flask/app.py", line 1799, in dispatch_request
    return self.view_functions[rule.endpoint](**req.view_args)
  File "app.py", line 260, in d3_data
    with open ("/static/data/d3_data.json", "r") as f:
FileNotFoundError: [Errno 2] No such file or directory: '/static/data/d3_data.json'

[2019-Dec-14 18:55] 127.0.0.1 GET http /favicon.ico? 5xx INTERNAL SERVER ERROR
Traceback (most recent call last):
  File "/home/jon/venv/p3/lib/python3.6/site-packages/flask/app.py", line 1813, in full_dispatch_request
    rv = self.dispatch_request()
  File "/home/jon/venv/p3/lib/python3.6/site-packages/flask/app.py", line 1791, in dispatch_request
    self.raise_routing_exception(req)
  File "/home/jon/venv/p3/lib/python3.6/site-packages/flask/app.py", line 1774, in raise_routing_exception
    raise request.routing_exception
  File "/home/jon/venv/p3/lib/python3.6/site-packages/flask/ctx.py", line 336, in match_request
    self.url_adapter.match(return_rule=True)
  File "/home/jon/venv/p3/lib/python3.6/site-packages/werkzeug/routing.py", line 1581, in match
    raise NotFound()
werkzeug.exceptions.NotFound: 404 Not Found: The requested URL was not found on the server.  If you entered the URL manually please check your spelling and try again.

[2019-Dec-14 18:56] 127.0.0.1 GET http /network? 200 OK
[2019-Dec-14 18:56] 127.0.0.1 GET http /d3_data? 5xx INTERNAL SERVER ERROR
Traceback (most recent call last):
  File "/home/jon/venv/p3/lib/python3.6/site-packages/flask/app.py", line 1813, in full_dispatch_request
    rv = self.dispatch_request()
  File "/home/jon/venv/p3/lib/python3.6/site-packages/flask/app.py", line 1799, in dispatch_request
    return self.view_functions[rule.endpoint](**req.view_args)
  File "app.py", line 260, in d3_data
    with open ("/static/data/d3_data.json", "r") as f:
FileNotFoundError: [Errno 2] No such file or directory: '/static/data/d3_data.json'

[2019-Dec-14 18:56] 127.0.0.1 GET http /favicon.ico? 5xx INTERNAL SERVER ERROR
Traceback (most recent call last):
  File "/home/jon/venv/p3/lib/python3.6/site-packages/flask/app.py", line 1813, in full_dispatch_request
    rv = self.dispatch_request()
  File "/home/jon/venv/p3/lib/python3.6/site-packages/flask/app.py", line 1791, in dispatch_request
    self.raise_routing_exception(req)
  File "/home/jon/venv/p3/lib/python3.6/site-packages/flask/app.py", line 1774, in raise_routing_exception
    raise request.routing_exception
  File "/home/jon/venv/p3/lib/python3.6/site-packages/flask/ctx.py", line 336, in match_request
    self.url_adapter.match(return_rule=True)
  File "/home/jon/venv/p3/lib/python3.6/site-packages/werkzeug/routing.py", line 1581, in match
    raise NotFound()
werkzeug.exceptions.NotFound: 404 Not Found: The requested URL was not found on the server.  If you entered the URL manually please check your spelling and try again.

[2019-Dec-14 18:56] 127.0.0.1 GET http /network? 200 OK
[2019-Dec-14 18:56] 127.0.0.1 GET http /d3_data? 200 OK
[2019-Dec-14 18:56] 127.0.0.1 GET http /favicon.ico? 5xx INTERNAL SERVER ERROR
Traceback (most recent call last):
  File "/home/jon/venv/p3/lib/python3.6/site-packages/flask/app.py", line 1813, in full_dispatch_request
    rv = self.dispatch_request()
  File "/home/jon/venv/p3/lib/python3.6/site-packages/flask/app.py", line 1791, in dispatch_request
    self.raise_routing_exception(req)
  File "/home/jon/venv/p3/lib/python3.6/site-packages/flask/app.py", line 1774, in raise_routing_exception
    raise request.routing_exception
  File "/home/jon/venv/p3/lib/python3.6/site-packages/flask/ctx.py", line 336, in match_request
    self.url_adapter.match(return_rule=True)
  File "/home/jon/venv/p3/lib/python3.6/site-packages/werkzeug/routing.py", line 1581, in match
    raise NotFound()
werkzeug.exceptions.NotFound: 404 Not Found: The requested URL was not found on the server.  If you entered the URL manually please check your spelling and try again.

[2019-Dec-14 18:56] 127.0.0.1 GET http /? 200 OK
[2019-Dec-14 18:56] 127.0.0.1 GET http /static/js/jquery-1.9.0.js? 200 OK
[2019-Dec-14 18:56] 127.0.0.1 GET http /static/css/signin.css? 200 OK
[2019-Dec-14 18:56] 127.0.0.1 GET http /static/css/auto-complete.css? 200 OK
[2019-Dec-14 18:56] 127.0.0.1 GET http /static/js/script.js? 200 OK
[2019-Dec-14 18:56] 127.0.0.1 GET http /static/js/auto-complete.min.js? 200 OK
[2019-Dec-14 18:56] 127.0.0.1 GET http /static/js/fetch.js? 200 OK
[2019-Dec-14 18:56] 127.0.0.1 GET http /static/css/my_style.css? 200 OK
[2019-Dec-14 18:56] 127.0.0.1 GET http /static/css/scss_css.css? 200 OK
[2019-Dec-14 18:56] 127.0.0.1 GET http /static/data/data.json? 200 OK
[2019-Dec-14 18:56] 127.0.0.1 GET http /static/js/autocomplete.js? 200 OK
[2019-Dec-14 18:56] 127.0.0.1 GET http /static/css/scss_css.css.map? 200 OK
[2019-Dec-14 18:56] 127.0.0.1 GET http /network? 200 OK
[2019-Dec-14 18:56] 127.0.0.1 GET http /d3_data? 200 OK
[2019-Dec-14 18:56] 127.0.0.1 GET http /favicon.ico? 5xx INTERNAL SERVER ERROR
Traceback (most recent call last):
  File "/home/jon/venv/p3/lib/python3.6/site-packages/flask/app.py", line 1813, in full_dispatch_request
    rv = self.dispatch_request()
  File "/home/jon/venv/p3/lib/python3.6/site-packages/flask/app.py", line 1791, in dispatch_request
    self.raise_routing_exception(req)
  File "/home/jon/venv/p3/lib/python3.6/site-packages/flask/app.py", line 1774, in raise_routing_exception
    raise request.routing_exception
  File "/home/jon/venv/p3/lib/python3.6/site-packages/flask/ctx.py", line 336, in match_request
    self.url_adapter.match(return_rule=True)
  File "/home/jon/venv/p3/lib/python3.6/site-packages/werkzeug/routing.py", line 1581, in match
    raise NotFound()
werkzeug.exceptions.NotFound: 404 Not Found: The requested URL was not found on the server.  If you entered the URL manually please check your spelling and try again.

[2019-Dec-14 18:57] 127.0.0.1 GET http /network? 200 OK
[2019-Dec-14 18:57] 127.0.0.1 GET http /d3_data? 200 OK
[2019-Dec-14 18:57] 127.0.0.1 GET http /favicon.ico? 5xx INTERNAL SERVER ERROR
Traceback (most recent call last):
  File "/home/jon/venv/p3/lib/python3.6/site-packages/flask/app.py", line 1813, in full_dispatch_request
    rv = self.dispatch_request()
  File "/home/jon/venv/p3/lib/python3.6/site-packages/flask/app.py", line 1791, in dispatch_request
    self.raise_routing_exception(req)
  File "/home/jon/venv/p3/lib/python3.6/site-packages/flask/app.py", line 1774, in raise_routing_exception
    raise request.routing_exception
  File "/home/jon/venv/p3/lib/python3.6/site-packages/flask/ctx.py", line 336, in match_request
    self.url_adapter.match(return_rule=True)
  File "/home/jon/venv/p3/lib/python3.6/site-packages/werkzeug/routing.py", line 1581, in match
    raise NotFound()
werkzeug.exceptions.NotFound: 404 Not Found: The requested URL was not found on the server.  If you entered the URL manually please check your spelling and try again.

[2019-Dec-14 18:57] 127.0.0.1 GET http /network? 200 OK
[2019-Dec-14 18:57] 127.0.0.1 GET http /favicon.ico? 5xx INTERNAL SERVER ERROR
Traceback (most recent call last):
  File "/home/jon/venv/p3/lib/python3.6/site-packages/flask/app.py", line 1813, in full_dispatch_request
    rv = self.dispatch_request()
  File "/home/jon/venv/p3/lib/python3.6/site-packages/flask/app.py", line 1791, in dispatch_request
    self.raise_routing_exception(req)
  File "/home/jon/venv/p3/lib/python3.6/site-packages/flask/app.py", line 1774, in raise_routing_exception
    raise request.routing_exception
  File "/home/jon/venv/p3/lib/python3.6/site-packages/flask/ctx.py", line 336, in match_request
    self.url_adapter.match(return_rule=True)
  File "/home/jon/venv/p3/lib/python3.6/site-packages/werkzeug/routing.py", line 1581, in match
    raise NotFound()
werkzeug.exceptions.NotFound: 404 Not Found: The requested URL was not found on the server.  If you entered the URL manually please check your spelling and try again.

[2019-Dec-14 18:58] 127.0.0.1 GET http /network? 200 OK
[2019-Dec-14 18:58] 127.0.0.1 GET http /d3_data? 200 OK
[2019-Dec-14 18:58] 127.0.0.1 GET http /favicon.ico? 5xx INTERNAL SERVER ERROR
Traceback (most recent call last):
  File "/home/jon/venv/p3/lib/python3.6/site-packages/flask/app.py", line 1813, in full_dispatch_request
    rv = self.dispatch_request()
  File "/home/jon/venv/p3/lib/python3.6/site-packages/flask/app.py", line 1791, in dispatch_request
    self.raise_routing_exception(req)
  File "/home/jon/venv/p3/lib/python3.6/site-packages/flask/app.py", line 1774, in raise_routing_exception
    raise request.routing_exception
  File "/home/jon/venv/p3/lib/python3.6/site-packages/flask/ctx.py", line 336, in match_request
    self.url_adapter.match(return_rule=True)
  File "/home/jon/venv/p3/lib/python3.6/site-packages/werkzeug/routing.py", line 1581, in match
    raise NotFound()
werkzeug.exceptions.NotFound: 404 Not Found: The requested URL was not found on the server.  If you entered the URL manually please check your spelling and try again.

[2019-Dec-14 19:00] 127.0.0.1 GET http /network? 200 OK
[2019-Dec-14 19:00] 127.0.0.1 GET http /d3_data? 5xx INTERNAL SERVER ERROR
Traceback (most recent call last):
  File "/home/jon/venv/p3/lib/python3.6/site-packages/flask/app.py", line 1813, in full_dispatch_request
    rv = self.dispatch_request()
  File "/home/jon/venv/p3/lib/python3.6/site-packages/flask/app.py", line 1799, in dispatch_request
    return self.view_functions[rule.endpoint](**req.view_args)
  File "app.py", line 263, in d3_data
    return json.dumps(json.load(data_array))
  File "/home/jon/venv/p3/lib/python3.6/site-packages/flask/json/__init__.py", line 213, in load
    fp = _wrap_reader_for_text(fp, kwargs.pop('encoding', None) or 'utf-8')
  File "/home/jon/venv/p3/lib/python3.6/site-packages/flask/json/__init__.py", line 35, in _wrap_reader_for_text
    if isinstance(fp.read(0), bytes):
AttributeError: 'list' object has no attribute 'read'

[2019-Dec-14 19:00] 127.0.0.1 GET http /favicon.ico? 5xx INTERNAL SERVER ERROR
Traceback (most recent call last):
  File "/home/jon/venv/p3/lib/python3.6/site-packages/flask/app.py", line 1813, in full_dispatch_request
    rv = self.dispatch_request()
  File "/home/jon/venv/p3/lib/python3.6/site-packages/flask/app.py", line 1791, in dispatch_request
    self.raise_routing_exception(req)
  File "/home/jon/venv/p3/lib/python3.6/site-packages/flask/app.py", line 1774, in raise_routing_exception
    raise request.routing_exception
  File "/home/jon/venv/p3/lib/python3.6/site-packages/flask/ctx.py", line 336, in match_request
    self.url_adapter.match(return_rule=True)
  File "/home/jon/venv/p3/lib/python3.6/site-packages/werkzeug/routing.py", line 1581, in match
    raise NotFound()
werkzeug.exceptions.NotFound: 404 Not Found: The requested URL was not found on the server.  If you entered the URL manually please check your spelling and try again.

[2019-Dec-14 19:00] 127.0.0.1 GET http /network? 200 OK
[2019-Dec-14 19:00] 127.0.0.1 GET http /d3_data? 5xx INTERNAL SERVER ERROR
Traceback (most recent call last):
  File "/home/jon/venv/p3/lib/python3.6/site-packages/flask/app.py", line 1813, in full_dispatch_request
    rv = self.dispatch_request()
  File "/home/jon/venv/p3/lib/python3.6/site-packages/flask/app.py", line 1799, in dispatch_request
    return self.view_functions[rule.endpoint](**req.view_args)
  File "app.py", line 263, in d3_data
    return json.dumps(json.load(data_array))
  File "/home/jon/venv/p3/lib/python3.6/site-packages/flask/json/__init__.py", line 213, in load
    fp = _wrap_reader_for_text(fp, kwargs.pop('encoding', None) or 'utf-8')
  File "/home/jon/venv/p3/lib/python3.6/site-packages/flask/json/__init__.py", line 35, in _wrap_reader_for_text
    if isinstance(fp.read(0), bytes):
AttributeError: 'list' object has no attribute 'read'

[2019-Dec-14 19:00] 127.0.0.1 GET http /favicon.ico? 5xx INTERNAL SERVER ERROR
Traceback (most recent call last):
  File "/home/jon/venv/p3/lib/python3.6/site-packages/flask/app.py", line 1813, in full_dispatch_request
    rv = self.dispatch_request()
  File "/home/jon/venv/p3/lib/python3.6/site-packages/flask/app.py", line 1791, in dispatch_request
    self.raise_routing_exception(req)
  File "/home/jon/venv/p3/lib/python3.6/site-packages/flask/app.py", line 1774, in raise_routing_exception
    raise request.routing_exception
  File "/home/jon/venv/p3/lib/python3.6/site-packages/flask/ctx.py", line 336, in match_request
    self.url_adapter.match(return_rule=True)
  File "/home/jon/venv/p3/lib/python3.6/site-packages/werkzeug/routing.py", line 1581, in match
    raise NotFound()
werkzeug.exceptions.NotFound: 404 Not Found: The requested URL was not found on the server.  If you entered the URL manually please check your spelling and try again.

[2019-Dec-14 19:02] 127.0.0.1 GET http /network? 200 OK
[2019-Dec-14 19:02] 127.0.0.1 GET http /d3_data? 5xx INTERNAL SERVER ERROR
Traceback (most recent call last):
  File "/home/jon/venv/p3/lib/python3.6/site-packages/flask/app.py", line 1813, in full_dispatch_request
    rv = self.dispatch_request()
  File "/home/jon/venv/p3/lib/python3.6/site-packages/flask/app.py", line 1799, in dispatch_request
    return self.view_functions[rule.endpoint](**req.view_args)
  File "app.py", line 262, in d3_data
    data_str = data_array.join("\n")
AttributeError: 'list' object has no attribute 'join'

[2019-Dec-14 19:02] 127.0.0.1 GET http /favicon.ico? 5xx INTERNAL SERVER ERROR
Traceback (most recent call last):
  File "/home/jon/venv/p3/lib/python3.6/site-packages/flask/app.py", line 1813, in full_dispatch_request
    rv = self.dispatch_request()
  File "/home/jon/venv/p3/lib/python3.6/site-packages/flask/app.py", line 1791, in dispatch_request
    self.raise_routing_exception(req)
  File "/home/jon/venv/p3/lib/python3.6/site-packages/flask/app.py", line 1774, in raise_routing_exception
    raise request.routing_exception
  File "/home/jon/venv/p3/lib/python3.6/site-packages/flask/ctx.py", line 336, in match_request
    self.url_adapter.match(return_rule=True)
  File "/home/jon/venv/p3/lib/python3.6/site-packages/werkzeug/routing.py", line 1581, in match
    raise NotFound()
werkzeug.exceptions.NotFound: 404 Not Found: The requested URL was not found on the server.  If you entered the URL manually please check your spelling and try again.

[2019-Dec-14 19:02] 127.0.0.1 GET http /network? 200 OK
[2019-Dec-14 19:02] 127.0.0.1 GET http /d3_data? 5xx INTERNAL SERVER ERROR
Traceback (most recent call last):
  File "/home/jon/venv/p3/lib/python3.6/site-packages/flask/app.py", line 1813, in full_dispatch_request
    rv = self.dispatch_request()
  File "/home/jon/venv/p3/lib/python3.6/site-packages/flask/app.py", line 1799, in dispatch_request
    return self.view_functions[rule.endpoint](**req.view_args)
  File "app.py", line 262, in d3_data
    data_str = data_array.join("\n")
AttributeError: 'list' object has no attribute 'join'

[2019-Dec-14 19:02] 127.0.0.1 GET http /favicon.ico? 5xx INTERNAL SERVER ERROR
Traceback (most recent call last):
  File "/home/jon/venv/p3/lib/python3.6/site-packages/flask/app.py", line 1813, in full_dispatch_request
    rv = self.dispatch_request()
  File "/home/jon/venv/p3/lib/python3.6/site-packages/flask/app.py", line 1791, in dispatch_request
    self.raise_routing_exception(req)
  File "/home/jon/venv/p3/lib/python3.6/site-packages/flask/app.py", line 1774, in raise_routing_exception
    raise request.routing_exception
  File "/home/jon/venv/p3/lib/python3.6/site-packages/flask/ctx.py", line 336, in match_request
    self.url_adapter.match(return_rule=True)
  File "/home/jon/venv/p3/lib/python3.6/site-packages/werkzeug/routing.py", line 1581, in match
    raise NotFound()
werkzeug.exceptions.NotFound: 404 Not Found: The requested URL was not found on the server.  If you entered the URL manually please check your spelling and try again.

[2019-Dec-14 19:03] 127.0.0.1 GET http /network? 200 OK
[2019-Dec-14 19:03] 127.0.0.1 GET http /d3_data? 5xx INTERNAL SERVER ERROR
Traceback (most recent call last):
  File "/home/jon/venv/p3/lib/python3.6/site-packages/flask/app.py", line 1813, in full_dispatch_request
    rv = self.dispatch_request()
  File "/home/jon/venv/p3/lib/python3.6/site-packages/flask/app.py", line 1799, in dispatch_request
    return self.view_functions[rule.endpoint](**req.view_args)
  File "app.py", line 262, in d3_data
    data_str = data_array.join("\n")
AttributeError: 'list' object has no attribute 'join'

[2019-Dec-14 19:03] 127.0.0.1 GET http /favicon.ico? 5xx INTERNAL SERVER ERROR
Traceback (most recent call last):
  File "/home/jon/venv/p3/lib/python3.6/site-packages/flask/app.py", line 1813, in full_dispatch_request
    rv = self.dispatch_request()
  File "/home/jon/venv/p3/lib/python3.6/site-packages/flask/app.py", line 1791, in dispatch_request
    self.raise_routing_exception(req)
  File "/home/jon/venv/p3/lib/python3.6/site-packages/flask/app.py", line 1774, in raise_routing_exception
    raise request.routing_exception
  File "/home/jon/venv/p3/lib/python3.6/site-packages/flask/ctx.py", line 336, in match_request
    self.url_adapter.match(return_rule=True)
  File "/home/jon/venv/p3/lib/python3.6/site-packages/werkzeug/routing.py", line 1581, in match
    raise NotFound()
werkzeug.exceptions.NotFound: 404 Not Found: The requested URL was not found on the server.  If you entered the URL manually please check your spelling and try again.

[2019-Dec-14 19:08] 127.0.0.1 GET http /network? 200 OK
[2019-Dec-14 19:08] 127.0.0.1 GET http /d3_data? 5xx INTERNAL SERVER ERROR
Traceback (most recent call last):
  File "/home/jon/venv/p3/lib/python3.6/site-packages/flask/app.py", line 1813, in full_dispatch_request
    rv = self.dispatch_request()
  File "/home/jon/venv/p3/lib/python3.6/site-packages/flask/app.py", line 1799, in dispatch_request
    return self.view_functions[rule.endpoint](**req.view_args)
  File "app.py", line 263, in d3_data
    str = str + line.strip("\n")
UnboundLocalError: local variable 'str' referenced before assignment

[2019-Dec-14 19:08] 127.0.0.1 GET http /favicon.ico? 5xx INTERNAL SERVER ERROR
Traceback (most recent call last):
  File "/home/jon/venv/p3/lib/python3.6/site-packages/flask/app.py", line 1813, in full_dispatch_request
    rv = self.dispatch_request()
  File "/home/jon/venv/p3/lib/python3.6/site-packages/flask/app.py", line 1791, in dispatch_request
    self.raise_routing_exception(req)
  File "/home/jon/venv/p3/lib/python3.6/site-packages/flask/app.py", line 1774, in raise_routing_exception
    raise request.routing_exception
  File "/home/jon/venv/p3/lib/python3.6/site-packages/flask/ctx.py", line 336, in match_request
    self.url_adapter.match(return_rule=True)
  File "/home/jon/venv/p3/lib/python3.6/site-packages/werkzeug/routing.py", line 1581, in match
    raise NotFound()
werkzeug.exceptions.NotFound: 404 Not Found: The requested URL was not found on the server.  If you entered the URL manually please check your spelling and try again.

[2019-Dec-14 19:10] 127.0.0.1 GET http /network? 200 OK
[2019-Dec-14 19:10] 127.0.0.1 GET http /d3_data? 5xx INTERNAL SERVER ERROR
Traceback (most recent call last):
  File "/home/jon/venv/p3/lib/python3.6/site-packages/flask/app.py", line 1813, in full_dispatch_request
    rv = self.dispatch_request()
  File "/home/jon/venv/p3/lib/python3.6/site-packages/flask/app.py", line 1799, in dispatch_request
    return self.view_functions[rule.endpoint](**req.view_args)
  File "app.py", line 263, in d3_data
    str = str + line.strip("\n")
UnboundLocalError: local variable 'str' referenced before assignment

[2019-Dec-14 19:10] 127.0.0.1 GET http /favicon.ico? 5xx INTERNAL SERVER ERROR
Traceback (most recent call last):
  File "/home/jon/venv/p3/lib/python3.6/site-packages/flask/app.py", line 1813, in full_dispatch_request
    rv = self.dispatch_request()
  File "/home/jon/venv/p3/lib/python3.6/site-packages/flask/app.py", line 1791, in dispatch_request
    self.raise_routing_exception(req)
  File "/home/jon/venv/p3/lib/python3.6/site-packages/flask/app.py", line 1774, in raise_routing_exception
    raise request.routing_exception
  File "/home/jon/venv/p3/lib/python3.6/site-packages/flask/ctx.py", line 336, in match_request
    self.url_adapter.match(return_rule=True)
  File "/home/jon/venv/p3/lib/python3.6/site-packages/werkzeug/routing.py", line 1581, in match
    raise NotFound()
werkzeug.exceptions.NotFound: 404 Not Found: The requested URL was not found on the server.  If you entered the URL manually please check your spelling and try again.

[2019-Dec-14 19:11] 127.0.0.1 GET http /network? 200 OK
[2019-Dec-14 19:11] 127.0.0.1 GET http /d3_data? 5xx INTERNAL SERVER ERROR
Traceback (most recent call last):
  File "/home/jon/venv/p3/lib/python3.6/site-packages/flask/app.py", line 1813, in full_dispatch_request
    rv = self.dispatch_request()
  File "/home/jon/venv/p3/lib/python3.6/site-packages/flask/app.py", line 1799, in dispatch_request
    return self.view_functions[rule.endpoint](**req.view_args)
  File "app.py", line 264, in d3_data
    str = str + line.strip("\n")
UnboundLocalError: local variable 'str' referenced before assignment

[2019-Dec-14 19:11] 127.0.0.1 GET http /favicon.ico? 5xx INTERNAL SERVER ERROR
Traceback (most recent call last):
  File "/home/jon/venv/p3/lib/python3.6/site-packages/flask/app.py", line 1813, in full_dispatch_request
    rv = self.dispatch_request()
  File "/home/jon/venv/p3/lib/python3.6/site-packages/flask/app.py", line 1791, in dispatch_request
    self.raise_routing_exception(req)
  File "/home/jon/venv/p3/lib/python3.6/site-packages/flask/app.py", line 1774, in raise_routing_exception
    raise request.routing_exception
  File "/home/jon/venv/p3/lib/python3.6/site-packages/flask/ctx.py", line 336, in match_request
    self.url_adapter.match(return_rule=True)
  File "/home/jon/venv/p3/lib/python3.6/site-packages/werkzeug/routing.py", line 1581, in match
    raise NotFound()
werkzeug.exceptions.NotFound: 404 Not Found: The requested URL was not found on the server.  If you entered the URL manually please check your spelling and try again.

[2019-Dec-14 19:13] 127.0.0.1 GET http /network? 200 OK
[2019-Dec-14 19:13] 127.0.0.1 GET http /d3_data? 5xx INTERNAL SERVER ERROR
Traceback (most recent call last):
  File "/home/jon/venv/p3/lib/python3.6/site-packages/flask/app.py", line 1813, in full_dispatch_request
    rv = self.dispatch_request()
  File "/home/jon/venv/p3/lib/python3.6/site-packages/flask/app.py", line 1799, in dispatch_request
    return self.view_functions[rule.endpoint](**req.view_args)
  File "app.py", line 264, in d3_data
    str = str + line
UnboundLocalError: local variable 'str' referenced before assignment

[2019-Dec-14 19:13] 127.0.0.1 GET http /favicon.ico? 5xx INTERNAL SERVER ERROR
Traceback (most recent call last):
  File "/home/jon/venv/p3/lib/python3.6/site-packages/flask/app.py", line 1813, in full_dispatch_request
    rv = self.dispatch_request()
  File "/home/jon/venv/p3/lib/python3.6/site-packages/flask/app.py", line 1791, in dispatch_request
    self.raise_routing_exception(req)
  File "/home/jon/venv/p3/lib/python3.6/site-packages/flask/app.py", line 1774, in raise_routing_exception
    raise request.routing_exception
  File "/home/jon/venv/p3/lib/python3.6/site-packages/flask/ctx.py", line 336, in match_request
    self.url_adapter.match(return_rule=True)
  File "/home/jon/venv/p3/lib/python3.6/site-packages/werkzeug/routing.py", line 1581, in match
    raise NotFound()
werkzeug.exceptions.NotFound: 404 Not Found: The requested URL was not found on the server.  If you entered the URL manually please check your spelling and try again.

[2019-Dec-14 19:13] 127.0.0.1 GET http /network? 200 OK
[2019-Dec-14 19:13] 127.0.0.1 GET http /d3_data? 5xx INTERNAL SERVER ERROR
Traceback (most recent call last):
  File "/home/jon/venv/p3/lib/python3.6/site-packages/flask/app.py", line 1813, in full_dispatch_request
    rv = self.dispatch_request()
  File "/home/jon/venv/p3/lib/python3.6/site-packages/flask/app.py", line 1799, in dispatch_request
    return self.view_functions[rule.endpoint](**req.view_args)
  File "app.py", line 265, in d3_data
    str = str + line
UnboundLocalError: local variable 'str' referenced before assignment

[2019-Dec-14 19:13] 127.0.0.1 GET http /favicon.ico? 5xx INTERNAL SERVER ERROR
Traceback (most recent call last):
  File "/home/jon/venv/p3/lib/python3.6/site-packages/flask/app.py", line 1813, in full_dispatch_request
    rv = self.dispatch_request()
  File "/home/jon/venv/p3/lib/python3.6/site-packages/flask/app.py", line 1791, in dispatch_request
    self.raise_routing_exception(req)
  File "/home/jon/venv/p3/lib/python3.6/site-packages/flask/app.py", line 1774, in raise_routing_exception
    raise request.routing_exception
  File "/home/jon/venv/p3/lib/python3.6/site-packages/flask/ctx.py", line 336, in match_request
    self.url_adapter.match(return_rule=True)
  File "/home/jon/venv/p3/lib/python3.6/site-packages/werkzeug/routing.py", line 1581, in match
    raise NotFound()
werkzeug.exceptions.NotFound: 404 Not Found: The requested URL was not found on the server.  If you entered the URL manually please check your spelling and try again.

[2019-Dec-14 19:18] 127.0.0.1 GET http /network? 200 OK
[2019-Dec-14 19:18] 127.0.0.1 GET http /d3_data? 5xx INTERNAL SERVER ERROR
Traceback (most recent call last):
  File "/home/jon/venv/p3/lib/python3.6/site-packages/flask/app.py", line 1813, in full_dispatch_request
    rv = self.dispatch_request()
  File "/home/jon/venv/p3/lib/python3.6/site-packages/flask/app.py", line 1799, in dispatch_request
    return self.view_functions[rule.endpoint](**req.view_args)
  File "app.py", line 261, in d3_data
    data_array = json.load(first_page)
  File "/home/jon/venv/p3/lib/python3.6/site-packages/flask/json/__init__.py", line 213, in load
    fp = _wrap_reader_for_text(fp, kwargs.pop('encoding', None) or 'utf-8')
  File "/home/jon/venv/p3/lib/python3.6/site-packages/flask/json/__init__.py", line 35, in _wrap_reader_for_text
    if isinstance(fp.read(0), bytes):
AttributeError: 'function' object has no attribute 'read'

[2019-Dec-14 19:18] 127.0.0.1 GET http /favicon.ico? 5xx INTERNAL SERVER ERROR
Traceback (most recent call last):
  File "/home/jon/venv/p3/lib/python3.6/site-packages/flask/app.py", line 1813, in full_dispatch_request
    rv = self.dispatch_request()
  File "/home/jon/venv/p3/lib/python3.6/site-packages/flask/app.py", line 1791, in dispatch_request
    self.raise_routing_exception(req)
  File "/home/jon/venv/p3/lib/python3.6/site-packages/flask/app.py", line 1774, in raise_routing_exception
    raise request.routing_exception
  File "/home/jon/venv/p3/lib/python3.6/site-packages/flask/ctx.py", line 336, in match_request
    self.url_adapter.match(return_rule=True)
  File "/home/jon/venv/p3/lib/python3.6/site-packages/werkzeug/routing.py", line 1581, in match
    raise NotFound()
werkzeug.exceptions.NotFound: 404 Not Found: The requested URL was not found on the server.  If you entered the URL manually please check your spelling and try again.

[2019-Dec-14 19:19] 127.0.0.1 GET http /network? 200 OK
[2019-Dec-14 19:19] 127.0.0.1 GET http /d3_data? 5xx INTERNAL SERVER ERROR
Traceback (most recent call last):
  File "/home/jon/venv/p3/lib/python3.6/site-packages/flask/app.py", line 1813, in full_dispatch_request
    rv = self.dispatch_request()
  File "/home/jon/venv/p3/lib/python3.6/site-packages/flask/app.py", line 1799, in dispatch_request
    return self.view_functions[rule.endpoint](**req.view_args)
  File "app.py", line 261, in d3_data
    data_array = json.load(f)
  File "/home/jon/venv/p3/lib/python3.6/site-packages/flask/json/__init__.py", line 214, in load
    return _json.load(fp, **kwargs)
  File "/usr/lib/python3.6/json/__init__.py", line 299, in load
    parse_constant=parse_constant, object_pairs_hook=object_pairs_hook, **kw)
  File "/usr/lib/python3.6/json/__init__.py", line 367, in loads
    return cls(**kw).decode(s)
  File "/usr/lib/python3.6/json/decoder.py", line 342, in decode
    raise JSONDecodeError("Extra data", s, end)
json.decoder.JSONDecodeError: Extra data: line 93 column 5 (char 1212)

[2019-Dec-14 19:19] 127.0.0.1 GET http /favicon.ico? 5xx INTERNAL SERVER ERROR
Traceback (most recent call last):
  File "/home/jon/venv/p3/lib/python3.6/site-packages/flask/app.py", line 1813, in full_dispatch_request
    rv = self.dispatch_request()
  File "/home/jon/venv/p3/lib/python3.6/site-packages/flask/app.py", line 1791, in dispatch_request
    self.raise_routing_exception(req)
  File "/home/jon/venv/p3/lib/python3.6/site-packages/flask/app.py", line 1774, in raise_routing_exception
    raise request.routing_exception
  File "/home/jon/venv/p3/lib/python3.6/site-packages/flask/ctx.py", line 336, in match_request
    self.url_adapter.match(return_rule=True)
  File "/home/jon/venv/p3/lib/python3.6/site-packages/werkzeug/routing.py", line 1581, in match
    raise NotFound()
werkzeug.exceptions.NotFound: 404 Not Found: The requested URL was not found on the server.  If you entered the URL manually please check your spelling and try again.

[2019-Dec-14 19:19] 127.0.0.1 GET http /network? 200 OK
[2019-Dec-14 19:19] 127.0.0.1 GET http /d3_data? 5xx INTERNAL SERVER ERROR
Traceback (most recent call last):
  File "/home/jon/venv/p3/lib/python3.6/site-packages/flask/app.py", line 1813, in full_dispatch_request
    rv = self.dispatch_request()
  File "/home/jon/venv/p3/lib/python3.6/site-packages/flask/app.py", line 1799, in dispatch_request
    return self.view_functions[rule.endpoint](**req.view_args)
  File "app.py", line 261, in d3_data
    data_array = json.load(f)
  File "/usr/lib/python3.6/json/__init__.py", line 299, in load
    parse_constant=parse_constant, object_pairs_hook=object_pairs_hook, **kw)
  File "/usr/lib/python3.6/json/__init__.py", line 354, in loads
    return _default_decoder.decode(s)
  File "/usr/lib/python3.6/json/decoder.py", line 342, in decode
    raise JSONDecodeError("Extra data", s, end)
json.decoder.JSONDecodeError: Extra data: line 93 column 5 (char 1212)

[2019-Dec-14 19:19] 127.0.0.1 GET http /favicon.ico? 5xx INTERNAL SERVER ERROR
Traceback (most recent call last):
  File "/home/jon/venv/p3/lib/python3.6/site-packages/flask/app.py", line 1813, in full_dispatch_request
    rv = self.dispatch_request()
  File "/home/jon/venv/p3/lib/python3.6/site-packages/flask/app.py", line 1791, in dispatch_request
    self.raise_routing_exception(req)
  File "/home/jon/venv/p3/lib/python3.6/site-packages/flask/app.py", line 1774, in raise_routing_exception
    raise request.routing_exception
  File "/home/jon/venv/p3/lib/python3.6/site-packages/flask/ctx.py", line 336, in match_request
    self.url_adapter.match(return_rule=True)
  File "/home/jon/venv/p3/lib/python3.6/site-packages/werkzeug/routing.py", line 1581, in match
    raise NotFound()
werkzeug.exceptions.NotFound: 404 Not Found: The requested URL was not found on the server.  If you entered the URL manually please check your spelling and try again.

[2019-Dec-14 19:19] 127.0.0.1 GET http /? 200 OK
[2019-Dec-14 19:19] 127.0.0.1 GET http /static/css/auto-complete.css? 200 OK
[2019-Dec-14 19:19] 127.0.0.1 GET http /static/css/signin.css? 200 OK
[2019-Dec-14 19:19] 127.0.0.1 GET http /static/js/jquery-1.9.0.js? 200 OK
[2019-Dec-14 19:19] 127.0.0.1 GET http /static/js/script.js? 200 OK
[2019-Dec-14 19:19] 127.0.0.1 GET http /static/js/fetch.js? 200 OK
[2019-Dec-14 19:19] 127.0.0.1 GET http /static/css/my_style.css? 200 OK
[2019-Dec-14 19:19] 127.0.0.1 GET http /static/css/scss_css.css? 200 OK
[2019-Dec-14 19:19] 127.0.0.1 GET http /static/js/auto-complete.min.js? 200 OK
[2019-Dec-14 19:19] 127.0.0.1 GET http /static/data/data.json? 200 OK
[2019-Dec-14 19:19] 127.0.0.1 GET http /static/js/autocomplete.js? 200 OK
[2019-Dec-14 19:19] 127.0.0.1 GET http /static/css/scss_css.css.map? 200 OK
[2019-Dec-14 19:19] 127.0.0.1 GET http /network? 200 OK
[2019-Dec-14 19:19] 127.0.0.1 GET http /d3_data? 5xx INTERNAL SERVER ERROR
Traceback (most recent call last):
  File "/home/jon/venv/p3/lib/python3.6/site-packages/flask/app.py", line 1813, in full_dispatch_request
    rv = self.dispatch_request()
  File "/home/jon/venv/p3/lib/python3.6/site-packages/flask/app.py", line 1799, in dispatch_request
    return self.view_functions[rule.endpoint](**req.view_args)
  File "app.py", line 261, in d3_data
    data_array = json.load(f)
  File "/usr/lib/python3.6/json/__init__.py", line 299, in load
    parse_constant=parse_constant, object_pairs_hook=object_pairs_hook, **kw)
  File "/usr/lib/python3.6/json/__init__.py", line 354, in loads
    return _default_decoder.decode(s)
  File "/usr/lib/python3.6/json/decoder.py", line 342, in decode
    raise JSONDecodeError("Extra data", s, end)
json.decoder.JSONDecodeError: Extra data: line 93 column 5 (char 1212)

[2019-Dec-14 19:19] 127.0.0.1 GET http /favicon.ico? 5xx INTERNAL SERVER ERROR
Traceback (most recent call last):
  File "/home/jon/venv/p3/lib/python3.6/site-packages/flask/app.py", line 1813, in full_dispatch_request
    rv = self.dispatch_request()
  File "/home/jon/venv/p3/lib/python3.6/site-packages/flask/app.py", line 1791, in dispatch_request
    self.raise_routing_exception(req)
  File "/home/jon/venv/p3/lib/python3.6/site-packages/flask/app.py", line 1774, in raise_routing_exception
    raise request.routing_exception
  File "/home/jon/venv/p3/lib/python3.6/site-packages/flask/ctx.py", line 336, in match_request
    self.url_adapter.match(return_rule=True)
  File "/home/jon/venv/p3/lib/python3.6/site-packages/werkzeug/routing.py", line 1581, in match
    raise NotFound()
werkzeug.exceptions.NotFound: 404 Not Found: The requested URL was not found on the server.  If you entered the URL manually please check your spelling and try again.

[2019-Dec-14 19:21] 127.0.0.1 GET http /network? 200 OK
[2019-Dec-14 19:21] 127.0.0.1 GET http /favicon.ico? 5xx INTERNAL SERVER ERROR
Traceback (most recent call last):
  File "/home/jon/venv/p3/lib/python3.6/site-packages/flask/app.py", line 1813, in full_dispatch_request
    rv = self.dispatch_request()
  File "/home/jon/venv/p3/lib/python3.6/site-packages/flask/app.py", line 1791, in dispatch_request
    self.raise_routing_exception(req)
  File "/home/jon/venv/p3/lib/python3.6/site-packages/flask/app.py", line 1774, in raise_routing_exception
    raise request.routing_exception
  File "/home/jon/venv/p3/lib/python3.6/site-packages/flask/ctx.py", line 336, in match_request
    self.url_adapter.match(return_rule=True)
  File "/home/jon/venv/p3/lib/python3.6/site-packages/werkzeug/routing.py", line 1581, in match
    raise NotFound()
werkzeug.exceptions.NotFound: 404 Not Found: The requested URL was not found on the server.  If you entered the URL manually please check your spelling and try again.

[2019-Dec-14 19:22] 127.0.0.1 GET http /network? 200 OK
[2019-Dec-14 19:22] 127.0.0.1 GET http /d3_data? 200 OK
[2019-Dec-14 19:22] 127.0.0.1 GET http /favicon.ico? 5xx INTERNAL SERVER ERROR
Traceback (most recent call last):
  File "/home/jon/venv/p3/lib/python3.6/site-packages/flask/app.py", line 1813, in full_dispatch_request
    rv = self.dispatch_request()
  File "/home/jon/venv/p3/lib/python3.6/site-packages/flask/app.py", line 1791, in dispatch_request
    self.raise_routing_exception(req)
  File "/home/jon/venv/p3/lib/python3.6/site-packages/flask/app.py", line 1774, in raise_routing_exception
    raise request.routing_exception
  File "/home/jon/venv/p3/lib/python3.6/site-packages/flask/ctx.py", line 336, in match_request
    self.url_adapter.match(return_rule=True)
  File "/home/jon/venv/p3/lib/python3.6/site-packages/werkzeug/routing.py", line 1581, in match
    raise NotFound()
werkzeug.exceptions.NotFound: 404 Not Found: The requested URL was not found on the server.  If you entered the URL manually please check your spelling and try again.

[2019-Dec-14 20:07] 127.0.0.1 GET http /network? 200 OK
[2019-Dec-14 20:07] 127.0.0.1 GET http /d3_data? 200 OK
[2019-Dec-14 20:07] 127.0.0.1 GET http /favicon.ico? 5xx INTERNAL SERVER ERROR
Traceback (most recent call last):
  File "/home/jon/venv/p3/lib/python3.6/site-packages/flask/app.py", line 1813, in full_dispatch_request
    rv = self.dispatch_request()
  File "/home/jon/venv/p3/lib/python3.6/site-packages/flask/app.py", line 1791, in dispatch_request
    self.raise_routing_exception(req)
  File "/home/jon/venv/p3/lib/python3.6/site-packages/flask/app.py", line 1774, in raise_routing_exception
    raise request.routing_exception
  File "/home/jon/venv/p3/lib/python3.6/site-packages/flask/ctx.py", line 336, in match_request
    self.url_adapter.match(return_rule=True)
  File "/home/jon/venv/p3/lib/python3.6/site-packages/werkzeug/routing.py", line 1581, in match
    raise NotFound()
werkzeug.exceptions.NotFound: 404 Not Found: The requested URL was not found on the server.  If you entered the URL manually please check your spelling and try again.

[2019-Dec-14 20:11] 127.0.0.1 GET http /network? 200 OK
[2019-Dec-14 20:11] 127.0.0.1 GET http /d3_data? 200 OK
[2019-Dec-14 20:11] 127.0.0.1 GET http /favicon.ico? 5xx INTERNAL SERVER ERROR
Traceback (most recent call last):
  File "/home/jon/venv/p3/lib/python3.6/site-packages/flask/app.py", line 1813, in full_dispatch_request
    rv = self.dispatch_request()
  File "/home/jon/venv/p3/lib/python3.6/site-packages/flask/app.py", line 1791, in dispatch_request
    self.raise_routing_exception(req)
  File "/home/jon/venv/p3/lib/python3.6/site-packages/flask/app.py", line 1774, in raise_routing_exception
    raise request.routing_exception
  File "/home/jon/venv/p3/lib/python3.6/site-packages/flask/ctx.py", line 336, in match_request
    self.url_adapter.match(return_rule=True)
  File "/home/jon/venv/p3/lib/python3.6/site-packages/werkzeug/routing.py", line 1581, in match
    raise NotFound()
werkzeug.exceptions.NotFound: 404 Not Found: The requested URL was not found on the server.  If you entered the URL manually please check your spelling and try again.

[2019-Dec-14 20:11] 127.0.0.1 GET http /network? 200 OK
[2019-Dec-14 20:11] 127.0.0.1 GET http /d3_data? 200 OK
[2019-Dec-14 20:11] 127.0.0.1 GET http /favicon.ico? 5xx INTERNAL SERVER ERROR
Traceback (most recent call last):
  File "/home/jon/venv/p3/lib/python3.6/site-packages/flask/app.py", line 1813, in full_dispatch_request
    rv = self.dispatch_request()
  File "/home/jon/venv/p3/lib/python3.6/site-packages/flask/app.py", line 1791, in dispatch_request
    self.raise_routing_exception(req)
  File "/home/jon/venv/p3/lib/python3.6/site-packages/flask/app.py", line 1774, in raise_routing_exception
    raise request.routing_exception
  File "/home/jon/venv/p3/lib/python3.6/site-packages/flask/ctx.py", line 336, in match_request
    self.url_adapter.match(return_rule=True)
  File "/home/jon/venv/p3/lib/python3.6/site-packages/werkzeug/routing.py", line 1581, in match
    raise NotFound()
werkzeug.exceptions.NotFound: 404 Not Found: The requested URL was not found on the server.  If you entered the URL manually please check your spelling and try again.

[2019-Dec-14 20:23] 127.0.0.1 GET http /network? 200 OK
[2019-Dec-14 20:23] 127.0.0.1 GET http /d3_data? 200 OK
[2019-Dec-14 20:23] 127.0.0.1 GET http /favicon.ico? 5xx INTERNAL SERVER ERROR
Traceback (most recent call last):
  File "/home/jon/venv/p3/lib/python3.6/site-packages/flask/app.py", line 1813, in full_dispatch_request
    rv = self.dispatch_request()
  File "/home/jon/venv/p3/lib/python3.6/site-packages/flask/app.py", line 1791, in dispatch_request
    self.raise_routing_exception(req)
  File "/home/jon/venv/p3/lib/python3.6/site-packages/flask/app.py", line 1774, in raise_routing_exception
    raise request.routing_exception
  File "/home/jon/venv/p3/lib/python3.6/site-packages/flask/ctx.py", line 336, in match_request
    self.url_adapter.match(return_rule=True)
  File "/home/jon/venv/p3/lib/python3.6/site-packages/werkzeug/routing.py", line 1581, in match
    raise NotFound()
werkzeug.exceptions.NotFound: 404 Not Found: The requested URL was not found on the server.  If you entered the URL manually please check your spelling and try again.

[2019-Dec-14 20:26] 127.0.0.1 GET http /network? 200 OK
[2019-Dec-14 20:26] 127.0.0.1 GET http /d3_data? 200 OK
[2019-Dec-14 20:26] 127.0.0.1 GET http /favicon.ico? 5xx INTERNAL SERVER ERROR
Traceback (most recent call last):
  File "/home/jon/venv/p3/lib/python3.6/site-packages/flask/app.py", line 1813, in full_dispatch_request
    rv = self.dispatch_request()
  File "/home/jon/venv/p3/lib/python3.6/site-packages/flask/app.py", line 1791, in dispatch_request
    self.raise_routing_exception(req)
  File "/home/jon/venv/p3/lib/python3.6/site-packages/flask/app.py", line 1774, in raise_routing_exception
    raise request.routing_exception
  File "/home/jon/venv/p3/lib/python3.6/site-packages/flask/ctx.py", line 336, in match_request
    self.url_adapter.match(return_rule=True)
  File "/home/jon/venv/p3/lib/python3.6/site-packages/werkzeug/routing.py", line 1581, in match
    raise NotFound()
werkzeug.exceptions.NotFound: 404 Not Found: The requested URL was not found on the server.  If you entered the URL manually please check your spelling and try again.

[2019-Dec-14 20:31] 127.0.0.1 GET http /network? 200 OK
[2019-Dec-14 20:31] 127.0.0.1 GET http /d3_data? 200 OK
[2019-Dec-14 20:31] 127.0.0.1 GET http /favicon.ico? 5xx INTERNAL SERVER ERROR
Traceback (most recent call last):
  File "/home/jon/venv/p3/lib/python3.6/site-packages/flask/app.py", line 1813, in full_dispatch_request
    rv = self.dispatch_request()
  File "/home/jon/venv/p3/lib/python3.6/site-packages/flask/app.py", line 1791, in dispatch_request
    self.raise_routing_exception(req)
  File "/home/jon/venv/p3/lib/python3.6/site-packages/flask/app.py", line 1774, in raise_routing_exception
    raise request.routing_exception
  File "/home/jon/venv/p3/lib/python3.6/site-packages/flask/ctx.py", line 336, in match_request
    self.url_adapter.match(return_rule=True)
  File "/home/jon/venv/p3/lib/python3.6/site-packages/werkzeug/routing.py", line 1581, in match
    raise NotFound()
werkzeug.exceptions.NotFound: 404 Not Found: The requested URL was not found on the server.  If you entered the URL manually please check your spelling and try again.

[2019-Dec-14 20:31] 127.0.0.1 GET http /? 200 OK
[2019-Dec-14 20:31] 127.0.0.1 GET http /static/css/auto-complete.css? 200 OK
[2019-Dec-14 20:31] 127.0.0.1 GET http /static/css/signin.css? 200 OK
[2019-Dec-14 20:31] 127.0.0.1 GET http /static/js/jquery-1.9.0.js? 200 OK
[2019-Dec-14 20:31] 127.0.0.1 GET http /static/js/script.js? 200 OK
[2019-Dec-14 20:31] 127.0.0.1 GET http /static/js/fetch.js? 200 OK
[2019-Dec-14 20:31] 127.0.0.1 GET http /static/js/auto-complete.min.js? 200 OK
[2019-Dec-14 20:31] 127.0.0.1 GET http /static/css/my_style.css? 200 OK
[2019-Dec-14 20:31] 127.0.0.1 GET http /static/css/scss_css.css? 200 OK
[2019-Dec-14 20:31] 127.0.0.1 GET http /static/js/autocomplete.js? 200 OK
[2019-Dec-14 20:31] 127.0.0.1 GET http /static/data/data.json? 200 OK
[2019-Dec-14 20:31] 127.0.0.1 GET http /static/css/scss_css.css.map? 200 OK
[2019-Dec-14 20:31] 127.0.0.1 GET http /network1? 5xx INTERNAL SERVER ERROR
Traceback (most recent call last):
  File "/home/jon/venv/p3/lib/python3.6/site-packages/flask/app.py", line 1813, in full_dispatch_request
    rv = self.dispatch_request()
  File "/home/jon/venv/p3/lib/python3.6/site-packages/flask/app.py", line 1791, in dispatch_request
    self.raise_routing_exception(req)
  File "/home/jon/venv/p3/lib/python3.6/site-packages/flask/app.py", line 1774, in raise_routing_exception
    raise request.routing_exception
  File "/home/jon/venv/p3/lib/python3.6/site-packages/flask/ctx.py", line 336, in match_request
    self.url_adapter.match(return_rule=True)
  File "/home/jon/venv/p3/lib/python3.6/site-packages/werkzeug/routing.py", line 1581, in match
    raise NotFound()
werkzeug.exceptions.NotFound: 404 Not Found: The requested URL was not found on the server.  If you entered the URL manually please check your spelling and try again.

[2019-Dec-14 20:31] 127.0.0.1 GET http /favicon.ico? 5xx INTERNAL SERVER ERROR
Traceback (most recent call last):
  File "/home/jon/venv/p3/lib/python3.6/site-packages/flask/app.py", line 1813, in full_dispatch_request
    rv = self.dispatch_request()
  File "/home/jon/venv/p3/lib/python3.6/site-packages/flask/app.py", line 1791, in dispatch_request
    self.raise_routing_exception(req)
  File "/home/jon/venv/p3/lib/python3.6/site-packages/flask/app.py", line 1774, in raise_routing_exception
    raise request.routing_exception
  File "/home/jon/venv/p3/lib/python3.6/site-packages/flask/ctx.py", line 336, in match_request
    self.url_adapter.match(return_rule=True)
  File "/home/jon/venv/p3/lib/python3.6/site-packages/werkzeug/routing.py", line 1581, in match
    raise NotFound()
werkzeug.exceptions.NotFound: 404 Not Found: The requested URL was not found on the server.  If you entered the URL manually please check your spelling and try again.

[2019-Dec-14 20:34] 127.0.0.1 GET http /network1? 200 OK
[2019-Dec-14 20:34] 127.0.0.1 GET http /d3_data1? 200 OK
[2019-Dec-14 20:34] 127.0.0.1 GET http /favicon.ico? 5xx INTERNAL SERVER ERROR
Traceback (most recent call last):
  File "/home/jon/venv/p3/lib/python3.6/site-packages/flask/app.py", line 1813, in full_dispatch_request
    rv = self.dispatch_request()
  File "/home/jon/venv/p3/lib/python3.6/site-packages/flask/app.py", line 1791, in dispatch_request
    self.raise_routing_exception(req)
  File "/home/jon/venv/p3/lib/python3.6/site-packages/flask/app.py", line 1774, in raise_routing_exception
    raise request.routing_exception
  File "/home/jon/venv/p3/lib/python3.6/site-packages/flask/ctx.py", line 336, in match_request
    self.url_adapter.match(return_rule=True)
  File "/home/jon/venv/p3/lib/python3.6/site-packages/werkzeug/routing.py", line 1581, in match
    raise NotFound()
werkzeug.exceptions.NotFound: 404 Not Found: The requested URL was not found on the server.  If you entered the URL manually please check your spelling and try again.

[2019-Dec-14 20:48] 127.0.0.1 GET http /network1? 200 OK
[2019-Dec-14 20:48] 127.0.0.1 GET http /d3_data1? 200 OK
[2019-Dec-14 20:48] 127.0.0.1 GET http /favicon.ico? 5xx INTERNAL SERVER ERROR
Traceback (most recent call last):
  File "/home/jon/venv/p3/lib/python3.6/site-packages/flask/app.py", line 1813, in full_dispatch_request
    rv = self.dispatch_request()
  File "/home/jon/venv/p3/lib/python3.6/site-packages/flask/app.py", line 1791, in dispatch_request
    self.raise_routing_exception(req)
  File "/home/jon/venv/p3/lib/python3.6/site-packages/flask/app.py", line 1774, in raise_routing_exception
    raise request.routing_exception
  File "/home/jon/venv/p3/lib/python3.6/site-packages/flask/ctx.py", line 336, in match_request
    self.url_adapter.match(return_rule=True)
  File "/home/jon/venv/p3/lib/python3.6/site-packages/werkzeug/routing.py", line 1581, in match
    raise NotFound()
werkzeug.exceptions.NotFound: 404 Not Found: The requested URL was not found on the server.  If you entered the URL manually please check your spelling and try again.

[2019-Dec-14 21:03] 127.0.0.1 GET http /? 200 OK
[2019-Dec-14 21:03] 127.0.0.1 GET http /? 200 OK
[2019-Dec-14 21:03] 127.0.0.1 GET http /static/favicon.ico? 200 OK
[2019-Dec-14 21:03] 127.0.0.1 GET http /network2? 200 OK
[2019-Dec-14 21:03] 127.0.0.1 GET http /favicon.ico? 5xx INTERNAL SERVER ERROR
Traceback (most recent call last):
  File "/home/jon/venv/p3/lib/python3.6/site-packages/flask/app.py", line 1813, in full_dispatch_request
    rv = self.dispatch_request()
  File "/home/jon/venv/p3/lib/python3.6/site-packages/flask/app.py", line 1791, in dispatch_request
    self.raise_routing_exception(req)
  File "/home/jon/venv/p3/lib/python3.6/site-packages/flask/app.py", line 1774, in raise_routing_exception
    raise request.routing_exception
  File "/home/jon/venv/p3/lib/python3.6/site-packages/flask/ctx.py", line 336, in match_request
    self.url_adapter.match(return_rule=True)
  File "/home/jon/venv/p3/lib/python3.6/site-packages/werkzeug/routing.py", line 1581, in match
    raise NotFound()
werkzeug.exceptions.NotFound: 404 Not Found: The requested URL was not found on the server.  If you entered the URL manually please check your spelling and try again.

[2019-Dec-14 21:05] 127.0.0.1 GET http /network2? 200 OK
[2019-Dec-14 21:05] 127.0.0.1 GET http /d3_data2? 200 OK
[2019-Dec-14 21:05] 127.0.0.1 GET http /favicon.ico? 5xx INTERNAL SERVER ERROR
Traceback (most recent call last):
  File "/home/jon/venv/p3/lib/python3.6/site-packages/flask/app.py", line 1813, in full_dispatch_request
    rv = self.dispatch_request()
  File "/home/jon/venv/p3/lib/python3.6/site-packages/flask/app.py", line 1791, in dispatch_request
    self.raise_routing_exception(req)
  File "/home/jon/venv/p3/lib/python3.6/site-packages/flask/app.py", line 1774, in raise_routing_exception
    raise request.routing_exception
  File "/home/jon/venv/p3/lib/python3.6/site-packages/flask/ctx.py", line 336, in match_request
    self.url_adapter.match(return_rule=True)
  File "/home/jon/venv/p3/lib/python3.6/site-packages/werkzeug/routing.py", line 1581, in match
    raise NotFound()
werkzeug.exceptions.NotFound: 404 Not Found: The requested URL was not found on the server.  If you entered the URL manually please check your spelling and try again.

[2019-Dec-14 21:11] 127.0.0.1 GET http /network2? 200 OK
[2019-Dec-14 21:11] 127.0.0.1 GET http /d3_data2? 200 OK
[2019-Dec-14 21:11] 127.0.0.1 GET http /favicon.ico? 5xx INTERNAL SERVER ERROR
Traceback (most recent call last):
  File "/home/jon/venv/p3/lib/python3.6/site-packages/flask/app.py", line 1813, in full_dispatch_request
    rv = self.dispatch_request()
  File "/home/jon/venv/p3/lib/python3.6/site-packages/flask/app.py", line 1791, in dispatch_request
    self.raise_routing_exception(req)
  File "/home/jon/venv/p3/lib/python3.6/site-packages/flask/app.py", line 1774, in raise_routing_exception
    raise request.routing_exception
  File "/home/jon/venv/p3/lib/python3.6/site-packages/flask/ctx.py", line 336, in match_request
    self.url_adapter.match(return_rule=True)
  File "/home/jon/venv/p3/lib/python3.6/site-packages/werkzeug/routing.py", line 1581, in match
    raise NotFound()
werkzeug.exceptions.NotFound: 404 Not Found: The requested URL was not found on the server.  If you entered the URL manually please check your spelling and try again.

[2019-Dec-14 21:11] 127.0.0.1 GET http /network2? 200 OK
[2019-Dec-14 21:11] 127.0.0.1 GET http /d3_data2? 200 OK
[2019-Dec-14 21:11] 127.0.0.1 GET http /favicon.ico? 5xx INTERNAL SERVER ERROR
Traceback (most recent call last):
  File "/home/jon/venv/p3/lib/python3.6/site-packages/flask/app.py", line 1813, in full_dispatch_request
    rv = self.dispatch_request()
  File "/home/jon/venv/p3/lib/python3.6/site-packages/flask/app.py", line 1791, in dispatch_request
    self.raise_routing_exception(req)
  File "/home/jon/venv/p3/lib/python3.6/site-packages/flask/app.py", line 1774, in raise_routing_exception
    raise request.routing_exception
  File "/home/jon/venv/p3/lib/python3.6/site-packages/flask/ctx.py", line 336, in match_request
    self.url_adapter.match(return_rule=True)
  File "/home/jon/venv/p3/lib/python3.6/site-packages/werkzeug/routing.py", line 1581, in match
    raise NotFound()
werkzeug.exceptions.NotFound: 404 Not Found: The requested URL was not found on the server.  If you entered the URL manually please check your spelling and try again.

[2019-Dec-14 21:14] 127.0.0.1 GET http /network2? 200 OK
[2019-Dec-14 21:14] 127.0.0.1 GET http /d3_data2? 200 OK
[2019-Dec-14 21:14] 127.0.0.1 GET http /favicon.ico? 5xx INTERNAL SERVER ERROR
Traceback (most recent call last):
  File "/home/jon/venv/p3/lib/python3.6/site-packages/flask/app.py", line 1813, in full_dispatch_request
    rv = self.dispatch_request()
  File "/home/jon/venv/p3/lib/python3.6/site-packages/flask/app.py", line 1791, in dispatch_request
    self.raise_routing_exception(req)
  File "/home/jon/venv/p3/lib/python3.6/site-packages/flask/app.py", line 1774, in raise_routing_exception
    raise request.routing_exception
  File "/home/jon/venv/p3/lib/python3.6/site-packages/flask/ctx.py", line 336, in match_request
    self.url_adapter.match(return_rule=True)
  File "/home/jon/venv/p3/lib/python3.6/site-packages/werkzeug/routing.py", line 1581, in match
    raise NotFound()
werkzeug.exceptions.NotFound: 404 Not Found: The requested URL was not found on the server.  If you entered the URL manually please check your spelling and try again.

[2019-Dec-14 21:18] 127.0.0.1 GET http /network2? 200 OK
[2019-Dec-14 21:18] 127.0.0.1 GET http /d3_data2? 200 OK
[2019-Dec-14 21:18] 127.0.0.1 GET http /favicon.ico? 5xx INTERNAL SERVER ERROR
Traceback (most recent call last):
  File "/home/jon/venv/p3/lib/python3.6/site-packages/flask/app.py", line 1813, in full_dispatch_request
    rv = self.dispatch_request()
  File "/home/jon/venv/p3/lib/python3.6/site-packages/flask/app.py", line 1791, in dispatch_request
    self.raise_routing_exception(req)
  File "/home/jon/venv/p3/lib/python3.6/site-packages/flask/app.py", line 1774, in raise_routing_exception
    raise request.routing_exception
  File "/home/jon/venv/p3/lib/python3.6/site-packages/flask/ctx.py", line 336, in match_request
    self.url_adapter.match(return_rule=True)
  File "/home/jon/venv/p3/lib/python3.6/site-packages/werkzeug/routing.py", line 1581, in match
    raise NotFound()
werkzeug.exceptions.NotFound: 404 Not Found: The requested URL was not found on the server.  If you entered the URL manually please check your spelling and try again.

[2019-Dec-14 21:18] 127.0.0.1 GET http /network2? 200 OK
[2019-Dec-14 21:18] 127.0.0.1 GET http /d3_data2? 200 OK
[2019-Dec-14 21:18] 127.0.0.1 GET http /favicon.ico? 5xx INTERNAL SERVER ERROR
Traceback (most recent call last):
  File "/home/jon/venv/p3/lib/python3.6/site-packages/flask/app.py", line 1813, in full_dispatch_request
    rv = self.dispatch_request()
  File "/home/jon/venv/p3/lib/python3.6/site-packages/flask/app.py", line 1791, in dispatch_request
    self.raise_routing_exception(req)
  File "/home/jon/venv/p3/lib/python3.6/site-packages/flask/app.py", line 1774, in raise_routing_exception
    raise request.routing_exception
  File "/home/jon/venv/p3/lib/python3.6/site-packages/flask/ctx.py", line 336, in match_request
    self.url_adapter.match(return_rule=True)
  File "/home/jon/venv/p3/lib/python3.6/site-packages/werkzeug/routing.py", line 1581, in match
    raise NotFound()
werkzeug.exceptions.NotFound: 404 Not Found: The requested URL was not found on the server.  If you entered the URL manually please check your spelling and try again.

[2019-Dec-14 21:20] 127.0.0.1 GET http /network1? 200 OK
[2019-Dec-14 21:20] 127.0.0.1 GET http /favicon.ico? 5xx INTERNAL SERVER ERROR
Traceback (most recent call last):
  File "/home/jon/venv/p3/lib/python3.6/site-packages/flask/app.py", line 1813, in full_dispatch_request
    rv = self.dispatch_request()
  File "/home/jon/venv/p3/lib/python3.6/site-packages/flask/app.py", line 1791, in dispatch_request
    self.raise_routing_exception(req)
  File "/home/jon/venv/p3/lib/python3.6/site-packages/flask/app.py", line 1774, in raise_routing_exception
    raise request.routing_exception
  File "/home/jon/venv/p3/lib/python3.6/site-packages/flask/ctx.py", line 336, in match_request
    self.url_adapter.match(return_rule=True)
  File "/home/jon/venv/p3/lib/python3.6/site-packages/werkzeug/routing.py", line 1581, in match
    raise NotFound()
werkzeug.exceptions.NotFound: 404 Not Found: The requested URL was not found on the server.  If you entered the URL manually please check your spelling and try again.

[2019-Dec-14 21:20] 127.0.0.1 GET http /? 200 OK
[2019-Dec-14 21:20] 127.0.0.1 GET http /static/css/auto-complete.css? 200 OK
[2019-Dec-14 21:20] 127.0.0.1 GET http /static/css/signin.css? 200 OK
[2019-Dec-14 21:20] 127.0.0.1 GET http /static/js/jquery-1.9.0.js? 200 OK
[2019-Dec-14 21:20] 127.0.0.1 GET http /static/css/my_style.css? 200 OK
[2019-Dec-14 21:20] 127.0.0.1 GET http /static/css/scss_css.css? 200 OK
[2019-Dec-14 21:20] 127.0.0.1 GET http /static/js/fetch.js? 200 OK
[2019-Dec-14 21:20] 127.0.0.1 GET http /static/js/script.js? 200 OK
[2019-Dec-14 21:20] 127.0.0.1 GET http /static/js/auto-complete.min.js? 200 OK
[2019-Dec-14 21:20] 127.0.0.1 GET http /static/data/data.json? 200 OK
[2019-Dec-14 21:20] 127.0.0.1 GET http /static/js/autocomplete.js? 200 OK
[2019-Dec-14 21:20] 127.0.0.1 GET http /static/css/scss_css.css.map? 200 OK
[2019-Dec-14 21:20] 127.0.0.1 GET http /network2? 200 OK
[2019-Dec-14 21:20] 127.0.0.1 GET http /d3_data2? 200 OK
